package thaumcraft.common.lib.world.dim;

import java.util.Random;
import net.minecraft.init.Blocks;
import net.minecraft.world.World;
import net.minecraftforge.common.util.ForgeDirection;
import thaumcraft.common.config.ConfigBlocks;

public class GenPortal extends GenCommon {
   static void generatePortal(World world, Random random, int cx, int cz, int y, Cell cell) {
      int x = cx * 16;
      int z = cz * 16;

//      for(int a = 1; a <= 15; ++a) {
//         for(int b = 1; b <= 15; ++b) {
//            for(int c = 0; c < 13; ++c) {
//               if (a == 1 || a == 15 || b == 1 || b == 15) {
//                  placeBlock(world, x + a, y + c, z + b, 1, cell);
//               }
//            }
//         }
//      }
//
//      for(int a = 2; a <= 14; ++a) {
//         for(int b = 2; b <= 14; ++b) {
//            for(int c = 1; c < 12; ++c) {
//               if ((a == 2 || a == 14 || b == 2 || b == 14) && (a != 2 || b <= 3 || b >= 12 || !cell.west || c >= 10) && (a != 14 || b <= 3 || b >= 12 || !cell.east || c >= 10) && (b != 2 || a <= 3 || a >= 12 || !cell.north || c >= 10) && (b != 14 || a <= 3 || a >= 12 || !cell.south || c >= 10)) {
//                  placeBlock(world, x + a, y + c, z + b, 8, cell);
//               }
//            }
//         }
//      }
//
//      for(int a = 3; a <= 13; ++a) {
//         for(int b = 3; b <= 13; ++b) {
//            for(int c = 2; c < 11; ++c) {
//               if ((a == 3 || a == 13 || b == 3 || b == 13) && (a > 4 || b > 4) && (a > 4 || b < 12) && (a < 12 || b > 4) && (a < 12 || b < 12)) {
//                  placeBlock(world, x + a, y + c, z + b, 2, cell);
//               }
//            }
//         }
//      }
//
//      for(int a = 2; a <= 14; ++a) {
//         for(int b = 2; b <= 14; ++b) {
//            placeBlock(world, x + a, y - 1, z + b, 1, cell);
//            placeBlock(world, x + a, y, z + b, 8, cell);
//            placeBlock(world, x + a, y + 1, z + b, 19, cell);
//            placeBlock(world, x + a, y + 13, z + b, 1, cell);
//            placeBlock(world, x + a, y + 12, z + b, 8, cell);
//            placeBlock(world, x + a, y + 11, z + b, 2, cell);
//             {
//                int q = Math.min(Math.abs(8 - a), Math.abs(8 - b));
//
//                for(int g = 0; g < q - 1; ++g) {
//                   placeBlock(world, x + a, y + 1 + g, z + b, 19, cell);
//                }
//             }
//
//            if (a > 3 && a < 13 && b > 3 && b < 13) {
//               int q = Math.min(Math.abs(8 - a), Math.abs(8 - b));
//
//               for(int g = 0; g < q; ++g) {
//                  placeBlock(world, x + a, y + 11 - g, z + b, 19, cell);
//               }
//            }
//         }
//      }
//
//      for(int g = 0; g < 5; ++g) {
//         placeBlock(world, x + 6 + g, y + 2, z + 4, 10, ForgeDirection.NORTH, cell);
//         placeBlock(world, x + 6 + g, y + 2, z + 12, 10, ForgeDirection.SOUTH, cell);
//         placeBlock(world, x + 12, y + 2, z + 6 + g, 10, ForgeDirection.EAST, cell);
//         placeBlock(world, x + 4, y + 2, z + 6 + g, 10, ForgeDirection.WEST, cell);
//      }
//
//      GenCommon.generateConnections(world, random, cx, cz, y, cell, 3, true);
//
//      for(int a = 3; a <= 13; ++a) {
//         for(int b = 3; b <= 13; ++b) {
//            for(int c = 1; c < 12; ++c) {
//               if (a <= 4 && b <= 4 || a <= 4 && b >= 12 || a >= 12 && b <= 4 || a >= 12 && b >= 12) {
//                  placeBlock(world, x + a, y + c, z + b, 9, cell);
//                  world.notifyBlockChange(x + a, y + c, z + b, Blocks.air);
//               }
//            }
//         }
//      }
//
//      placeBlock(world, x + 5, y + 3, z + 5, 10, ForgeDirection.NORTH, cell);
//      placeBlock(world, x + 4, y + 3, z + 5, 10, ForgeDirection.NORTH, cell);
//      placeBlock(world, x + 5, y + 3, z + 4, 10, ForgeDirection.WEST, cell);
//      placeBlock(world, x + 5, y + 8, z + 5, 11, ForgeDirection.NORTH, cell);
//      placeBlock(world, x + 4, y + 8, z + 5, 11, ForgeDirection.NORTH, cell);
//      placeBlock(world, x + 5, y + 8, z + 4, 11, ForgeDirection.WEST, cell);
//      placeBlock(world, x + 12, y + 3, z + 5, 10, ForgeDirection.NORTH, cell);
//      placeBlock(world, x + 11, y + 3, z + 5, 10, ForgeDirection.NORTH, cell);
//      placeBlock(world, x + 11, y + 3, z + 4, 10, ForgeDirection.EAST, cell);
//      placeBlock(world, x + 12, y + 8, z + 5, 11, ForgeDirection.NORTH, cell);
//      placeBlock(world, x + 11, y + 8, z + 5, 11, ForgeDirection.NORTH, cell);
//      placeBlock(world, x + 11, y + 8, z + 4, 11, ForgeDirection.EAST, cell);
//      placeBlock(world, x + 5, y + 3, z + 11, 10, ForgeDirection.SOUTH, cell);
//      placeBlock(world, x + 4, y + 3, z + 11, 10, ForgeDirection.SOUTH, cell);
//      placeBlock(world, x + 5, y + 3, z + 12, 10, ForgeDirection.WEST, cell);
//      placeBlock(world, x + 5, y + 8, z + 11, 11, ForgeDirection.SOUTH, cell);
//      placeBlock(world, x + 4, y + 8, z + 11, 11, ForgeDirection.SOUTH, cell);
//      placeBlock(world, x + 5, y + 8, z + 12, 11, ForgeDirection.WEST, cell);
//      placeBlock(world, x + 12, y + 3, z + 11, 10, ForgeDirection.SOUTH, cell);
//      placeBlock(world, x + 11, y + 3, z + 11, 10, ForgeDirection.SOUTH, cell);
//      placeBlock(world, x + 11, y + 3, z + 12, 10, ForgeDirection.EAST, cell);
//      placeBlock(world, x + 12, y + 8, z + 11, 11, ForgeDirection.SOUTH, cell);
//      placeBlock(world, x + 11, y + 8, z + 11, 11, ForgeDirection.SOUTH, cell);
//      placeBlock(world, x + 11, y + 8, z + 12, 11, ForgeDirection.EAST, cell);

      //generated text with java
      {
         placeBlock(world, x + 1, y , z + 1, 1, cell);
         placeBlock(world, x + 1, y + 1, z + 1, 1, cell);
         placeBlock(world, x + 1, y + 2, z + 1, 1, cell);
         placeBlock(world, x + 1, y + 3, z + 1, 1, cell);
         placeBlock(world, x + 1, y + 4, z + 1, 1, cell);
         placeBlock(world, x + 1, y + 5, z + 1, 1, cell);
         placeBlock(world, x + 1, y + 6, z + 1, 1, cell);
         placeBlock(world, x + 1, y + 7, z + 1, 1, cell);
         placeBlock(world, x + 1, y + 8, z + 1, 1, cell);
         placeBlock(world, x + 1, y + 9, z + 1, 1, cell);
         placeBlock(world, x + 1, y + 10, z + 1, 1, cell);
         placeBlock(world, x + 1, y + 11, z + 1, 1, cell);
         placeBlock(world, x + 1, y + 12, z + 1, 1, cell);
         placeBlock(world, x + 1, y , z + 2, 1, cell);
         placeBlock(world, x + 1, y + 1, z + 2, 1, cell);
         placeBlock(world, x + 1, y + 2, z + 2, 1, cell);
         placeBlock(world, x + 1, y + 3, z + 2, 1, cell);
         placeBlock(world, x + 1, y + 4, z + 2, 1, cell);
         placeBlock(world, x + 1, y + 5, z + 2, 1, cell);
         placeBlock(world, x + 1, y + 6, z + 2, 1, cell);
         placeBlock(world, x + 1, y + 7, z + 2, 1, cell);
         placeBlock(world, x + 1, y + 8, z + 2, 1, cell);
         placeBlock(world, x + 1, y + 9, z + 2, 1, cell);
         placeBlock(world, x + 1, y + 10, z + 2, 1, cell);
         placeBlock(world, x + 1, y + 11, z + 2, 1, cell);
         placeBlock(world, x + 1, y + 12, z + 2, 1, cell);
         placeBlock(world, x + 1, y , z + 3, 1, cell);
         placeBlock(world, x + 1, y + 1, z + 3, 1, cell);
         placeBlock(world, x + 1, y + 2, z + 3, 1, cell);
         placeBlock(world, x + 1, y + 3, z + 3, 1, cell);
         placeBlock(world, x + 1, y + 4, z + 3, 1, cell);
         placeBlock(world, x + 1, y + 5, z + 3, 1, cell);
         placeBlock(world, x + 1, y + 6, z + 3, 1, cell);
         placeBlock(world, x + 1, y + 7, z + 3, 1, cell);
         placeBlock(world, x + 1, y + 8, z + 3, 1, cell);
         placeBlock(world, x + 1, y + 9, z + 3, 1, cell);
         placeBlock(world, x + 1, y + 10, z + 3, 1, cell);
         placeBlock(world, x + 1, y + 11, z + 3, 1, cell);
         placeBlock(world, x + 1, y + 12, z + 3, 1, cell);
         placeBlock(world, x + 1, y , z + 4, 1, cell);
         placeBlock(world, x + 1, y + 1, z + 4, 1, cell);
         placeBlock(world, x + 1, y + 2, z + 4, 1, cell);
         placeBlock(world, x + 1, y + 3, z + 4, 1, cell);
         placeBlock(world, x + 1, y + 4, z + 4, 1, cell);
         placeBlock(world, x + 1, y + 5, z + 4, 1, cell);
         placeBlock(world, x + 1, y + 6, z + 4, 1, cell);
         placeBlock(world, x + 1, y + 7, z + 4, 1, cell);
         placeBlock(world, x + 1, y + 8, z + 4, 1, cell);
         placeBlock(world, x + 1, y + 9, z + 4, 1, cell);
         placeBlock(world, x + 1, y + 10, z + 4, 1, cell);
         placeBlock(world, x + 1, y + 11, z + 4, 1, cell);
         placeBlock(world, x + 1, y + 12, z + 4, 1, cell);
         placeBlock(world, x + 1, y , z + 5, 1, cell);
         placeBlock(world, x + 1, y + 1, z + 5, 1, cell);
         placeBlock(world, x + 1, y + 2, z + 5, 1, cell);
         placeBlock(world, x + 1, y + 3, z + 5, 1, cell);
         placeBlock(world, x + 1, y + 4, z + 5, 1, cell);
         placeBlock(world, x + 1, y + 5, z + 5, 1, cell);
         placeBlock(world, x + 1, y + 6, z + 5, 1, cell);
         placeBlock(world, x + 1, y + 7, z + 5, 1, cell);
         placeBlock(world, x + 1, y + 8, z + 5, 1, cell);
         placeBlock(world, x + 1, y + 9, z + 5, 1, cell);
         placeBlock(world, x + 1, y + 10, z + 5, 1, cell);
         placeBlock(world, x + 1, y + 11, z + 5, 1, cell);
         placeBlock(world, x + 1, y + 12, z + 5, 1, cell);
         placeBlock(world, x + 1, y , z + 6, 1, cell);
         placeBlock(world, x + 1, y + 1, z + 6, 1, cell);
         placeBlock(world, x + 1, y + 2, z + 6, 1, cell);
         placeBlock(world, x + 1, y + 3, z + 6, 1, cell);
         placeBlock(world, x + 1, y + 4, z + 6, 1, cell);
         placeBlock(world, x + 1, y + 5, z + 6, 1, cell);
         placeBlock(world, x + 1, y + 6, z + 6, 1, cell);
         placeBlock(world, x + 1, y + 7, z + 6, 1, cell);
         placeBlock(world, x + 1, y + 8, z + 6, 1, cell);
         placeBlock(world, x + 1, y + 9, z + 6, 1, cell);
         placeBlock(world, x + 1, y + 10, z + 6, 1, cell);
         placeBlock(world, x + 1, y + 11, z + 6, 1, cell);
         placeBlock(world, x + 1, y + 12, z + 6, 1, cell);
         placeBlock(world, x + 1, y , z + 7, 1, cell);
         placeBlock(world, x + 1, y + 1, z + 7, 1, cell);
         placeBlock(world, x + 1, y + 2, z + 7, 1, cell);
         placeBlock(world, x + 1, y + 3, z + 7, 1, cell);
         placeBlock(world, x + 1, y + 4, z + 7, 1, cell);
         placeBlock(world, x + 1, y + 5, z + 7, 1, cell);
         placeBlock(world, x + 1, y + 6, z + 7, 1, cell);
         placeBlock(world, x + 1, y + 7, z + 7, 1, cell);
         placeBlock(world, x + 1, y + 8, z + 7, 1, cell);
         placeBlock(world, x + 1, y + 9, z + 7, 1, cell);
         placeBlock(world, x + 1, y + 10, z + 7, 1, cell);
         placeBlock(world, x + 1, y + 11, z + 7, 1, cell);
         placeBlock(world, x + 1, y + 12, z + 7, 1, cell);
         placeBlock(world, x + 1, y , z + 8, 1, cell);
         placeBlock(world, x + 1, y + 1, z + 8, 1, cell);
         placeBlock(world, x + 1, y + 2, z + 8, 1, cell);
         placeBlock(world, x + 1, y + 3, z + 8, 1, cell);
         placeBlock(world, x + 1, y + 4, z + 8, 1, cell);
         placeBlock(world, x + 1, y + 5, z + 8, 1, cell);
         placeBlock(world, x + 1, y + 6, z + 8, 1, cell);
         placeBlock(world, x + 1, y + 7, z + 8, 1, cell);
         placeBlock(world, x + 1, y + 8, z + 8, 1, cell);
         placeBlock(world, x + 1, y + 9, z + 8, 1, cell);
         placeBlock(world, x + 1, y + 10, z + 8, 1, cell);
         placeBlock(world, x + 1, y + 11, z + 8, 1, cell);
         placeBlock(world, x + 1, y + 12, z + 8, 1, cell);
         placeBlock(world, x + 1, y , z + 9, 1, cell);
         placeBlock(world, x + 1, y + 1, z + 9, 1, cell);
         placeBlock(world, x + 1, y + 2, z + 9, 1, cell);
         placeBlock(world, x + 1, y + 3, z + 9, 1, cell);
         placeBlock(world, x + 1, y + 4, z + 9, 1, cell);
         placeBlock(world, x + 1, y + 5, z + 9, 1, cell);
         placeBlock(world, x + 1, y + 6, z + 9, 1, cell);
         placeBlock(world, x + 1, y + 7, z + 9, 1, cell);
         placeBlock(world, x + 1, y + 8, z + 9, 1, cell);
         placeBlock(world, x + 1, y + 9, z + 9, 1, cell);
         placeBlock(world, x + 1, y + 10, z + 9, 1, cell);
         placeBlock(world, x + 1, y + 11, z + 9, 1, cell);
         placeBlock(world, x + 1, y + 12, z + 9, 1, cell);
         placeBlock(world, x + 1, y , z + 10, 1, cell);
         placeBlock(world, x + 1, y + 1, z + 10, 1, cell);
         placeBlock(world, x + 1, y + 2, z + 10, 1, cell);
         placeBlock(world, x + 1, y + 3, z + 10, 1, cell);
         placeBlock(world, x + 1, y + 4, z + 10, 1, cell);
         placeBlock(world, x + 1, y + 5, z + 10, 1, cell);
         placeBlock(world, x + 1, y + 6, z + 10, 1, cell);
         placeBlock(world, x + 1, y + 7, z + 10, 1, cell);
         placeBlock(world, x + 1, y + 8, z + 10, 1, cell);
         placeBlock(world, x + 1, y + 9, z + 10, 1, cell);
         placeBlock(world, x + 1, y + 10, z + 10, 1, cell);
         placeBlock(world, x + 1, y + 11, z + 10, 1, cell);
         placeBlock(world, x + 1, y + 12, z + 10, 1, cell);
         placeBlock(world, x + 1, y , z + 11, 1, cell);
         placeBlock(world, x + 1, y + 1, z + 11, 1, cell);
         placeBlock(world, x + 1, y + 2, z + 11, 1, cell);
         placeBlock(world, x + 1, y + 3, z + 11, 1, cell);
         placeBlock(world, x + 1, y + 4, z + 11, 1, cell);
         placeBlock(world, x + 1, y + 5, z + 11, 1, cell);
         placeBlock(world, x + 1, y + 6, z + 11, 1, cell);
         placeBlock(world, x + 1, y + 7, z + 11, 1, cell);
         placeBlock(world, x + 1, y + 8, z + 11, 1, cell);
         placeBlock(world, x + 1, y + 9, z + 11, 1, cell);
         placeBlock(world, x + 1, y + 10, z + 11, 1, cell);
         placeBlock(world, x + 1, y + 11, z + 11, 1, cell);
         placeBlock(world, x + 1, y + 12, z + 11, 1, cell);
         placeBlock(world, x + 1, y , z + 12, 1, cell);
         placeBlock(world, x + 1, y + 1, z + 12, 1, cell);
         placeBlock(world, x + 1, y + 2, z + 12, 1, cell);
         placeBlock(world, x + 1, y + 3, z + 12, 1, cell);
         placeBlock(world, x + 1, y + 4, z + 12, 1, cell);
         placeBlock(world, x + 1, y + 5, z + 12, 1, cell);
         placeBlock(world, x + 1, y + 6, z + 12, 1, cell);
         placeBlock(world, x + 1, y + 7, z + 12, 1, cell);
         placeBlock(world, x + 1, y + 8, z + 12, 1, cell);
         placeBlock(world, x + 1, y + 9, z + 12, 1, cell);
         placeBlock(world, x + 1, y + 10, z + 12, 1, cell);
         placeBlock(world, x + 1, y + 11, z + 12, 1, cell);
         placeBlock(world, x + 1, y + 12, z + 12, 1, cell);
         placeBlock(world, x + 1, y , z + 13, 1, cell);
         placeBlock(world, x + 1, y + 1, z + 13, 1, cell);
         placeBlock(world, x + 1, y + 2, z + 13, 1, cell);
         placeBlock(world, x + 1, y + 3, z + 13, 1, cell);
         placeBlock(world, x + 1, y + 4, z + 13, 1, cell);
         placeBlock(world, x + 1, y + 5, z + 13, 1, cell);
         placeBlock(world, x + 1, y + 6, z + 13, 1, cell);
         placeBlock(world, x + 1, y + 7, z + 13, 1, cell);
         placeBlock(world, x + 1, y + 8, z + 13, 1, cell);
         placeBlock(world, x + 1, y + 9, z + 13, 1, cell);
         placeBlock(world, x + 1, y + 10, z + 13, 1, cell);
         placeBlock(world, x + 1, y + 11, z + 13, 1, cell);
         placeBlock(world, x + 1, y + 12, z + 13, 1, cell);
         placeBlock(world, x + 1, y , z + 14, 1, cell);
         placeBlock(world, x + 1, y + 1, z + 14, 1, cell);
         placeBlock(world, x + 1, y + 2, z + 14, 1, cell);
         placeBlock(world, x + 1, y + 3, z + 14, 1, cell);
         placeBlock(world, x + 1, y + 4, z + 14, 1, cell);
         placeBlock(world, x + 1, y + 5, z + 14, 1, cell);
         placeBlock(world, x + 1, y + 6, z + 14, 1, cell);
         placeBlock(world, x + 1, y + 7, z + 14, 1, cell);
         placeBlock(world, x + 1, y + 8, z + 14, 1, cell);
         placeBlock(world, x + 1, y + 9, z + 14, 1, cell);
         placeBlock(world, x + 1, y + 10, z + 14, 1, cell);
         placeBlock(world, x + 1, y + 11, z + 14, 1, cell);
         placeBlock(world, x + 1, y + 12, z + 14, 1, cell);
         placeBlock(world, x + 1, y , z + 15, 1, cell);
         placeBlock(world, x + 1, y + 1, z + 15, 1, cell);
         placeBlock(world, x + 1, y + 2, z + 15, 1, cell);
         placeBlock(world, x + 1, y + 3, z + 15, 1, cell);
         placeBlock(world, x + 1, y + 4, z + 15, 1, cell);
         placeBlock(world, x + 1, y + 5, z + 15, 1, cell);
         placeBlock(world, x + 1, y + 6, z + 15, 1, cell);
         placeBlock(world, x + 1, y + 7, z + 15, 1, cell);
         placeBlock(world, x + 1, y + 8, z + 15, 1, cell);
         placeBlock(world, x + 1, y + 9, z + 15, 1, cell);
         placeBlock(world, x + 1, y + 10, z + 15, 1, cell);
         placeBlock(world, x + 1, y + 11, z + 15, 1, cell);
         placeBlock(world, x + 1, y + 12, z + 15, 1, cell);
         placeBlock(world, x + 2, y , z + 1, 1, cell);
         placeBlock(world, x + 2, y + 1, z + 1, 1, cell);
         placeBlock(world, x + 2, y + 2, z + 1, 1, cell);
         placeBlock(world, x + 2, y + 3, z + 1, 1, cell);
         placeBlock(world, x + 2, y + 4, z + 1, 1, cell);
         placeBlock(world, x + 2, y + 5, z + 1, 1, cell);
         placeBlock(world, x + 2, y + 6, z + 1, 1, cell);
         placeBlock(world, x + 2, y + 7, z + 1, 1, cell);
         placeBlock(world, x + 2, y + 8, z + 1, 1, cell);
         placeBlock(world, x + 2, y + 9, z + 1, 1, cell);
         placeBlock(world, x + 2, y + 10, z + 1, 1, cell);
         placeBlock(world, x + 2, y + 11, z + 1, 1, cell);
         placeBlock(world, x + 2, y + 12, z + 1, 1, cell);
         placeBlock(world, x + 2, y , z + 15, 1, cell);
         placeBlock(world, x + 2, y + 1, z + 15, 1, cell);
         placeBlock(world, x + 2, y + 2, z + 15, 1, cell);
         placeBlock(world, x + 2, y + 3, z + 15, 1, cell);
         placeBlock(world, x + 2, y + 4, z + 15, 1, cell);
         placeBlock(world, x + 2, y + 5, z + 15, 1, cell);
         placeBlock(world, x + 2, y + 6, z + 15, 1, cell);
         placeBlock(world, x + 2, y + 7, z + 15, 1, cell);
         placeBlock(world, x + 2, y + 8, z + 15, 1, cell);
         placeBlock(world, x + 2, y + 9, z + 15, 1, cell);
         placeBlock(world, x + 2, y + 10, z + 15, 1, cell);
         placeBlock(world, x + 2, y + 11, z + 15, 1, cell);
         placeBlock(world, x + 2, y + 12, z + 15, 1, cell);
         placeBlock(world, x + 3, y , z + 1, 1, cell);
         placeBlock(world, x + 3, y + 1, z + 1, 1, cell);
         placeBlock(world, x + 3, y + 2, z + 1, 1, cell);
         placeBlock(world, x + 3, y + 3, z + 1, 1, cell);
         placeBlock(world, x + 3, y + 4, z + 1, 1, cell);
         placeBlock(world, x + 3, y + 5, z + 1, 1, cell);
         placeBlock(world, x + 3, y + 6, z + 1, 1, cell);
         placeBlock(world, x + 3, y + 7, z + 1, 1, cell);
         placeBlock(world, x + 3, y + 8, z + 1, 1, cell);
         placeBlock(world, x + 3, y + 9, z + 1, 1, cell);
         placeBlock(world, x + 3, y + 10, z + 1, 1, cell);
         placeBlock(world, x + 3, y + 11, z + 1, 1, cell);
         placeBlock(world, x + 3, y + 12, z + 1, 1, cell);
         placeBlock(world, x + 3, y , z + 15, 1, cell);
         placeBlock(world, x + 3, y + 1, z + 15, 1, cell);
         placeBlock(world, x + 3, y + 2, z + 15, 1, cell);
         placeBlock(world, x + 3, y + 3, z + 15, 1, cell);
         placeBlock(world, x + 3, y + 4, z + 15, 1, cell);
         placeBlock(world, x + 3, y + 5, z + 15, 1, cell);
         placeBlock(world, x + 3, y + 6, z + 15, 1, cell);
         placeBlock(world, x + 3, y + 7, z + 15, 1, cell);
         placeBlock(world, x + 3, y + 8, z + 15, 1, cell);
         placeBlock(world, x + 3, y + 9, z + 15, 1, cell);
         placeBlock(world, x + 3, y + 10, z + 15, 1, cell);
         placeBlock(world, x + 3, y + 11, z + 15, 1, cell);
         placeBlock(world, x + 3, y + 12, z + 15, 1, cell);
         placeBlock(world, x + 4, y , z + 1, 1, cell);
         placeBlock(world, x + 4, y + 1, z + 1, 1, cell);
         placeBlock(world, x + 4, y + 2, z + 1, 1, cell);
         placeBlock(world, x + 4, y + 3, z + 1, 1, cell);
         placeBlock(world, x + 4, y + 4, z + 1, 1, cell);
         placeBlock(world, x + 4, y + 5, z + 1, 1, cell);
         placeBlock(world, x + 4, y + 6, z + 1, 1, cell);
         placeBlock(world, x + 4, y + 7, z + 1, 1, cell);
         placeBlock(world, x + 4, y + 8, z + 1, 1, cell);
         placeBlock(world, x + 4, y + 9, z + 1, 1, cell);
         placeBlock(world, x + 4, y + 10, z + 1, 1, cell);
         placeBlock(world, x + 4, y + 11, z + 1, 1, cell);
         placeBlock(world, x + 4, y + 12, z + 1, 1, cell);
         placeBlock(world, x + 4, y , z + 15, 1, cell);
         placeBlock(world, x + 4, y + 1, z + 15, 1, cell);
         placeBlock(world, x + 4, y + 2, z + 15, 1, cell);
         placeBlock(world, x + 4, y + 3, z + 15, 1, cell);
         placeBlock(world, x + 4, y + 4, z + 15, 1, cell);
         placeBlock(world, x + 4, y + 5, z + 15, 1, cell);
         placeBlock(world, x + 4, y + 6, z + 15, 1, cell);
         placeBlock(world, x + 4, y + 7, z + 15, 1, cell);
         placeBlock(world, x + 4, y + 8, z + 15, 1, cell);
         placeBlock(world, x + 4, y + 9, z + 15, 1, cell);
         placeBlock(world, x + 4, y + 10, z + 15, 1, cell);
         placeBlock(world, x + 4, y + 11, z + 15, 1, cell);
         placeBlock(world, x + 4, y + 12, z + 15, 1, cell);
         placeBlock(world, x + 5, y , z + 1, 1, cell);
         placeBlock(world, x + 5, y + 1, z + 1, 1, cell);
         placeBlock(world, x + 5, y + 2, z + 1, 1, cell);
         placeBlock(world, x + 5, y + 3, z + 1, 1, cell);
         placeBlock(world, x + 5, y + 4, z + 1, 1, cell);
         placeBlock(world, x + 5, y + 5, z + 1, 1, cell);
         placeBlock(world, x + 5, y + 6, z + 1, 1, cell);
         placeBlock(world, x + 5, y + 7, z + 1, 1, cell);
         placeBlock(world, x + 5, y + 8, z + 1, 1, cell);
         placeBlock(world, x + 5, y + 9, z + 1, 1, cell);
         placeBlock(world, x + 5, y + 10, z + 1, 1, cell);
         placeBlock(world, x + 5, y + 11, z + 1, 1, cell);
         placeBlock(world, x + 5, y + 12, z + 1, 1, cell);
         placeBlock(world, x + 5, y , z + 15, 1, cell);
         placeBlock(world, x + 5, y + 1, z + 15, 1, cell);
         placeBlock(world, x + 5, y + 2, z + 15, 1, cell);
         placeBlock(world, x + 5, y + 3, z + 15, 1, cell);
         placeBlock(world, x + 5, y + 4, z + 15, 1, cell);
         placeBlock(world, x + 5, y + 5, z + 15, 1, cell);
         placeBlock(world, x + 5, y + 6, z + 15, 1, cell);
         placeBlock(world, x + 5, y + 7, z + 15, 1, cell);
         placeBlock(world, x + 5, y + 8, z + 15, 1, cell);
         placeBlock(world, x + 5, y + 9, z + 15, 1, cell);
         placeBlock(world, x + 5, y + 10, z + 15, 1, cell);
         placeBlock(world, x + 5, y + 11, z + 15, 1, cell);
         placeBlock(world, x + 5, y + 12, z + 15, 1, cell);
         placeBlock(world, x + 6, y , z + 1, 1, cell);
         placeBlock(world, x + 6, y + 1, z + 1, 1, cell);
         placeBlock(world, x + 6, y + 2, z + 1, 1, cell);
         placeBlock(world, x + 6, y + 3, z + 1, 1, cell);
         placeBlock(world, x + 6, y + 4, z + 1, 1, cell);
         placeBlock(world, x + 6, y + 5, z + 1, 1, cell);
         placeBlock(world, x + 6, y + 6, z + 1, 1, cell);
         placeBlock(world, x + 6, y + 7, z + 1, 1, cell);
         placeBlock(world, x + 6, y + 8, z + 1, 1, cell);
         placeBlock(world, x + 6, y + 9, z + 1, 1, cell);
         placeBlock(world, x + 6, y + 10, z + 1, 1, cell);
         placeBlock(world, x + 6, y + 11, z + 1, 1, cell);
         placeBlock(world, x + 6, y + 12, z + 1, 1, cell);
         placeBlock(world, x + 6, y , z + 15, 1, cell);
         placeBlock(world, x + 6, y + 1, z + 15, 1, cell);
         placeBlock(world, x + 6, y + 2, z + 15, 1, cell);
         placeBlock(world, x + 6, y + 3, z + 15, 1, cell);
         placeBlock(world, x + 6, y + 4, z + 15, 1, cell);
         placeBlock(world, x + 6, y + 5, z + 15, 1, cell);
         placeBlock(world, x + 6, y + 6, z + 15, 1, cell);
         placeBlock(world, x + 6, y + 7, z + 15, 1, cell);
         placeBlock(world, x + 6, y + 8, z + 15, 1, cell);
         placeBlock(world, x + 6, y + 9, z + 15, 1, cell);
         placeBlock(world, x + 6, y + 10, z + 15, 1, cell);
         placeBlock(world, x + 6, y + 11, z + 15, 1, cell);
         placeBlock(world, x + 6, y + 12, z + 15, 1, cell);
         placeBlock(world, x + 7, y , z + 1, 1, cell);
         placeBlock(world, x + 7, y + 1, z + 1, 1, cell);
         placeBlock(world, x + 7, y + 2, z + 1, 1, cell);
         placeBlock(world, x + 7, y + 3, z + 1, 1, cell);
         placeBlock(world, x + 7, y + 4, z + 1, 1, cell);
         placeBlock(world, x + 7, y + 5, z + 1, 1, cell);
         placeBlock(world, x + 7, y + 6, z + 1, 1, cell);
         placeBlock(world, x + 7, y + 7, z + 1, 1, cell);
         placeBlock(world, x + 7, y + 8, z + 1, 1, cell);
         placeBlock(world, x + 7, y + 9, z + 1, 1, cell);
         placeBlock(world, x + 7, y + 10, z + 1, 1, cell);
         placeBlock(world, x + 7, y + 11, z + 1, 1, cell);
         placeBlock(world, x + 7, y + 12, z + 1, 1, cell);
         placeBlock(world, x + 7, y , z + 15, 1, cell);
         placeBlock(world, x + 7, y + 1, z + 15, 1, cell);
         placeBlock(world, x + 7, y + 2, z + 15, 1, cell);
         placeBlock(world, x + 7, y + 3, z + 15, 1, cell);
         placeBlock(world, x + 7, y + 4, z + 15, 1, cell);
         placeBlock(world, x + 7, y + 5, z + 15, 1, cell);
         placeBlock(world, x + 7, y + 6, z + 15, 1, cell);
         placeBlock(world, x + 7, y + 7, z + 15, 1, cell);
         placeBlock(world, x + 7, y + 8, z + 15, 1, cell);
         placeBlock(world, x + 7, y + 9, z + 15, 1, cell);
         placeBlock(world, x + 7, y + 10, z + 15, 1, cell);
         placeBlock(world, x + 7, y + 11, z + 15, 1, cell);
         placeBlock(world, x + 7, y + 12, z + 15, 1, cell);
         placeBlock(world, x + 8, y , z + 1, 1, cell);
         placeBlock(world, x + 8, y + 1, z + 1, 1, cell);
         placeBlock(world, x + 8, y + 2, z + 1, 1, cell);
         placeBlock(world, x + 8, y + 3, z + 1, 1, cell);
         placeBlock(world, x + 8, y + 4, z + 1, 1, cell);
         placeBlock(world, x + 8, y + 5, z + 1, 1, cell);
         placeBlock(world, x + 8, y + 6, z + 1, 1, cell);
         placeBlock(world, x + 8, y + 7, z + 1, 1, cell);
         placeBlock(world, x + 8, y + 8, z + 1, 1, cell);
         placeBlock(world, x + 8, y + 9, z + 1, 1, cell);
         placeBlock(world, x + 8, y + 10, z + 1, 1, cell);
         placeBlock(world, x + 8, y + 11, z + 1, 1, cell);
         placeBlock(world, x + 8, y + 12, z + 1, 1, cell);
         placeBlock(world, x + 8, y , z + 15, 1, cell);
         placeBlock(world, x + 8, y + 1, z + 15, 1, cell);
         placeBlock(world, x + 8, y + 2, z + 15, 1, cell);
         placeBlock(world, x + 8, y + 3, z + 15, 1, cell);
         placeBlock(world, x + 8, y + 4, z + 15, 1, cell);
         placeBlock(world, x + 8, y + 5, z + 15, 1, cell);
         placeBlock(world, x + 8, y + 6, z + 15, 1, cell);
         placeBlock(world, x + 8, y + 7, z + 15, 1, cell);
         placeBlock(world, x + 8, y + 8, z + 15, 1, cell);
         placeBlock(world, x + 8, y + 9, z + 15, 1, cell);
         placeBlock(world, x + 8, y + 10, z + 15, 1, cell);
         placeBlock(world, x + 8, y + 11, z + 15, 1, cell);
         placeBlock(world, x + 8, y + 12, z + 15, 1, cell);
         placeBlock(world, x + 9, y , z + 1, 1, cell);
         placeBlock(world, x + 9, y + 1, z + 1, 1, cell);
         placeBlock(world, x + 9, y + 2, z + 1, 1, cell);
         placeBlock(world, x + 9, y + 3, z + 1, 1, cell);
         placeBlock(world, x + 9, y + 4, z + 1, 1, cell);
         placeBlock(world, x + 9, y + 5, z + 1, 1, cell);
         placeBlock(world, x + 9, y + 6, z + 1, 1, cell);
         placeBlock(world, x + 9, y + 7, z + 1, 1, cell);
         placeBlock(world, x + 9, y + 8, z + 1, 1, cell);
         placeBlock(world, x + 9, y + 9, z + 1, 1, cell);
         placeBlock(world, x + 9, y + 10, z + 1, 1, cell);
         placeBlock(world, x + 9, y + 11, z + 1, 1, cell);
         placeBlock(world, x + 9, y + 12, z + 1, 1, cell);
         placeBlock(world, x + 9, y , z + 15, 1, cell);
         placeBlock(world, x + 9, y + 1, z + 15, 1, cell);
         placeBlock(world, x + 9, y + 2, z + 15, 1, cell);
         placeBlock(world, x + 9, y + 3, z + 15, 1, cell);
         placeBlock(world, x + 9, y + 4, z + 15, 1, cell);
         placeBlock(world, x + 9, y + 5, z + 15, 1, cell);
         placeBlock(world, x + 9, y + 6, z + 15, 1, cell);
         placeBlock(world, x + 9, y + 7, z + 15, 1, cell);
         placeBlock(world, x + 9, y + 8, z + 15, 1, cell);
         placeBlock(world, x + 9, y + 9, z + 15, 1, cell);
         placeBlock(world, x + 9, y + 10, z + 15, 1, cell);
         placeBlock(world, x + 9, y + 11, z + 15, 1, cell);
         placeBlock(world, x + 9, y + 12, z + 15, 1, cell);
         placeBlock(world, x + 10, y , z + 1, 1, cell);
         placeBlock(world, x + 10, y + 1, z + 1, 1, cell);
         placeBlock(world, x + 10, y + 2, z + 1, 1, cell);
         placeBlock(world, x + 10, y + 3, z + 1, 1, cell);
         placeBlock(world, x + 10, y + 4, z + 1, 1, cell);
         placeBlock(world, x + 10, y + 5, z + 1, 1, cell);
         placeBlock(world, x + 10, y + 6, z + 1, 1, cell);
         placeBlock(world, x + 10, y + 7, z + 1, 1, cell);
         placeBlock(world, x + 10, y + 8, z + 1, 1, cell);
         placeBlock(world, x + 10, y + 9, z + 1, 1, cell);
         placeBlock(world, x + 10, y + 10, z + 1, 1, cell);
         placeBlock(world, x + 10, y + 11, z + 1, 1, cell);
         placeBlock(world, x + 10, y + 12, z + 1, 1, cell);
         placeBlock(world, x + 10, y , z + 15, 1, cell);
         placeBlock(world, x + 10, y + 1, z + 15, 1, cell);
         placeBlock(world, x + 10, y + 2, z + 15, 1, cell);
         placeBlock(world, x + 10, y + 3, z + 15, 1, cell);
         placeBlock(world, x + 10, y + 4, z + 15, 1, cell);
         placeBlock(world, x + 10, y + 5, z + 15, 1, cell);
         placeBlock(world, x + 10, y + 6, z + 15, 1, cell);
         placeBlock(world, x + 10, y + 7, z + 15, 1, cell);
         placeBlock(world, x + 10, y + 8, z + 15, 1, cell);
         placeBlock(world, x + 10, y + 9, z + 15, 1, cell);
         placeBlock(world, x + 10, y + 10, z + 15, 1, cell);
         placeBlock(world, x + 10, y + 11, z + 15, 1, cell);
         placeBlock(world, x + 10, y + 12, z + 15, 1, cell);
         placeBlock(world, x + 11, y , z + 1, 1, cell);
         placeBlock(world, x + 11, y + 1, z + 1, 1, cell);
         placeBlock(world, x + 11, y + 2, z + 1, 1, cell);
         placeBlock(world, x + 11, y + 3, z + 1, 1, cell);
         placeBlock(world, x + 11, y + 4, z + 1, 1, cell);
         placeBlock(world, x + 11, y + 5, z + 1, 1, cell);
         placeBlock(world, x + 11, y + 6, z + 1, 1, cell);
         placeBlock(world, x + 11, y + 7, z + 1, 1, cell);
         placeBlock(world, x + 11, y + 8, z + 1, 1, cell);
         placeBlock(world, x + 11, y + 9, z + 1, 1, cell);
         placeBlock(world, x + 11, y + 10, z + 1, 1, cell);
         placeBlock(world, x + 11, y + 11, z + 1, 1, cell);
         placeBlock(world, x + 11, y + 12, z + 1, 1, cell);
         placeBlock(world, x + 11, y , z + 15, 1, cell);
         placeBlock(world, x + 11, y + 1, z + 15, 1, cell);
         placeBlock(world, x + 11, y + 2, z + 15, 1, cell);
         placeBlock(world, x + 11, y + 3, z + 15, 1, cell);
         placeBlock(world, x + 11, y + 4, z + 15, 1, cell);
         placeBlock(world, x + 11, y + 5, z + 15, 1, cell);
         placeBlock(world, x + 11, y + 6, z + 15, 1, cell);
         placeBlock(world, x + 11, y + 7, z + 15, 1, cell);
         placeBlock(world, x + 11, y + 8, z + 15, 1, cell);
         placeBlock(world, x + 11, y + 9, z + 15, 1, cell);
         placeBlock(world, x + 11, y + 10, z + 15, 1, cell);
         placeBlock(world, x + 11, y + 11, z + 15, 1, cell);
         placeBlock(world, x + 11, y + 12, z + 15, 1, cell);
         placeBlock(world, x + 12, y , z + 1, 1, cell);
         placeBlock(world, x + 12, y + 1, z + 1, 1, cell);
         placeBlock(world, x + 12, y + 2, z + 1, 1, cell);
         placeBlock(world, x + 12, y + 3, z + 1, 1, cell);
         placeBlock(world, x + 12, y + 4, z + 1, 1, cell);
         placeBlock(world, x + 12, y + 5, z + 1, 1, cell);
         placeBlock(world, x + 12, y + 6, z + 1, 1, cell);
         placeBlock(world, x + 12, y + 7, z + 1, 1, cell);
         placeBlock(world, x + 12, y + 8, z + 1, 1, cell);
         placeBlock(world, x + 12, y + 9, z + 1, 1, cell);
         placeBlock(world, x + 12, y + 10, z + 1, 1, cell);
         placeBlock(world, x + 12, y + 11, z + 1, 1, cell);
         placeBlock(world, x + 12, y + 12, z + 1, 1, cell);
         placeBlock(world, x + 12, y , z + 15, 1, cell);
         placeBlock(world, x + 12, y + 1, z + 15, 1, cell);
         placeBlock(world, x + 12, y + 2, z + 15, 1, cell);
         placeBlock(world, x + 12, y + 3, z + 15, 1, cell);
         placeBlock(world, x + 12, y + 4, z + 15, 1, cell);
         placeBlock(world, x + 12, y + 5, z + 15, 1, cell);
         placeBlock(world, x + 12, y + 6, z + 15, 1, cell);
         placeBlock(world, x + 12, y + 7, z + 15, 1, cell);
         placeBlock(world, x + 12, y + 8, z + 15, 1, cell);
         placeBlock(world, x + 12, y + 9, z + 15, 1, cell);
         placeBlock(world, x + 12, y + 10, z + 15, 1, cell);
         placeBlock(world, x + 12, y + 11, z + 15, 1, cell);
         placeBlock(world, x + 12, y + 12, z + 15, 1, cell);
         placeBlock(world, x + 13, y , z + 1, 1, cell);
         placeBlock(world, x + 13, y + 1, z + 1, 1, cell);
         placeBlock(world, x + 13, y + 2, z + 1, 1, cell);
         placeBlock(world, x + 13, y + 3, z + 1, 1, cell);
         placeBlock(world, x + 13, y + 4, z + 1, 1, cell);
         placeBlock(world, x + 13, y + 5, z + 1, 1, cell);
         placeBlock(world, x + 13, y + 6, z + 1, 1, cell);
         placeBlock(world, x + 13, y + 7, z + 1, 1, cell);
         placeBlock(world, x + 13, y + 8, z + 1, 1, cell);
         placeBlock(world, x + 13, y + 9, z + 1, 1, cell);
         placeBlock(world, x + 13, y + 10, z + 1, 1, cell);
         placeBlock(world, x + 13, y + 11, z + 1, 1, cell);
         placeBlock(world, x + 13, y + 12, z + 1, 1, cell);
         placeBlock(world, x + 13, y , z + 15, 1, cell);
         placeBlock(world, x + 13, y + 1, z + 15, 1, cell);
         placeBlock(world, x + 13, y + 2, z + 15, 1, cell);
         placeBlock(world, x + 13, y + 3, z + 15, 1, cell);
         placeBlock(world, x + 13, y + 4, z + 15, 1, cell);
         placeBlock(world, x + 13, y + 5, z + 15, 1, cell);
         placeBlock(world, x + 13, y + 6, z + 15, 1, cell);
         placeBlock(world, x + 13, y + 7, z + 15, 1, cell);
         placeBlock(world, x + 13, y + 8, z + 15, 1, cell);
         placeBlock(world, x + 13, y + 9, z + 15, 1, cell);
         placeBlock(world, x + 13, y + 10, z + 15, 1, cell);
         placeBlock(world, x + 13, y + 11, z + 15, 1, cell);
         placeBlock(world, x + 13, y + 12, z + 15, 1, cell);
         placeBlock(world, x + 14, y , z + 1, 1, cell);
         placeBlock(world, x + 14, y + 1, z + 1, 1, cell);
         placeBlock(world, x + 14, y + 2, z + 1, 1, cell);
         placeBlock(world, x + 14, y + 3, z + 1, 1, cell);
         placeBlock(world, x + 14, y + 4, z + 1, 1, cell);
         placeBlock(world, x + 14, y + 5, z + 1, 1, cell);
         placeBlock(world, x + 14, y + 6, z + 1, 1, cell);
         placeBlock(world, x + 14, y + 7, z + 1, 1, cell);
         placeBlock(world, x + 14, y + 8, z + 1, 1, cell);
         placeBlock(world, x + 14, y + 9, z + 1, 1, cell);
         placeBlock(world, x + 14, y + 10, z + 1, 1, cell);
         placeBlock(world, x + 14, y + 11, z + 1, 1, cell);
         placeBlock(world, x + 14, y + 12, z + 1, 1, cell);
         placeBlock(world, x + 14, y , z + 15, 1, cell);
         placeBlock(world, x + 14, y + 1, z + 15, 1, cell);
         placeBlock(world, x + 14, y + 2, z + 15, 1, cell);
         placeBlock(world, x + 14, y + 3, z + 15, 1, cell);
         placeBlock(world, x + 14, y + 4, z + 15, 1, cell);
         placeBlock(world, x + 14, y + 5, z + 15, 1, cell);
         placeBlock(world, x + 14, y + 6, z + 15, 1, cell);
         placeBlock(world, x + 14, y + 7, z + 15, 1, cell);
         placeBlock(world, x + 14, y + 8, z + 15, 1, cell);
         placeBlock(world, x + 14, y + 9, z + 15, 1, cell);
         placeBlock(world, x + 14, y + 10, z + 15, 1, cell);
         placeBlock(world, x + 14, y + 11, z + 15, 1, cell);
         placeBlock(world, x + 14, y + 12, z + 15, 1, cell);
         placeBlock(world, x + 15, y , z + 1, 1, cell);
         placeBlock(world, x + 15, y + 1, z + 1, 1, cell);
         placeBlock(world, x + 15, y + 2, z + 1, 1, cell);
         placeBlock(world, x + 15, y + 3, z + 1, 1, cell);
         placeBlock(world, x + 15, y + 4, z + 1, 1, cell);
         placeBlock(world, x + 15, y + 5, z + 1, 1, cell);
         placeBlock(world, x + 15, y + 6, z + 1, 1, cell);
         placeBlock(world, x + 15, y + 7, z + 1, 1, cell);
         placeBlock(world, x + 15, y + 8, z + 1, 1, cell);
         placeBlock(world, x + 15, y + 9, z + 1, 1, cell);
         placeBlock(world, x + 15, y + 10, z + 1, 1, cell);
         placeBlock(world, x + 15, y + 11, z + 1, 1, cell);
         placeBlock(world, x + 15, y + 12, z + 1, 1, cell);
         placeBlock(world, x + 15, y , z + 2, 1, cell);
         placeBlock(world, x + 15, y + 1, z + 2, 1, cell);
         placeBlock(world, x + 15, y + 2, z + 2, 1, cell);
         placeBlock(world, x + 15, y + 3, z + 2, 1, cell);
         placeBlock(world, x + 15, y + 4, z + 2, 1, cell);
         placeBlock(world, x + 15, y + 5, z + 2, 1, cell);
         placeBlock(world, x + 15, y + 6, z + 2, 1, cell);
         placeBlock(world, x + 15, y + 7, z + 2, 1, cell);
         placeBlock(world, x + 15, y + 8, z + 2, 1, cell);
         placeBlock(world, x + 15, y + 9, z + 2, 1, cell);
         placeBlock(world, x + 15, y + 10, z + 2, 1, cell);
         placeBlock(world, x + 15, y + 11, z + 2, 1, cell);
         placeBlock(world, x + 15, y + 12, z + 2, 1, cell);
         placeBlock(world, x + 15, y , z + 3, 1, cell);
         placeBlock(world, x + 15, y + 1, z + 3, 1, cell);
         placeBlock(world, x + 15, y + 2, z + 3, 1, cell);
         placeBlock(world, x + 15, y + 3, z + 3, 1, cell);
         placeBlock(world, x + 15, y + 4, z + 3, 1, cell);
         placeBlock(world, x + 15, y + 5, z + 3, 1, cell);
         placeBlock(world, x + 15, y + 6, z + 3, 1, cell);
         placeBlock(world, x + 15, y + 7, z + 3, 1, cell);
         placeBlock(world, x + 15, y + 8, z + 3, 1, cell);
         placeBlock(world, x + 15, y + 9, z + 3, 1, cell);
         placeBlock(world, x + 15, y + 10, z + 3, 1, cell);
         placeBlock(world, x + 15, y + 11, z + 3, 1, cell);
         placeBlock(world, x + 15, y + 12, z + 3, 1, cell);
         placeBlock(world, x + 15, y , z + 4, 1, cell);
         placeBlock(world, x + 15, y + 1, z + 4, 1, cell);
         placeBlock(world, x + 15, y + 2, z + 4, 1, cell);
         placeBlock(world, x + 15, y + 3, z + 4, 1, cell);
         placeBlock(world, x + 15, y + 4, z + 4, 1, cell);
         placeBlock(world, x + 15, y + 5, z + 4, 1, cell);
         placeBlock(world, x + 15, y + 6, z + 4, 1, cell);
         placeBlock(world, x + 15, y + 7, z + 4, 1, cell);
         placeBlock(world, x + 15, y + 8, z + 4, 1, cell);
         placeBlock(world, x + 15, y + 9, z + 4, 1, cell);
         placeBlock(world, x + 15, y + 10, z + 4, 1, cell);
         placeBlock(world, x + 15, y + 11, z + 4, 1, cell);
         placeBlock(world, x + 15, y + 12, z + 4, 1, cell);
         placeBlock(world, x + 15, y , z + 5, 1, cell);
         placeBlock(world, x + 15, y + 1, z + 5, 1, cell);
         placeBlock(world, x + 15, y + 2, z + 5, 1, cell);
         placeBlock(world, x + 15, y + 3, z + 5, 1, cell);
         placeBlock(world, x + 15, y + 4, z + 5, 1, cell);
         placeBlock(world, x + 15, y + 5, z + 5, 1, cell);
         placeBlock(world, x + 15, y + 6, z + 5, 1, cell);
         placeBlock(world, x + 15, y + 7, z + 5, 1, cell);
         placeBlock(world, x + 15, y + 8, z + 5, 1, cell);
         placeBlock(world, x + 15, y + 9, z + 5, 1, cell);
         placeBlock(world, x + 15, y + 10, z + 5, 1, cell);
         placeBlock(world, x + 15, y + 11, z + 5, 1, cell);
         placeBlock(world, x + 15, y + 12, z + 5, 1, cell);
         placeBlock(world, x + 15, y , z + 6, 1, cell);
         placeBlock(world, x + 15, y + 1, z + 6, 1, cell);
         placeBlock(world, x + 15, y + 2, z + 6, 1, cell);
         placeBlock(world, x + 15, y + 3, z + 6, 1, cell);
         placeBlock(world, x + 15, y + 4, z + 6, 1, cell);
         placeBlock(world, x + 15, y + 5, z + 6, 1, cell);
         placeBlock(world, x + 15, y + 6, z + 6, 1, cell);
         placeBlock(world, x + 15, y + 7, z + 6, 1, cell);
         placeBlock(world, x + 15, y + 8, z + 6, 1, cell);
         placeBlock(world, x + 15, y + 9, z + 6, 1, cell);
         placeBlock(world, x + 15, y + 10, z + 6, 1, cell);
         placeBlock(world, x + 15, y + 11, z + 6, 1, cell);
         placeBlock(world, x + 15, y + 12, z + 6, 1, cell);
         placeBlock(world, x + 15, y , z + 7, 1, cell);
         placeBlock(world, x + 15, y + 1, z + 7, 1, cell);
         placeBlock(world, x + 15, y + 2, z + 7, 1, cell);
         placeBlock(world, x + 15, y + 3, z + 7, 1, cell);
         placeBlock(world, x + 15, y + 4, z + 7, 1, cell);
         placeBlock(world, x + 15, y + 5, z + 7, 1, cell);
         placeBlock(world, x + 15, y + 6, z + 7, 1, cell);
         placeBlock(world, x + 15, y + 7, z + 7, 1, cell);
         placeBlock(world, x + 15, y + 8, z + 7, 1, cell);
         placeBlock(world, x + 15, y + 9, z + 7, 1, cell);
         placeBlock(world, x + 15, y + 10, z + 7, 1, cell);
         placeBlock(world, x + 15, y + 11, z + 7, 1, cell);
         placeBlock(world, x + 15, y + 12, z + 7, 1, cell);
         placeBlock(world, x + 15, y , z + 8, 1, cell);
         placeBlock(world, x + 15, y + 1, z + 8, 1, cell);
         placeBlock(world, x + 15, y + 2, z + 8, 1, cell);
         placeBlock(world, x + 15, y + 3, z + 8, 1, cell);
         placeBlock(world, x + 15, y + 4, z + 8, 1, cell);
         placeBlock(world, x + 15, y + 5, z + 8, 1, cell);
         placeBlock(world, x + 15, y + 6, z + 8, 1, cell);
         placeBlock(world, x + 15, y + 7, z + 8, 1, cell);
         placeBlock(world, x + 15, y + 8, z + 8, 1, cell);
         placeBlock(world, x + 15, y + 9, z + 8, 1, cell);
         placeBlock(world, x + 15, y + 10, z + 8, 1, cell);
         placeBlock(world, x + 15, y + 11, z + 8, 1, cell);
         placeBlock(world, x + 15, y + 12, z + 8, 1, cell);
         placeBlock(world, x + 15, y , z + 9, 1, cell);
         placeBlock(world, x + 15, y + 1, z + 9, 1, cell);
         placeBlock(world, x + 15, y + 2, z + 9, 1, cell);
         placeBlock(world, x + 15, y + 3, z + 9, 1, cell);
         placeBlock(world, x + 15, y + 4, z + 9, 1, cell);
         placeBlock(world, x + 15, y + 5, z + 9, 1, cell);
         placeBlock(world, x + 15, y + 6, z + 9, 1, cell);
         placeBlock(world, x + 15, y + 7, z + 9, 1, cell);
         placeBlock(world, x + 15, y + 8, z + 9, 1, cell);
         placeBlock(world, x + 15, y + 9, z + 9, 1, cell);
         placeBlock(world, x + 15, y + 10, z + 9, 1, cell);
         placeBlock(world, x + 15, y + 11, z + 9, 1, cell);
         placeBlock(world, x + 15, y + 12, z + 9, 1, cell);
         placeBlock(world, x + 15, y , z + 10, 1, cell);
         placeBlock(world, x + 15, y + 1, z + 10, 1, cell);
         placeBlock(world, x + 15, y + 2, z + 10, 1, cell);
         placeBlock(world, x + 15, y + 3, z + 10, 1, cell);
         placeBlock(world, x + 15, y + 4, z + 10, 1, cell);
         placeBlock(world, x + 15, y + 5, z + 10, 1, cell);
         placeBlock(world, x + 15, y + 6, z + 10, 1, cell);
         placeBlock(world, x + 15, y + 7, z + 10, 1, cell);
         placeBlock(world, x + 15, y + 8, z + 10, 1, cell);
         placeBlock(world, x + 15, y + 9, z + 10, 1, cell);
         placeBlock(world, x + 15, y + 10, z + 10, 1, cell);
         placeBlock(world, x + 15, y + 11, z + 10, 1, cell);
         placeBlock(world, x + 15, y + 12, z + 10, 1, cell);
         placeBlock(world, x + 15, y , z + 11, 1, cell);
         placeBlock(world, x + 15, y + 1, z + 11, 1, cell);
         placeBlock(world, x + 15, y + 2, z + 11, 1, cell);
         placeBlock(world, x + 15, y + 3, z + 11, 1, cell);
         placeBlock(world, x + 15, y + 4, z + 11, 1, cell);
         placeBlock(world, x + 15, y + 5, z + 11, 1, cell);
         placeBlock(world, x + 15, y + 6, z + 11, 1, cell);
         placeBlock(world, x + 15, y + 7, z + 11, 1, cell);
         placeBlock(world, x + 15, y + 8, z + 11, 1, cell);
         placeBlock(world, x + 15, y + 9, z + 11, 1, cell);
         placeBlock(world, x + 15, y + 10, z + 11, 1, cell);
         placeBlock(world, x + 15, y + 11, z + 11, 1, cell);
         placeBlock(world, x + 15, y + 12, z + 11, 1, cell);
         placeBlock(world, x + 15, y , z + 12, 1, cell);
         placeBlock(world, x + 15, y + 1, z + 12, 1, cell);
         placeBlock(world, x + 15, y + 2, z + 12, 1, cell);
         placeBlock(world, x + 15, y + 3, z + 12, 1, cell);
         placeBlock(world, x + 15, y + 4, z + 12, 1, cell);
         placeBlock(world, x + 15, y + 5, z + 12, 1, cell);
         placeBlock(world, x + 15, y + 6, z + 12, 1, cell);
         placeBlock(world, x + 15, y + 7, z + 12, 1, cell);
         placeBlock(world, x + 15, y + 8, z + 12, 1, cell);
         placeBlock(world, x + 15, y + 9, z + 12, 1, cell);
         placeBlock(world, x + 15, y + 10, z + 12, 1, cell);
         placeBlock(world, x + 15, y + 11, z + 12, 1, cell);
         placeBlock(world, x + 15, y + 12, z + 12, 1, cell);
         placeBlock(world, x + 15, y , z + 13, 1, cell);
         placeBlock(world, x + 15, y + 1, z + 13, 1, cell);
         placeBlock(world, x + 15, y + 2, z + 13, 1, cell);
         placeBlock(world, x + 15, y + 3, z + 13, 1, cell);
         placeBlock(world, x + 15, y + 4, z + 13, 1, cell);
         placeBlock(world, x + 15, y + 5, z + 13, 1, cell);
         placeBlock(world, x + 15, y + 6, z + 13, 1, cell);
         placeBlock(world, x + 15, y + 7, z + 13, 1, cell);
         placeBlock(world, x + 15, y + 8, z + 13, 1, cell);
         placeBlock(world, x + 15, y + 9, z + 13, 1, cell);
         placeBlock(world, x + 15, y + 10, z + 13, 1, cell);
         placeBlock(world, x + 15, y + 11, z + 13, 1, cell);
         placeBlock(world, x + 15, y + 12, z + 13, 1, cell);
         placeBlock(world, x + 15, y , z + 14, 1, cell);
         placeBlock(world, x + 15, y + 1, z + 14, 1, cell);
         placeBlock(world, x + 15, y + 2, z + 14, 1, cell);
         placeBlock(world, x + 15, y + 3, z + 14, 1, cell);
         placeBlock(world, x + 15, y + 4, z + 14, 1, cell);
         placeBlock(world, x + 15, y + 5, z + 14, 1, cell);
         placeBlock(world, x + 15, y + 6, z + 14, 1, cell);
         placeBlock(world, x + 15, y + 7, z + 14, 1, cell);
         placeBlock(world, x + 15, y + 8, z + 14, 1, cell);
         placeBlock(world, x + 15, y + 9, z + 14, 1, cell);
         placeBlock(world, x + 15, y + 10, z + 14, 1, cell);
         placeBlock(world, x + 15, y + 11, z + 14, 1, cell);
         placeBlock(world, x + 15, y + 12, z + 14, 1, cell);
         placeBlock(world, x + 15, y , z + 15, 1, cell);
         placeBlock(world, x + 15, y + 1, z + 15, 1, cell);
         placeBlock(world, x + 15, y + 2, z + 15, 1, cell);
         placeBlock(world, x + 15, y + 3, z + 15, 1, cell);
         placeBlock(world, x + 15, y + 4, z + 15, 1, cell);
         placeBlock(world, x + 15, y + 5, z + 15, 1, cell);
         placeBlock(world, x + 15, y + 6, z + 15, 1, cell);
         placeBlock(world, x + 15, y + 7, z + 15, 1, cell);
         placeBlock(world, x + 15, y + 8, z + 15, 1, cell);
         placeBlock(world, x + 15, y + 9, z + 15, 1, cell);
         placeBlock(world, x + 15, y + 10, z + 15, 1, cell);
         placeBlock(world, x + 15, y + 11, z + 15, 1, cell);
         placeBlock(world, x + 15, y + 12, z + 15, 1, cell);
         placeBlock(world, x + 2, y + 6, z + 2, 8, cell);
         placeBlock(world, x + 2, y + 7, z + 2, 8, cell);
         placeBlock(world, x + 2, y + 8, z + 2, 8, cell);
         placeBlock(world, x + 2, y + 9, z + 2, 8, cell);
         placeBlock(world, x + 2, y + 10, z + 2, 8, cell);
         placeBlock(world, x + 2, y + 5, z + 3, 8, cell);
         placeBlock(world, x + 2, y + 6, z + 3, 8, cell);
         placeBlock(world, x + 2, y + 7, z + 3, 8, cell);
         placeBlock(world, x + 2, y + 8, z + 3, 8, cell);
         placeBlock(world, x + 2, y + 9, z + 3, 8, cell);
         placeBlock(world, x + 2, y + 10, z + 3, 8, cell);
         placeBlock(world, x + 2, y + 4, z + 4, 8, cell);
         placeBlock(world, x + 2, y + 5, z + 4, 8, cell);
         placeBlock(world, x + 2, y + 6, z + 4, 8, cell);
         placeBlock(world, x + 2, y + 7, z + 4, 8, cell);
         placeBlock(world, x + 2, y + 8, z + 4, 8, cell);
         placeBlock(world, x + 2, y + 9, z + 4, 8, cell);
         placeBlock(world, x + 2, y + 10, z + 4, 8, cell);
         placeBlock(world, x + 2, y + 3, z + 5, 8, cell);
         placeBlock(world, x + 2, y + 4, z + 5, 8, cell);
         placeBlock(world, x + 2, y + 5, z + 5, 8, cell);
         placeBlock(world, x + 2, y + 6, z + 5, 8, cell);
         placeBlock(world, x + 2, y + 7, z + 5, 8, cell);
         placeBlock(world, x + 2, y + 8, z + 5, 8, cell);
         placeBlock(world, x + 2, y + 9, z + 5, 8, cell);
         placeBlock(world, x + 2, y + 10, z + 5, 8, cell);
         placeBlock(world, x + 2, y + 2, z + 6, 8, cell);
         placeBlock(world, x + 2, y + 3, z + 6, 8, cell);
         placeBlock(world, x + 2, y + 4, z + 6, 8, cell);
         placeBlock(world, x + 2, y + 5, z + 6, 8, cell);
         placeBlock(world, x + 2, y + 6, z + 6, 8, cell);
         placeBlock(world, x + 2, y + 7, z + 6, 8, cell);
         placeBlock(world, x + 2, y + 8, z + 6, 8, cell);
         placeBlock(world, x + 2, y + 9, z + 6, 8, cell);
         placeBlock(world, x + 2, y + 10, z + 6, 8, cell);
         placeBlock(world, x + 2, y + 2, z + 7, 8, cell);
         placeBlock(world, x + 2, y + 3, z + 7, 8, cell);
         placeBlock(world, x + 2, y + 4, z + 7, 8, cell);
         placeBlock(world, x + 2, y + 5, z + 7, 8, cell);
         placeBlock(world, x + 2, y + 6, z + 7, 8, cell);
         placeBlock(world, x + 2, y + 7, z + 7, 8, cell);
         placeBlock(world, x + 2, y + 8, z + 7, 8, cell);
         placeBlock(world, x + 2, y + 9, z + 7, 8, cell);
         placeBlock(world, x + 2, y + 10, z + 7, 8, cell);
         placeBlock(world, x + 2, y + 2, z + 8, 8, cell);
         placeBlock(world, x + 2, y + 3, z + 8, 8, cell);
         placeBlock(world, x + 2, y + 4, z + 8, 8, cell);
         placeBlock(world, x + 2, y + 5, z + 8, 8, cell);
         placeBlock(world, x + 2, y + 6, z + 8, 8, cell);
         placeBlock(world, x + 2, y + 7, z + 8, 8, cell);
         placeBlock(world, x + 2, y + 8, z + 8, 8, cell);
         placeBlock(world, x + 2, y + 9, z + 8, 8, cell);
         placeBlock(world, x + 2, y + 10, z + 8, 8, cell);
         placeBlock(world, x + 2, y + 2, z + 9, 8, cell);
         placeBlock(world, x + 2, y + 3, z + 9, 8, cell);
         placeBlock(world, x + 2, y + 4, z + 9, 8, cell);
         placeBlock(world, x + 2, y + 5, z + 9, 8, cell);
         placeBlock(world, x + 2, y + 6, z + 9, 8, cell);
         placeBlock(world, x + 2, y + 7, z + 9, 8, cell);
         placeBlock(world, x + 2, y + 8, z + 9, 8, cell);
         placeBlock(world, x + 2, y + 9, z + 9, 8, cell);
         placeBlock(world, x + 2, y + 10, z + 9, 8, cell);
         placeBlock(world, x + 2, y + 2, z + 10, 8, cell);
         placeBlock(world, x + 2, y + 3, z + 10, 8, cell);
         placeBlock(world, x + 2, y + 4, z + 10, 8, cell);
         placeBlock(world, x + 2, y + 5, z + 10, 8, cell);
         placeBlock(world, x + 2, y + 6, z + 10, 8, cell);
         placeBlock(world, x + 2, y + 7, z + 10, 8, cell);
         placeBlock(world, x + 2, y + 8, z + 10, 8, cell);
         placeBlock(world, x + 2, y + 9, z + 10, 8, cell);
         placeBlock(world, x + 2, y + 10, z + 10, 8, cell);
         placeBlock(world, x + 2, y + 3, z + 11, 8, cell);
         placeBlock(world, x + 2, y + 4, z + 11, 8, cell);
         placeBlock(world, x + 2, y + 5, z + 11, 8, cell);
         placeBlock(world, x + 2, y + 6, z + 11, 8, cell);
         placeBlock(world, x + 2, y + 7, z + 11, 8, cell);
         placeBlock(world, x + 2, y + 8, z + 11, 8, cell);
         placeBlock(world, x + 2, y + 9, z + 11, 8, cell);
         placeBlock(world, x + 2, y + 10, z + 11, 8, cell);
         placeBlock(world, x + 2, y + 4, z + 12, 8, cell);
         placeBlock(world, x + 2, y + 5, z + 12, 8, cell);
         placeBlock(world, x + 2, y + 6, z + 12, 8, cell);
         placeBlock(world, x + 2, y + 7, z + 12, 8, cell);
         placeBlock(world, x + 2, y + 8, z + 12, 8, cell);
         placeBlock(world, x + 2, y + 9, z + 12, 8, cell);
         placeBlock(world, x + 2, y + 10, z + 12, 8, cell);
         placeBlock(world, x + 2, y + 5, z + 13, 8, cell);
         placeBlock(world, x + 2, y + 6, z + 13, 8, cell);
         placeBlock(world, x + 2, y + 7, z + 13, 8, cell);
         placeBlock(world, x + 2, y + 8, z + 13, 8, cell);
         placeBlock(world, x + 2, y + 9, z + 13, 8, cell);
         placeBlock(world, x + 2, y + 10, z + 13, 8, cell);
         placeBlock(world, x + 2, y + 6, z + 14, 8, cell);
         placeBlock(world, x + 2, y + 7, z + 14, 8, cell);
         placeBlock(world, x + 2, y + 8, z + 14, 8, cell);
         placeBlock(world, x + 2, y + 9, z + 14, 8, cell);
         placeBlock(world, x + 2, y + 10, z + 14, 8, cell);
         placeBlock(world, x + 3, y + 5, z + 2, 8, cell);
         placeBlock(world, x + 3, y + 6, z + 2, 8, cell);
         placeBlock(world, x + 3, y + 7, z + 2, 8, cell);
         placeBlock(world, x + 3, y + 8, z + 2, 8, cell);
         placeBlock(world, x + 3, y + 9, z + 2, 8, cell);
         placeBlock(world, x + 3, y + 10, z + 2, 8, cell);
         placeBlock(world, x + 3, y + 5, z + 14, 8, cell);
         placeBlock(world, x + 3, y + 6, z + 14, 8, cell);
         placeBlock(world, x + 3, y + 7, z + 14, 8, cell);
         placeBlock(world, x + 3, y + 8, z + 14, 8, cell);
         placeBlock(world, x + 3, y + 9, z + 14, 8, cell);
         placeBlock(world, x + 3, y + 10, z + 14, 8, cell);
         placeBlock(world, x + 4, y + 4, z + 2, 8, cell);
         placeBlock(world, x + 4, y + 5, z + 2, 8, cell);
         placeBlock(world, x + 4, y + 6, z + 2, 8, cell);
         placeBlock(world, x + 4, y + 7, z + 2, 8, cell);
         placeBlock(world, x + 4, y + 8, z + 2, 8, cell);
         placeBlock(world, x + 4, y + 9, z + 2, 8, cell);
         placeBlock(world, x + 4, y + 10, z + 2, 8, cell);
         placeBlock(world, x + 4, y + 4, z + 14, 8, cell);
         placeBlock(world, x + 4, y + 5, z + 14, 8, cell);
         placeBlock(world, x + 4, y + 6, z + 14, 8, cell);
         placeBlock(world, x + 4, y + 7, z + 14, 8, cell);
         placeBlock(world, x + 4, y + 8, z + 14, 8, cell);
         placeBlock(world, x + 4, y + 9, z + 14, 8, cell);
         placeBlock(world, x + 4, y + 10, z + 14, 8, cell);
         placeBlock(world, x + 5, y + 3, z + 2, 8, cell);
         placeBlock(world, x + 5, y + 4, z + 2, 8, cell);
         placeBlock(world, x + 5, y + 5, z + 2, 8, cell);
         placeBlock(world, x + 5, y + 6, z + 2, 8, cell);
         placeBlock(world, x + 5, y + 7, z + 2, 8, cell);
         placeBlock(world, x + 5, y + 8, z + 2, 8, cell);
         placeBlock(world, x + 5, y + 9, z + 2, 8, cell);
         placeBlock(world, x + 5, y + 10, z + 2, 8, cell);
         placeBlock(world, x + 5, y + 3, z + 14, 8, cell);
         placeBlock(world, x + 5, y + 4, z + 14, 8, cell);
         placeBlock(world, x + 5, y + 5, z + 14, 8, cell);
         placeBlock(world, x + 5, y + 6, z + 14, 8, cell);
         placeBlock(world, x + 5, y + 7, z + 14, 8, cell);
         placeBlock(world, x + 5, y + 8, z + 14, 8, cell);
         placeBlock(world, x + 5, y + 9, z + 14, 8, cell);
         placeBlock(world, x + 5, y + 10, z + 14, 8, cell);
         placeBlock(world, x + 6, y + 2, z + 2, 8, cell);
         placeBlock(world, x + 6, y + 3, z + 2, 8, cell);
         placeBlock(world, x + 6, y + 4, z + 2, 8, cell);
         placeBlock(world, x + 6, y + 5, z + 2, 8, cell);
         placeBlock(world, x + 6, y + 6, z + 2, 8, cell);
         placeBlock(world, x + 6, y + 7, z + 2, 8, cell);
         placeBlock(world, x + 6, y + 8, z + 2, 8, cell);
         placeBlock(world, x + 6, y + 9, z + 2, 8, cell);
         placeBlock(world, x + 6, y + 10, z + 2, 8, cell);
         placeBlock(world, x + 6, y + 2, z + 14, 8, cell);
         placeBlock(world, x + 6, y + 3, z + 14, 8, cell);
         placeBlock(world, x + 6, y + 4, z + 14, 8, cell);
         placeBlock(world, x + 6, y + 5, z + 14, 8, cell);
         placeBlock(world, x + 6, y + 6, z + 14, 8, cell);
         placeBlock(world, x + 6, y + 7, z + 14, 8, cell);
         placeBlock(world, x + 6, y + 8, z + 14, 8, cell);
         placeBlock(world, x + 6, y + 9, z + 14, 8, cell);
         placeBlock(world, x + 6, y + 10, z + 14, 8, cell);
         placeBlock(world, x + 7, y + 2, z + 2, 8, cell);
         placeBlock(world, x + 7, y + 3, z + 2, 8, cell);
         placeBlock(world, x + 7, y + 4, z + 2, 8, cell);
         placeBlock(world, x + 7, y + 5, z + 2, 8, cell);
         placeBlock(world, x + 7, y + 6, z + 2, 8, cell);
         placeBlock(world, x + 7, y + 7, z + 2, 8, cell);
         placeBlock(world, x + 7, y + 8, z + 2, 8, cell);
         placeBlock(world, x + 7, y + 9, z + 2, 8, cell);
         placeBlock(world, x + 7, y + 10, z + 2, 8, cell);
         placeBlock(world, x + 7, y + 2, z + 14, 8, cell);
         placeBlock(world, x + 7, y + 3, z + 14, 8, cell);
         placeBlock(world, x + 7, y + 4, z + 14, 8, cell);
         placeBlock(world, x + 7, y + 5, z + 14, 8, cell);
         placeBlock(world, x + 7, y + 6, z + 14, 8, cell);
         placeBlock(world, x + 7, y + 7, z + 14, 8, cell);
         placeBlock(world, x + 7, y + 8, z + 14, 8, cell);
         placeBlock(world, x + 7, y + 9, z + 14, 8, cell);
         placeBlock(world, x + 7, y + 10, z + 14, 8, cell);
         placeBlock(world, x + 8, y + 2, z + 2, 8, cell);
         placeBlock(world, x + 8, y + 3, z + 2, 8, cell);
         placeBlock(world, x + 8, y + 4, z + 2, 8, cell);
         placeBlock(world, x + 8, y + 5, z + 2, 8, cell);
         placeBlock(world, x + 8, y + 6, z + 2, 8, cell);
         placeBlock(world, x + 8, y + 7, z + 2, 8, cell);
         placeBlock(world, x + 8, y + 8, z + 2, 8, cell);
         placeBlock(world, x + 8, y + 9, z + 2, 8, cell);
         placeBlock(world, x + 8, y + 10, z + 2, 8, cell);
         placeBlock(world, x + 8, y + 2, z + 14, 8, cell);
         placeBlock(world, x + 8, y + 3, z + 14, 8, cell);
         placeBlock(world, x + 8, y + 4, z + 14, 8, cell);
         placeBlock(world, x + 8, y + 5, z + 14, 8, cell);
         placeBlock(world, x + 8, y + 6, z + 14, 8, cell);
         placeBlock(world, x + 8, y + 7, z + 14, 8, cell);
         placeBlock(world, x + 8, y + 8, z + 14, 8, cell);
         placeBlock(world, x + 8, y + 9, z + 14, 8, cell);
         placeBlock(world, x + 8, y + 10, z + 14, 8, cell);
         placeBlock(world, x + 9, y + 2, z + 2, 8, cell);
         placeBlock(world, x + 9, y + 3, z + 2, 8, cell);
         placeBlock(world, x + 9, y + 4, z + 2, 8, cell);
         placeBlock(world, x + 9, y + 5, z + 2, 8, cell);
         placeBlock(world, x + 9, y + 6, z + 2, 8, cell);
         placeBlock(world, x + 9, y + 7, z + 2, 8, cell);
         placeBlock(world, x + 9, y + 8, z + 2, 8, cell);
         placeBlock(world, x + 9, y + 9, z + 2, 8, cell);
         placeBlock(world, x + 9, y + 10, z + 2, 8, cell);
         placeBlock(world, x + 9, y + 2, z + 14, 8, cell);
         placeBlock(world, x + 9, y + 3, z + 14, 8, cell);
         placeBlock(world, x + 9, y + 4, z + 14, 8, cell);
         placeBlock(world, x + 9, y + 5, z + 14, 8, cell);
         placeBlock(world, x + 9, y + 6, z + 14, 8, cell);
         placeBlock(world, x + 9, y + 7, z + 14, 8, cell);
         placeBlock(world, x + 9, y + 8, z + 14, 8, cell);
         placeBlock(world, x + 9, y + 9, z + 14, 8, cell);
         placeBlock(world, x + 9, y + 10, z + 14, 8, cell);
         placeBlock(world, x + 10, y + 2, z + 2, 8, cell);
         placeBlock(world, x + 10, y + 3, z + 2, 8, cell);
         placeBlock(world, x + 10, y + 4, z + 2, 8, cell);
         placeBlock(world, x + 10, y + 5, z + 2, 8, cell);
         placeBlock(world, x + 10, y + 6, z + 2, 8, cell);
         placeBlock(world, x + 10, y + 7, z + 2, 8, cell);
         placeBlock(world, x + 10, y + 8, z + 2, 8, cell);
         placeBlock(world, x + 10, y + 9, z + 2, 8, cell);
         placeBlock(world, x + 10, y + 10, z + 2, 8, cell);
         placeBlock(world, x + 10, y + 2, z + 14, 8, cell);
         placeBlock(world, x + 10, y + 3, z + 14, 8, cell);
         placeBlock(world, x + 10, y + 4, z + 14, 8, cell);
         placeBlock(world, x + 10, y + 5, z + 14, 8, cell);
         placeBlock(world, x + 10, y + 6, z + 14, 8, cell);
         placeBlock(world, x + 10, y + 7, z + 14, 8, cell);
         placeBlock(world, x + 10, y + 8, z + 14, 8, cell);
         placeBlock(world, x + 10, y + 9, z + 14, 8, cell);
         placeBlock(world, x + 10, y + 10, z + 14, 8, cell);
         placeBlock(world, x + 11, y + 3, z + 2, 8, cell);
         placeBlock(world, x + 11, y + 4, z + 2, 8, cell);
         placeBlock(world, x + 11, y + 5, z + 2, 8, cell);
         placeBlock(world, x + 11, y + 6, z + 2, 8, cell);
         placeBlock(world, x + 11, y + 7, z + 2, 8, cell);
         placeBlock(world, x + 11, y + 8, z + 2, 8, cell);
         placeBlock(world, x + 11, y + 9, z + 2, 8, cell);
         placeBlock(world, x + 11, y + 10, z + 2, 8, cell);
         placeBlock(world, x + 11, y + 3, z + 14, 8, cell);
         placeBlock(world, x + 11, y + 4, z + 14, 8, cell);
         placeBlock(world, x + 11, y + 5, z + 14, 8, cell);
         placeBlock(world, x + 11, y + 6, z + 14, 8, cell);
         placeBlock(world, x + 11, y + 7, z + 14, 8, cell);
         placeBlock(world, x + 11, y + 8, z + 14, 8, cell);
         placeBlock(world, x + 11, y + 9, z + 14, 8, cell);
         placeBlock(world, x + 11, y + 10, z + 14, 8, cell);
         placeBlock(world, x + 12, y + 4, z + 2, 8, cell);
         placeBlock(world, x + 12, y + 5, z + 2, 8, cell);
         placeBlock(world, x + 12, y + 6, z + 2, 8, cell);
         placeBlock(world, x + 12, y + 7, z + 2, 8, cell);
         placeBlock(world, x + 12, y + 8, z + 2, 8, cell);
         placeBlock(world, x + 12, y + 9, z + 2, 8, cell);
         placeBlock(world, x + 12, y + 10, z + 2, 8, cell);
         placeBlock(world, x + 12, y + 4, z + 14, 8, cell);
         placeBlock(world, x + 12, y + 5, z + 14, 8, cell);
         placeBlock(world, x + 12, y + 6, z + 14, 8, cell);
         placeBlock(world, x + 12, y + 7, z + 14, 8, cell);
         placeBlock(world, x + 12, y + 8, z + 14, 8, cell);
         placeBlock(world, x + 12, y + 9, z + 14, 8, cell);
         placeBlock(world, x + 12, y + 10, z + 14, 8, cell);
         placeBlock(world, x + 13, y + 5, z + 2, 8, cell);
         placeBlock(world, x + 13, y + 6, z + 2, 8, cell);
         placeBlock(world, x + 13, y + 7, z + 2, 8, cell);
         placeBlock(world, x + 13, y + 8, z + 2, 8, cell);
         placeBlock(world, x + 13, y + 9, z + 2, 8, cell);
         placeBlock(world, x + 13, y + 10, z + 2, 8, cell);
         placeBlock(world, x + 13, y + 5, z + 14, 8, cell);
         placeBlock(world, x + 13, y + 6, z + 14, 8, cell);
         placeBlock(world, x + 13, y + 7, z + 14, 8, cell);
         placeBlock(world, x + 13, y + 8, z + 14, 8, cell);
         placeBlock(world, x + 13, y + 9, z + 14, 8, cell);
         placeBlock(world, x + 13, y + 10, z + 14, 8, cell);
         placeBlock(world, x + 14, y + 6, z + 2, 8, cell);
         placeBlock(world, x + 14, y + 7, z + 2, 8, cell);
         placeBlock(world, x + 14, y + 8, z + 2, 8, cell);
         placeBlock(world, x + 14, y + 9, z + 2, 8, cell);
         placeBlock(world, x + 14, y + 10, z + 2, 8, cell);
         placeBlock(world, x + 14, y + 5, z + 3, 8, cell);
         placeBlock(world, x + 14, y + 6, z + 3, 8, cell);
         placeBlock(world, x + 14, y + 7, z + 3, 8, cell);
         placeBlock(world, x + 14, y + 8, z + 3, 8, cell);
         placeBlock(world, x + 14, y + 9, z + 3, 8, cell);
         placeBlock(world, x + 14, y + 10, z + 3, 8, cell);
         placeBlock(world, x + 14, y + 4, z + 4, 8, cell);
         placeBlock(world, x + 14, y + 5, z + 4, 8, cell);
         placeBlock(world, x + 14, y + 6, z + 4, 8, cell);
         placeBlock(world, x + 14, y + 7, z + 4, 8, cell);
         placeBlock(world, x + 14, y + 8, z + 4, 8, cell);
         placeBlock(world, x + 14, y + 9, z + 4, 8, cell);
         placeBlock(world, x + 14, y + 10, z + 4, 8, cell);
         placeBlock(world, x + 14, y + 3, z + 5, 8, cell);
         placeBlock(world, x + 14, y + 4, z + 5, 8, cell);
         placeBlock(world, x + 14, y + 5, z + 5, 8, cell);
         placeBlock(world, x + 14, y + 6, z + 5, 8, cell);
         placeBlock(world, x + 14, y + 7, z + 5, 8, cell);
         placeBlock(world, x + 14, y + 8, z + 5, 8, cell);
         placeBlock(world, x + 14, y + 9, z + 5, 8, cell);
         placeBlock(world, x + 14, y + 10, z + 5, 8, cell);
         placeBlock(world, x + 14, y + 2, z + 6, 8, cell);
         placeBlock(world, x + 14, y + 3, z + 6, 8, cell);
         placeBlock(world, x + 14, y + 4, z + 6, 8, cell);
         placeBlock(world, x + 14, y + 5, z + 6, 8, cell);
         placeBlock(world, x + 14, y + 6, z + 6, 8, cell);
         placeBlock(world, x + 14, y + 7, z + 6, 8, cell);
         placeBlock(world, x + 14, y + 8, z + 6, 8, cell);
         placeBlock(world, x + 14, y + 9, z + 6, 8, cell);
         placeBlock(world, x + 14, y + 10, z + 6, 8, cell);
         placeBlock(world, x + 14, y + 2, z + 7, 8, cell);
         placeBlock(world, x + 14, y + 3, z + 7, 8, cell);
         placeBlock(world, x + 14, y + 4, z + 7, 8, cell);
         placeBlock(world, x + 14, y + 5, z + 7, 8, cell);
         placeBlock(world, x + 14, y + 6, z + 7, 8, cell);
         placeBlock(world, x + 14, y + 7, z + 7, 8, cell);
         placeBlock(world, x + 14, y + 8, z + 7, 8, cell);
         placeBlock(world, x + 14, y + 9, z + 7, 8, cell);
         placeBlock(world, x + 14, y + 10, z + 7, 8, cell);
         placeBlock(world, x + 14, y + 2, z + 8, 8, cell);
         placeBlock(world, x + 14, y + 3, z + 8, 8, cell);
         placeBlock(world, x + 14, y + 4, z + 8, 8, cell);
         placeBlock(world, x + 14, y + 5, z + 8, 8, cell);
         placeBlock(world, x + 14, y + 6, z + 8, 8, cell);
         placeBlock(world, x + 14, y + 7, z + 8, 8, cell);
         placeBlock(world, x + 14, y + 8, z + 8, 8, cell);
         placeBlock(world, x + 14, y + 9, z + 8, 8, cell);
         placeBlock(world, x + 14, y + 10, z + 8, 8, cell);
         placeBlock(world, x + 14, y + 2, z + 9, 8, cell);
         placeBlock(world, x + 14, y + 3, z + 9, 8, cell);
         placeBlock(world, x + 14, y + 4, z + 9, 8, cell);
         placeBlock(world, x + 14, y + 5, z + 9, 8, cell);
         placeBlock(world, x + 14, y + 6, z + 9, 8, cell);
         placeBlock(world, x + 14, y + 7, z + 9, 8, cell);
         placeBlock(world, x + 14, y + 8, z + 9, 8, cell);
         placeBlock(world, x + 14, y + 9, z + 9, 8, cell);
         placeBlock(world, x + 14, y + 10, z + 9, 8, cell);
         placeBlock(world, x + 14, y + 2, z + 10, 8, cell);
         placeBlock(world, x + 14, y + 3, z + 10, 8, cell);
         placeBlock(world, x + 14, y + 4, z + 10, 8, cell);
         placeBlock(world, x + 14, y + 5, z + 10, 8, cell);
         placeBlock(world, x + 14, y + 6, z + 10, 8, cell);
         placeBlock(world, x + 14, y + 7, z + 10, 8, cell);
         placeBlock(world, x + 14, y + 8, z + 10, 8, cell);
         placeBlock(world, x + 14, y + 9, z + 10, 8, cell);
         placeBlock(world, x + 14, y + 10, z + 10, 8, cell);
         placeBlock(world, x + 14, y + 3, z + 11, 8, cell);
         placeBlock(world, x + 14, y + 4, z + 11, 8, cell);
         placeBlock(world, x + 14, y + 5, z + 11, 8, cell);
         placeBlock(world, x + 14, y + 6, z + 11, 8, cell);
         placeBlock(world, x + 14, y + 7, z + 11, 8, cell);
         placeBlock(world, x + 14, y + 8, z + 11, 8, cell);
         placeBlock(world, x + 14, y + 9, z + 11, 8, cell);
         placeBlock(world, x + 14, y + 10, z + 11, 8, cell);
         placeBlock(world, x + 14, y + 4, z + 12, 8, cell);
         placeBlock(world, x + 14, y + 5, z + 12, 8, cell);
         placeBlock(world, x + 14, y + 6, z + 12, 8, cell);
         placeBlock(world, x + 14, y + 7, z + 12, 8, cell);
         placeBlock(world, x + 14, y + 8, z + 12, 8, cell);
         placeBlock(world, x + 14, y + 9, z + 12, 8, cell);
         placeBlock(world, x + 14, y + 10, z + 12, 8, cell);
         placeBlock(world, x + 14, y + 5, z + 13, 8, cell);
         placeBlock(world, x + 14, y + 6, z + 13, 8, cell);
         placeBlock(world, x + 14, y + 7, z + 13, 8, cell);
         placeBlock(world, x + 14, y + 8, z + 13, 8, cell);
         placeBlock(world, x + 14, y + 9, z + 13, 8, cell);
         placeBlock(world, x + 14, y + 10, z + 13, 8, cell);
         placeBlock(world, x + 14, y + 6, z + 14, 8, cell);
         placeBlock(world, x + 14, y + 7, z + 14, 8, cell);
         placeBlock(world, x + 14, y + 8, z + 14, 8, cell);
         placeBlock(world, x + 14, y + 9, z + 14, 8, cell);
         placeBlock(world, x + 14, y + 10, z + 14, 8, cell);
         placeBlock(world, x + 3, y + 3, z + 5, 2, cell);
         placeBlock(world, x + 3, y + 4, z + 5, 2, cell);
         placeBlock(world, x + 3, y + 5, z + 5, 2, cell);
         placeBlock(world, x + 3, y + 6, z + 5, 2, cell);
         placeBlock(world, x + 3, y + 7, z + 5, 2, cell);
         placeBlock(world, x + 3, y + 8, z + 5, 2, cell);
         placeBlock(world, x + 3, y + 9, z + 5, 2, cell);
         placeBlock(world, x + 3, y + 10, z + 5, 2, cell);
         placeBlock(world, x + 3, y + 2, z + 6, 2, cell);
         placeBlock(world, x + 3, y + 3, z + 6, 2, cell);
         placeBlock(world, x + 3, y + 4, z + 6, 2, cell);
         placeBlock(world, x + 3, y + 5, z + 6, 2, cell);
         placeBlock(world, x + 3, y + 6, z + 6, 2, cell);
         placeBlock(world, x + 3, y + 7, z + 6, 2, cell);
         placeBlock(world, x + 3, y + 8, z + 6, 2, cell);
         placeBlock(world, x + 3, y + 9, z + 6, 2, cell);
         placeBlock(world, x + 3, y + 10, z + 6, 2, cell);
         placeBlock(world, x + 3, y + 2, z + 7, 2, cell);
         placeBlock(world, x + 3, y + 3, z + 7, 2, cell);
         placeBlock(world, x + 3, y + 4, z + 7, 2, cell);
         placeBlock(world, x + 3, y + 5, z + 7, 2, cell);
         placeBlock(world, x + 3, y + 6, z + 7, 2, cell);
         placeBlock(world, x + 3, y + 7, z + 7, 2, cell);
         placeBlock(world, x + 3, y + 8, z + 7, 2, cell);
         placeBlock(world, x + 3, y + 9, z + 7, 2, cell);
         placeBlock(world, x + 3, y + 10, z + 7, 2, cell);
         placeBlock(world, x + 3, y + 2, z + 8, 2, cell);
         placeBlock(world, x + 3, y + 3, z + 8, 2, cell);
         placeBlock(world, x + 3, y + 4, z + 8, 2, cell);
         placeBlock(world, x + 3, y + 5, z + 8, 2, cell);
         placeBlock(world, x + 3, y + 6, z + 8, 2, cell);
         placeBlock(world, x + 3, y + 7, z + 8, 2, cell);
         placeBlock(world, x + 3, y + 8, z + 8, 2, cell);
         placeBlock(world, x + 3, y + 9, z + 8, 2, cell);
         placeBlock(world, x + 3, y + 10, z + 8, 2, cell);
         placeBlock(world, x + 3, y + 2, z + 9, 2, cell);
         placeBlock(world, x + 3, y + 3, z + 9, 2, cell);
         placeBlock(world, x + 3, y + 4, z + 9, 2, cell);
         placeBlock(world, x + 3, y + 5, z + 9, 2, cell);
         placeBlock(world, x + 3, y + 6, z + 9, 2, cell);
         placeBlock(world, x + 3, y + 7, z + 9, 2, cell);
         placeBlock(world, x + 3, y + 8, z + 9, 2, cell);
         placeBlock(world, x + 3, y + 9, z + 9, 2, cell);
         placeBlock(world, x + 3, y + 10, z + 9, 2, cell);
         placeBlock(world, x + 3, y + 2, z + 10, 2, cell);
         placeBlock(world, x + 3, y + 3, z + 10, 2, cell);
         placeBlock(world, x + 3, y + 4, z + 10, 2, cell);
         placeBlock(world, x + 3, y + 5, z + 10, 2, cell);
         placeBlock(world, x + 3, y + 6, z + 10, 2, cell);
         placeBlock(world, x + 3, y + 7, z + 10, 2, cell);
         placeBlock(world, x + 3, y + 8, z + 10, 2, cell);
         placeBlock(world, x + 3, y + 9, z + 10, 2, cell);
         placeBlock(world, x + 3, y + 10, z + 10, 2, cell);
         placeBlock(world, x + 3, y + 3, z + 11, 2, cell);
         placeBlock(world, x + 3, y + 4, z + 11, 2, cell);
         placeBlock(world, x + 3, y + 5, z + 11, 2, cell);
         placeBlock(world, x + 3, y + 6, z + 11, 2, cell);
         placeBlock(world, x + 3, y + 7, z + 11, 2, cell);
         placeBlock(world, x + 3, y + 8, z + 11, 2, cell);
         placeBlock(world, x + 3, y + 9, z + 11, 2, cell);
         placeBlock(world, x + 3, y + 10, z + 11, 2, cell);
         placeBlock(world, x + 5, y + 3, z + 3, 2, cell);
         placeBlock(world, x + 5, y + 4, z + 3, 2, cell);
         placeBlock(world, x + 5, y + 5, z + 3, 2, cell);
         placeBlock(world, x + 5, y + 6, z + 3, 2, cell);
         placeBlock(world, x + 5, y + 7, z + 3, 2, cell);
         placeBlock(world, x + 5, y + 8, z + 3, 2, cell);
         placeBlock(world, x + 5, y + 9, z + 3, 2, cell);
         placeBlock(world, x + 5, y + 10, z + 3, 2, cell);
         placeBlock(world, x + 5, y + 3, z + 13, 2, cell);
         placeBlock(world, x + 5, y + 4, z + 13, 2, cell);
         placeBlock(world, x + 5, y + 5, z + 13, 2, cell);
         placeBlock(world, x + 5, y + 6, z + 13, 2, cell);
         placeBlock(world, x + 5, y + 7, z + 13, 2, cell);
         placeBlock(world, x + 5, y + 8, z + 13, 2, cell);
         placeBlock(world, x + 5, y + 9, z + 13, 2, cell);
         placeBlock(world, x + 5, y + 10, z + 13, 2, cell);
         placeBlock(world, x + 6, y + 2, z + 3, 2, cell);
         placeBlock(world, x + 6, y + 3, z + 3, 2, cell);
         placeBlock(world, x + 6, y + 4, z + 3, 2, cell);
         placeBlock(world, x + 6, y + 5, z + 3, 2, cell);
         placeBlock(world, x + 6, y + 6, z + 3, 2, cell);
         placeBlock(world, x + 6, y + 7, z + 3, 2, cell);
         placeBlock(world, x + 6, y + 8, z + 3, 2, cell);
         placeBlock(world, x + 6, y + 9, z + 3, 2, cell);
         placeBlock(world, x + 6, y + 10, z + 3, 2, cell);
         placeBlock(world, x + 6, y + 2, z + 13, 2, cell);
         placeBlock(world, x + 6, y + 3, z + 13, 2, cell);
         placeBlock(world, x + 6, y + 4, z + 13, 2, cell);
         placeBlock(world, x + 6, y + 5, z + 13, 2, cell);
         placeBlock(world, x + 6, y + 6, z + 13, 2, cell);
         placeBlock(world, x + 6, y + 7, z + 13, 2, cell);
         placeBlock(world, x + 6, y + 8, z + 13, 2, cell);
         placeBlock(world, x + 6, y + 9, z + 13, 2, cell);
         placeBlock(world, x + 6, y + 10, z + 13, 2, cell);
         placeBlock(world, x + 7, y + 2, z + 3, 2, cell);
         placeBlock(world, x + 7, y + 3, z + 3, 2, cell);
         placeBlock(world, x + 7, y + 4, z + 3, 2, cell);
         placeBlock(world, x + 7, y + 5, z + 3, 2, cell);
         placeBlock(world, x + 7, y + 6, z + 3, 2, cell);
         placeBlock(world, x + 7, y + 7, z + 3, 2, cell);
         placeBlock(world, x + 7, y + 8, z + 3, 2, cell);
         placeBlock(world, x + 7, y + 9, z + 3, 2, cell);
         placeBlock(world, x + 7, y + 10, z + 3, 2, cell);
         placeBlock(world, x + 7, y + 2, z + 13, 2, cell);
         placeBlock(world, x + 7, y + 3, z + 13, 2, cell);
         placeBlock(world, x + 7, y + 4, z + 13, 2, cell);
         placeBlock(world, x + 7, y + 5, z + 13, 2, cell);
         placeBlock(world, x + 7, y + 6, z + 13, 2, cell);
         placeBlock(world, x + 7, y + 7, z + 13, 2, cell);
         placeBlock(world, x + 7, y + 8, z + 13, 2, cell);
         placeBlock(world, x + 7, y + 9, z + 13, 2, cell);
         placeBlock(world, x + 7, y + 10, z + 13, 2, cell);
         placeBlock(world, x + 8, y + 2, z + 3, 2, cell);
         placeBlock(world, x + 8, y + 3, z + 3, 2, cell);
         placeBlock(world, x + 8, y + 4, z + 3, 2, cell);
         placeBlock(world, x + 8, y + 5, z + 3, 2, cell);
         placeBlock(world, x + 8, y + 6, z + 3, 2, cell);
         placeBlock(world, x + 8, y + 7, z + 3, 2, cell);
         placeBlock(world, x + 8, y + 8, z + 3, 2, cell);
         placeBlock(world, x + 8, y + 9, z + 3, 2, cell);
         placeBlock(world, x + 8, y + 10, z + 3, 2, cell);
         placeBlock(world, x + 8, y + 2, z + 13, 2, cell);
         placeBlock(world, x + 8, y + 3, z + 13, 2, cell);
         placeBlock(world, x + 8, y + 4, z + 13, 2, cell);
         placeBlock(world, x + 8, y + 5, z + 13, 2, cell);
         placeBlock(world, x + 8, y + 6, z + 13, 2, cell);
         placeBlock(world, x + 8, y + 7, z + 13, 2, cell);
         placeBlock(world, x + 8, y + 8, z + 13, 2, cell);
         placeBlock(world, x + 8, y + 9, z + 13, 2, cell);
         placeBlock(world, x + 8, y + 10, z + 13, 2, cell);
         placeBlock(world, x + 9, y + 2, z + 3, 2, cell);
         placeBlock(world, x + 9, y + 3, z + 3, 2, cell);
         placeBlock(world, x + 9, y + 4, z + 3, 2, cell);
         placeBlock(world, x + 9, y + 5, z + 3, 2, cell);
         placeBlock(world, x + 9, y + 6, z + 3, 2, cell);
         placeBlock(world, x + 9, y + 7, z + 3, 2, cell);
         placeBlock(world, x + 9, y + 8, z + 3, 2, cell);
         placeBlock(world, x + 9, y + 9, z + 3, 2, cell);
         placeBlock(world, x + 9, y + 10, z + 3, 2, cell);
         placeBlock(world, x + 9, y + 2, z + 13, 2, cell);
         placeBlock(world, x + 9, y + 3, z + 13, 2, cell);
         placeBlock(world, x + 9, y + 4, z + 13, 2, cell);
         placeBlock(world, x + 9, y + 5, z + 13, 2, cell);
         placeBlock(world, x + 9, y + 6, z + 13, 2, cell);
         placeBlock(world, x + 9, y + 7, z + 13, 2, cell);
         placeBlock(world, x + 9, y + 8, z + 13, 2, cell);
         placeBlock(world, x + 9, y + 9, z + 13, 2, cell);
         placeBlock(world, x + 9, y + 10, z + 13, 2, cell);
         placeBlock(world, x + 10, y + 2, z + 3, 2, cell);
         placeBlock(world, x + 10, y + 3, z + 3, 2, cell);
         placeBlock(world, x + 10, y + 4, z + 3, 2, cell);
         placeBlock(world, x + 10, y + 5, z + 3, 2, cell);
         placeBlock(world, x + 10, y + 6, z + 3, 2, cell);
         placeBlock(world, x + 10, y + 7, z + 3, 2, cell);
         placeBlock(world, x + 10, y + 8, z + 3, 2, cell);
         placeBlock(world, x + 10, y + 9, z + 3, 2, cell);
         placeBlock(world, x + 10, y + 10, z + 3, 2, cell);
         placeBlock(world, x + 10, y + 2, z + 13, 2, cell);
         placeBlock(world, x + 10, y + 3, z + 13, 2, cell);
         placeBlock(world, x + 10, y + 4, z + 13, 2, cell);
         placeBlock(world, x + 10, y + 5, z + 13, 2, cell);
         placeBlock(world, x + 10, y + 6, z + 13, 2, cell);
         placeBlock(world, x + 10, y + 7, z + 13, 2, cell);
         placeBlock(world, x + 10, y + 8, z + 13, 2, cell);
         placeBlock(world, x + 10, y + 9, z + 13, 2, cell);
         placeBlock(world, x + 10, y + 10, z + 13, 2, cell);
         placeBlock(world, x + 11, y + 3, z + 3, 2, cell);
         placeBlock(world, x + 11, y + 4, z + 3, 2, cell);
         placeBlock(world, x + 11, y + 5, z + 3, 2, cell);
         placeBlock(world, x + 11, y + 6, z + 3, 2, cell);
         placeBlock(world, x + 11, y + 7, z + 3, 2, cell);
         placeBlock(world, x + 11, y + 8, z + 3, 2, cell);
         placeBlock(world, x + 11, y + 9, z + 3, 2, cell);
         placeBlock(world, x + 11, y + 10, z + 3, 2, cell);
         placeBlock(world, x + 11, y + 3, z + 13, 2, cell);
         placeBlock(world, x + 11, y + 4, z + 13, 2, cell);
         placeBlock(world, x + 11, y + 5, z + 13, 2, cell);
         placeBlock(world, x + 11, y + 6, z + 13, 2, cell);
         placeBlock(world, x + 11, y + 7, z + 13, 2, cell);
         placeBlock(world, x + 11, y + 8, z + 13, 2, cell);
         placeBlock(world, x + 11, y + 9, z + 13, 2, cell);
         placeBlock(world, x + 11, y + 10, z + 13, 2, cell);
         placeBlock(world, x + 13, y + 3, z + 5, 2, cell);
         placeBlock(world, x + 13, y + 4, z + 5, 2, cell);
         placeBlock(world, x + 13, y + 5, z + 5, 2, cell);
         placeBlock(world, x + 13, y + 6, z + 5, 2, cell);
         placeBlock(world, x + 13, y + 7, z + 5, 2, cell);
         placeBlock(world, x + 13, y + 8, z + 5, 2, cell);
         placeBlock(world, x + 13, y + 9, z + 5, 2, cell);
         placeBlock(world, x + 13, y + 10, z + 5, 2, cell);
         placeBlock(world, x + 13, y + 2, z + 6, 2, cell);
         placeBlock(world, x + 13, y + 3, z + 6, 2, cell);
         placeBlock(world, x + 13, y + 4, z + 6, 2, cell);
         placeBlock(world, x + 13, y + 5, z + 6, 2, cell);
         placeBlock(world, x + 13, y + 6, z + 6, 2, cell);
         placeBlock(world, x + 13, y + 7, z + 6, 2, cell);
         placeBlock(world, x + 13, y + 8, z + 6, 2, cell);
         placeBlock(world, x + 13, y + 9, z + 6, 2, cell);
         placeBlock(world, x + 13, y + 10, z + 6, 2, cell);
         placeBlock(world, x + 13, y + 2, z + 7, 2, cell);
         placeBlock(world, x + 13, y + 3, z + 7, 2, cell);
         placeBlock(world, x + 13, y + 4, z + 7, 2, cell);
         placeBlock(world, x + 13, y + 5, z + 7, 2, cell);
         placeBlock(world, x + 13, y + 6, z + 7, 2, cell);
         placeBlock(world, x + 13, y + 7, z + 7, 2, cell);
         placeBlock(world, x + 13, y + 8, z + 7, 2, cell);
         placeBlock(world, x + 13, y + 9, z + 7, 2, cell);
         placeBlock(world, x + 13, y + 10, z + 7, 2, cell);
         placeBlock(world, x + 13, y + 2, z + 8, 2, cell);
         placeBlock(world, x + 13, y + 3, z + 8, 2, cell);
         placeBlock(world, x + 13, y + 4, z + 8, 2, cell);
         placeBlock(world, x + 13, y + 5, z + 8, 2, cell);
         placeBlock(world, x + 13, y + 6, z + 8, 2, cell);
         placeBlock(world, x + 13, y + 7, z + 8, 2, cell);
         placeBlock(world, x + 13, y + 8, z + 8, 2, cell);
         placeBlock(world, x + 13, y + 9, z + 8, 2, cell);
         placeBlock(world, x + 13, y + 10, z + 8, 2, cell);
         placeBlock(world, x + 13, y + 2, z + 9, 2, cell);
         placeBlock(world, x + 13, y + 3, z + 9, 2, cell);
         placeBlock(world, x + 13, y + 4, z + 9, 2, cell);
         placeBlock(world, x + 13, y + 5, z + 9, 2, cell);
         placeBlock(world, x + 13, y + 6, z + 9, 2, cell);
         placeBlock(world, x + 13, y + 7, z + 9, 2, cell);
         placeBlock(world, x + 13, y + 8, z + 9, 2, cell);
         placeBlock(world, x + 13, y + 9, z + 9, 2, cell);
         placeBlock(world, x + 13, y + 10, z + 9, 2, cell);
         placeBlock(world, x + 13, y + 2, z + 10, 2, cell);
         placeBlock(world, x + 13, y + 3, z + 10, 2, cell);
         placeBlock(world, x + 13, y + 4, z + 10, 2, cell);
         placeBlock(world, x + 13, y + 5, z + 10, 2, cell);
         placeBlock(world, x + 13, y + 6, z + 10, 2, cell);
         placeBlock(world, x + 13, y + 7, z + 10, 2, cell);
         placeBlock(world, x + 13, y + 8, z + 10, 2, cell);
         placeBlock(world, x + 13, y + 9, z + 10, 2, cell);
         placeBlock(world, x + 13, y + 10, z + 10, 2, cell);
         placeBlock(world, x + 13, y + 3, z + 11, 2, cell);
         placeBlock(world, x + 13, y + 4, z + 11, 2, cell);
         placeBlock(world, x + 13, y + 5, z + 11, 2, cell);
         placeBlock(world, x + 13, y + 6, z + 11, 2, cell);
         placeBlock(world, x + 13, y + 7, z + 11, 2, cell);
         placeBlock(world, x + 13, y + 8, z + 11, 2, cell);
         placeBlock(world, x + 13, y + 9, z + 11, 2, cell);
         placeBlock(world, x + 13, y + 10, z + 11, 2, cell);
         placeBlock(world, x + 2, y + -1, z + 2, 1, cell);
         placeBlock(world, x + 2, y , z + 2, 8, cell);
         placeBlock(world, x + 2, y + 13, z + 2, 1, cell);
         placeBlock(world, x + 2, y + 12, z + 2, 8, cell);
         placeBlock(world, x + 2, y + 11, z + 2, 2, cell);
         placeBlock(world, x + 2, y + 1, z + 2, 19, cell);
         placeBlock(world, x + 2, y + 2, z + 2, 19, cell);
         placeBlock(world, x + 2, y + 3, z + 2, 19, cell);
         placeBlock(world, x + 2, y + 4, z + 2, 19, cell);
         placeBlock(world, x + 2, y + 5, z + 2, 19, cell);
         placeBlock(world, x + 2, y + -1, z + 3, 1, cell);
         placeBlock(world, x + 2, y , z + 3, 8, cell);
         placeBlock(world, x + 2, y + 13, z + 3, 1, cell);
         placeBlock(world, x + 2, y + 12, z + 3, 8, cell);
         placeBlock(world, x + 2, y + 11, z + 3, 2, cell);
         placeBlock(world, x + 2, y + 1, z + 3, 19, cell);
         placeBlock(world, x + 2, y + 2, z + 3, 19, cell);
         placeBlock(world, x + 2, y + 3, z + 3, 19, cell);
         placeBlock(world, x + 2, y + 4, z + 3, 19, cell);
         placeBlock(world, x + 2, y + -1, z + 4, 1, cell);
         placeBlock(world, x + 2, y , z + 4, 8, cell);
         placeBlock(world, x + 2, y + 13, z + 4, 1, cell);
         placeBlock(world, x + 2, y + 12, z + 4, 8, cell);
         placeBlock(world, x + 2, y + 11, z + 4, 2, cell);
         placeBlock(world, x + 2, y + 1, z + 4, 19, cell);
         placeBlock(world, x + 2, y + 2, z + 4, 19, cell);
         placeBlock(world, x + 2, y + 3, z + 4, 19, cell);
         placeBlock(world, x + 2, y + -1, z + 5, 1, cell);
         placeBlock(world, x + 2, y , z + 5, 8, cell);
         placeBlock(world, x + 2, y + 13, z + 5, 1, cell);
         placeBlock(world, x + 2, y + 12, z + 5, 8, cell);
         placeBlock(world, x + 2, y + 11, z + 5, 2, cell);
         placeBlock(world, x + 2, y + 1, z + 5, 19, cell);
         placeBlock(world, x + 2, y + 2, z + 5, 19, cell);
         placeBlock(world, x + 2, y + -1, z + 6, 1, cell);
         placeBlock(world, x + 2, y , z + 6, 8, cell);
         placeBlock(world, x + 2, y + 13, z + 6, 1, cell);
         placeBlock(world, x + 2, y + 12, z + 6, 8, cell);
         placeBlock(world, x + 2, y + 11, z + 6, 2, cell);
         placeBlock(world, x + 2, y + 1, z + 6, 19, cell);
         placeBlock(world, x + 2, y + -1, z + 7, 1, cell);
         placeBlock(world, x + 2, y , z + 7, 8, cell);
         placeBlock(world, x + 2, y + 1, z + 7, 19, cell);
         placeBlock(world, x + 2, y + 13, z + 7, 1, cell);
         placeBlock(world, x + 2, y + 12, z + 7, 8, cell);
         placeBlock(world, x + 2, y + 11, z + 7, 2, cell);
         placeBlock(world, x + 2, y + -1, z + 8, 1, cell);
         placeBlock(world, x + 2, y , z + 8, 8, cell);
         placeBlock(world, x + 2, y + 1, z + 8, 19, cell);
         placeBlock(world, x + 2, y + 13, z + 8, 1, cell);
         placeBlock(world, x + 2, y + 12, z + 8, 8, cell);
         placeBlock(world, x + 2, y + 11, z + 8, 2, cell);
         placeBlock(world, x + 2, y + -1, z + 9, 1, cell);
         placeBlock(world, x + 2, y , z + 9, 8, cell);
         placeBlock(world, x + 2, y + 1, z + 9, 19, cell);
         placeBlock(world, x + 2, y + 13, z + 9, 1, cell);
         placeBlock(world, x + 2, y + 12, z + 9, 8, cell);
         placeBlock(world, x + 2, y + 11, z + 9, 2, cell);
         placeBlock(world, x + 2, y + -1, z + 10, 1, cell);
         placeBlock(world, x + 2, y , z + 10, 8, cell);
         placeBlock(world, x + 2, y + 13, z + 10, 1, cell);
         placeBlock(world, x + 2, y + 12, z + 10, 8, cell);
         placeBlock(world, x + 2, y + 11, z + 10, 2, cell);
         placeBlock(world, x + 2, y + 1, z + 10, 19, cell);
         placeBlock(world, x + 2, y + -1, z + 11, 1, cell);
         placeBlock(world, x + 2, y , z + 11, 8, cell);
         placeBlock(world, x + 2, y + 13, z + 11, 1, cell);
         placeBlock(world, x + 2, y + 12, z + 11, 8, cell);
         placeBlock(world, x + 2, y + 11, z + 11, 2, cell);
         placeBlock(world, x + 2, y + 1, z + 11, 19, cell);
         placeBlock(world, x + 2, y + 2, z + 11, 19, cell);
         placeBlock(world, x + 2, y + -1, z + 12, 1, cell);
         placeBlock(world, x + 2, y , z + 12, 8, cell);
         placeBlock(world, x + 2, y + 13, z + 12, 1, cell);
         placeBlock(world, x + 2, y + 12, z + 12, 8, cell);
         placeBlock(world, x + 2, y + 11, z + 12, 2, cell);
         placeBlock(world, x + 2, y + 1, z + 12, 19, cell);
         placeBlock(world, x + 2, y + 2, z + 12, 19, cell);
         placeBlock(world, x + 2, y + 3, z + 12, 19, cell);
         placeBlock(world, x + 2, y + -1, z + 13, 1, cell);
         placeBlock(world, x + 2, y , z + 13, 8, cell);
         placeBlock(world, x + 2, y + 13, z + 13, 1, cell);
         placeBlock(world, x + 2, y + 12, z + 13, 8, cell);
         placeBlock(world, x + 2, y + 11, z + 13, 2, cell);
         placeBlock(world, x + 2, y + 1, z + 13, 19, cell);
         placeBlock(world, x + 2, y + 2, z + 13, 19, cell);
         placeBlock(world, x + 2, y + 3, z + 13, 19, cell);
         placeBlock(world, x + 2, y + 4, z + 13, 19, cell);
         placeBlock(world, x + 2, y + -1, z + 14, 1, cell);
         placeBlock(world, x + 2, y , z + 14, 8, cell);
         placeBlock(world, x + 2, y + 13, z + 14, 1, cell);
         placeBlock(world, x + 2, y + 12, z + 14, 8, cell);
         placeBlock(world, x + 2, y + 11, z + 14, 2, cell);
         placeBlock(world, x + 2, y + 1, z + 14, 19, cell);
         placeBlock(world, x + 2, y + 2, z + 14, 19, cell);
         placeBlock(world, x + 2, y + 3, z + 14, 19, cell);
         placeBlock(world, x + 2, y + 4, z + 14, 19, cell);
         placeBlock(world, x + 2, y + 5, z + 14, 19, cell);
         placeBlock(world, x + 3, y + -1, z + 2, 1, cell);
         placeBlock(world, x + 3, y , z + 2, 8, cell);
         placeBlock(world, x + 3, y + 13, z + 2, 1, cell);
         placeBlock(world, x + 3, y + 12, z + 2, 8, cell);
         placeBlock(world, x + 3, y + 11, z + 2, 2, cell);
         placeBlock(world, x + 3, y + 1, z + 2, 19, cell);
         placeBlock(world, x + 3, y + 2, z + 2, 19, cell);
         placeBlock(world, x + 3, y + 3, z + 2, 19, cell);
         placeBlock(world, x + 3, y + 4, z + 2, 19, cell);
         placeBlock(world, x + 3, y + -1, z + 3, 1, cell);
         placeBlock(world, x + 3, y , z + 3, 8, cell);
         placeBlock(world, x + 3, y + 13, z + 3, 1, cell);
         placeBlock(world, x + 3, y + 12, z + 3, 8, cell);
         placeBlock(world, x + 3, y + -1, z + 4, 1, cell);
         placeBlock(world, x + 3, y , z + 4, 8, cell);
         placeBlock(world, x + 3, y + 13, z + 4, 1, cell);
         placeBlock(world, x + 3, y + 12, z + 4, 8, cell);
         placeBlock(world, x + 3, y + -1, z + 5, 1, cell);
         placeBlock(world, x + 3, y , z + 5, 8, cell);
         placeBlock(world, x + 3, y + 13, z + 5, 1, cell);
         placeBlock(world, x + 3, y + 12, z + 5, 8, cell);
         placeBlock(world, x + 3, y + 11, z + 5, 2, cell);
         placeBlock(world, x + 3, y + 1, z + 5, 19, cell);
         placeBlock(world, x + 3, y + 2, z + 5, 19, cell);
         placeBlock(world, x + 3, y + -1, z + 6, 1, cell);
         placeBlock(world, x + 3, y , z + 6, 8, cell);
         placeBlock(world, x + 3, y + 13, z + 6, 1, cell);
         placeBlock(world, x + 3, y + 12, z + 6, 8, cell);
         placeBlock(world, x + 3, y + 11, z + 6, 2, cell);
         placeBlock(world, x + 3, y + 1, z + 6, 19, cell);
         placeBlock(world, x + 3, y + -1, z + 7, 1, cell);
         placeBlock(world, x + 3, y , z + 7, 8, cell);
         placeBlock(world, x + 3, y + 1, z + 7, 19, cell);
         placeBlock(world, x + 3, y + 13, z + 7, 1, cell);
         placeBlock(world, x + 3, y + 12, z + 7, 8, cell);
         placeBlock(world, x + 3, y + 11, z + 7, 2, cell);
         placeBlock(world, x + 3, y + -1, z + 8, 1, cell);
         placeBlock(world, x + 3, y , z + 8, 8, cell);
         placeBlock(world, x + 3, y + 1, z + 8, 19, cell);
         placeBlock(world, x + 3, y + 13, z + 8, 1, cell);
         placeBlock(world, x + 3, y + 12, z + 8, 8, cell);
         placeBlock(world, x + 3, y + 11, z + 8, 2, cell);
         placeBlock(world, x + 3, y + -1, z + 9, 1, cell);
         placeBlock(world, x + 3, y , z + 9, 8, cell);
         placeBlock(world, x + 3, y + 1, z + 9, 19, cell);
         placeBlock(world, x + 3, y + 13, z + 9, 1, cell);
         placeBlock(world, x + 3, y + 12, z + 9, 8, cell);
         placeBlock(world, x + 3, y + 11, z + 9, 2, cell);
         placeBlock(world, x + 3, y + -1, z + 10, 1, cell);
         placeBlock(world, x + 3, y , z + 10, 8, cell);
         placeBlock(world, x + 3, y + 13, z + 10, 1, cell);
         placeBlock(world, x + 3, y + 12, z + 10, 8, cell);
         placeBlock(world, x + 3, y + 11, z + 10, 2, cell);
         placeBlock(world, x + 3, y + 1, z + 10, 19, cell);
         placeBlock(world, x + 3, y + -1, z + 11, 1, cell);
         placeBlock(world, x + 3, y , z + 11, 8, cell);
         placeBlock(world, x + 3, y + 13, z + 11, 1, cell);
         placeBlock(world, x + 3, y + 12, z + 11, 8, cell);
         placeBlock(world, x + 3, y + 11, z + 11, 2, cell);
         placeBlock(world, x + 3, y + 1, z + 11, 19, cell);
         placeBlock(world, x + 3, y + 2, z + 11, 19, cell);
         placeBlock(world, x + 3, y + -1, z + 12, 1, cell);
         placeBlock(world, x + 3, y , z + 12, 8, cell);
         placeBlock(world, x + 3, y + 13, z + 12, 1, cell);
         placeBlock(world, x + 3, y + 12, z + 12, 8, cell);
         placeBlock(world, x + 3, y + -1, z + 13, 1, cell);
         placeBlock(world, x + 3, y , z + 13, 8, cell);
         placeBlock(world, x + 3, y + 13, z + 13, 1, cell);
         placeBlock(world, x + 3, y + 12, z + 13, 8, cell);
         placeBlock(world, x + 3, y + -1, z + 14, 1, cell);
         placeBlock(world, x + 3, y , z + 14, 8, cell);
         placeBlock(world, x + 3, y + 13, z + 14, 1, cell);
         placeBlock(world, x + 3, y + 12, z + 14, 8, cell);
         placeBlock(world, x + 3, y + 11, z + 14, 2, cell);
         placeBlock(world, x + 3, y + 1, z + 14, 19, cell);
         placeBlock(world, x + 3, y + 2, z + 14, 19, cell);
         placeBlock(world, x + 3, y + 3, z + 14, 19, cell);
         placeBlock(world, x + 3, y + 4, z + 14, 19, cell);
         placeBlock(world, x + 4, y + -1, z + 2, 1, cell);
         placeBlock(world, x + 4, y , z + 2, 8, cell);
         placeBlock(world, x + 4, y + 13, z + 2, 1, cell);
         placeBlock(world, x + 4, y + 12, z + 2, 8, cell);
         placeBlock(world, x + 4, y + 11, z + 2, 2, cell);
         placeBlock(world, x + 4, y + 1, z + 2, 19, cell);
         placeBlock(world, x + 4, y + 2, z + 2, 19, cell);
         placeBlock(world, x + 4, y + 3, z + 2, 19, cell);
         placeBlock(world, x + 4, y + -1, z + 3, 1, cell);
         placeBlock(world, x + 4, y , z + 3, 8, cell);
         placeBlock(world, x + 4, y + 13, z + 3, 1, cell);
         placeBlock(world, x + 4, y + 12, z + 3, 8, cell);
         placeBlock(world, x + 4, y + -1, z + 4, 1, cell);
         placeBlock(world, x + 4, y , z + 4, 8, cell);
         placeBlock(world, x + 4, y + 13, z + 4, 1, cell);
         placeBlock(world, x + 4, y + 12, z + 4, 8, cell);
         placeBlock(world, x + 4, y + -1, z + 5, 1, cell);
         placeBlock(world, x + 4, y , z + 5, 8, cell);
         placeBlock(world, x + 4, y + 13, z + 5, 1, cell);
         placeBlock(world, x + 4, y + 12, z + 5, 8, cell);
         placeBlock(world, x + 4, y + 1, z + 5, 19, cell);
         placeBlock(world, x + 4, y + 2, z + 5, 19, cell);
         placeBlock(world, x + 4, y + 11, z + 5, 19, cell);
         placeBlock(world, x + 4, y + 10, z + 5, 19, cell);
         placeBlock(world, x + 4, y + 9, z + 5, 19, cell);
         placeBlock(world, x + 4, y + -1, z + 6, 1, cell);
         placeBlock(world, x + 4, y , z + 6, 8, cell);
         placeBlock(world, x + 4, y + 13, z + 6, 1, cell);
         placeBlock(world, x + 4, y + 12, z + 6, 8, cell);
         placeBlock(world, x + 4, y + 1, z + 6, 19, cell);
         placeBlock(world, x + 4, y + 11, z + 6, 19, cell);
         placeBlock(world, x + 4, y + 10, z + 6, 19, cell);
         placeBlock(world, x + 4, y + -1, z + 7, 1, cell);
         placeBlock(world, x + 4, y , z + 7, 8, cell);
         placeBlock(world, x + 4, y + 1, z + 7, 19, cell);
         placeBlock(world, x + 4, y + 13, z + 7, 1, cell);
         placeBlock(world, x + 4, y + 12, z + 7, 8, cell);
         placeBlock(world, x + 4, y + 11, z + 7, 19, cell);
         placeBlock(world, x + 4, y + -1, z + 8, 1, cell);
         placeBlock(world, x + 4, y , z + 8, 8, cell);
         placeBlock(world, x + 4, y + 1, z + 8, 19, cell);
         placeBlock(world, x + 4, y + 13, z + 8, 1, cell);
         placeBlock(world, x + 4, y + 12, z + 8, 8, cell);
         placeBlock(world, x + 4, y + 11, z + 8, 2, cell);
         placeBlock(world, x + 4, y + -1, z + 9, 1, cell);
         placeBlock(world, x + 4, y , z + 9, 8, cell);
         placeBlock(world, x + 4, y + 1, z + 9, 19, cell);
         placeBlock(world, x + 4, y + 13, z + 9, 1, cell);
         placeBlock(world, x + 4, y + 12, z + 9, 8, cell);
         placeBlock(world, x + 4, y + 11, z + 9, 19, cell);
         placeBlock(world, x + 4, y + -1, z + 10, 1, cell);
         placeBlock(world, x + 4, y , z + 10, 8, cell);
         placeBlock(world, x + 4, y + 13, z + 10, 1, cell);
         placeBlock(world, x + 4, y + 12, z + 10, 8, cell);
         placeBlock(world, x + 4, y + 1, z + 10, 19, cell);
         placeBlock(world, x + 4, y + 11, z + 10, 19, cell);
         placeBlock(world, x + 4, y + 10, z + 10, 19, cell);
