package thaumcraft.common.lib.world;

import java.util.Random;
import net.minecraft.block.Block;
import net.minecraft.init.Blocks;
import net.minecraft.tileentity.TileEntityChest;
import net.minecraft.tileentity.TileEntityMobSpawner;
import net.minecraft.world.World;
import net.minecraft.util.ResourceLocation;
import net.minecraft.world.gen.feature.WorldGenerator;
import net.minecraft.world.storage.loot.LootTableList;
import thaumcraft.common.config.ConfigBlocks;
import net.minecraft.util.math.BlockPos;

public class WorldGenMound extends WorldGenerator {
   protected static Block[] GetValidSpawnBlocks() {
      return new Block[]{Blocks.STONE, Blocks.GRASS, Blocks.DIRT};
   }

   public static boolean LocationIsValidSpawn(World world, int i, int j, int k) {
      int distanceToAir = 0;

      for(Block checkID = world.getBlockState(new BlockPos(i, j, k)).getBlock(); checkID != Blocks.AIR; checkID = world.getBlockState(new net.minecraft.util.math.BlockPos(i, j + distanceToAir, k)).getBlock()) {
         ++distanceToAir;
      }

       if (distanceToAir <= 2) {
           j += distanceToAir - 1;
           Block blockID = world.getBlockState(new BlockPos(i, j, k)).getBlock();
           Block blockIDAbove = world.getBlockState(new net.minecraft.util.math.BlockPos(i, j + 1, k)).getBlock();
           Block blockIDBelow = world.getBlockState(new net.minecraft.util.math.BlockPos(i, j - 1, k)).getBlock();

           for (Block x : GetValidSpawnBlocks()) {
               if (blockIDAbove != Blocks.AIR) {
                   return false;
               }

               if (blockID == x) {
                   return true;
               }

               if ((blockID == Blocks.SNOW_LAYER || blockID == Blocks.TALLGRASS) && blockIDBelow == x) {
                   return true;
               }
           }

       }
       return false;
   }

   @Override
   public boolean generate(World world, Random rand, BlockPos pos) {
      return generateStatic(world, rand, pos.getX(), pos.getY(), pos.getZ());
   }

   private boolean doGenerate(World world, Random rand, int i, int j, int k) {
      return generateStatic(world, rand, i, j, k);
   }
   public static boolean generateStatic(World world, Random rand, int i, int j, int k) {
      if (LocationIsValidSpawn(world, i + 9, j + 9, k + 9) && LocationIsValidSpawn(world, i, j + 9, k) && LocationIsValidSpawn(world, i + 18, j + 9, k) && LocationIsValidSpawn(world, i + 18, j + 9, k + 18) && LocationIsValidSpawn(world, i, j + 9, k + 18)) {
        world.setBlockState(new net.minecraft.util.math.BlockPos(i, j + 8, k + 4), (Blocks.DIRT).getDefaultState(), 3);
        world.setBlockState(new net.minecraft.util.math.BlockPos(i, j + 8, k + 5), (Blocks.DIRT).getDefaultState(), 3);
        world.setBlockState(new net.minecraft.util.math.BlockPos(i, j + 8, k + 6), (Blocks.DIRT).getDefaultState(), 3);
        world.setBlockState(new net.minecraft.util.math.BlockPos(i, j + 8, k + 7), (Blocks.DIRT).getDefaultState(), 3);
        world.setBlockState(new net.minecraft.util.math.BlockPos(i, j + 8, k + 8), (Blocks.COBBLESTONE).getDefaultState(), 3);
        world.setBlockState(new net.minecraft.util.math.BlockPos(i, j + 8, k + 9), (Blocks.COBBLESTONE).getDefaultState(), 3);
        world.setBlockState(new net.minecraft.util.math.BlockPos(i, j + 8, k + 10), (Blocks.COBBLESTONE).getDefaultState(), 3);
        world.setBlockState(new net.minecraft.util.math.BlockPos(i, j + 8, k + 11), (Blocks.DIRT).getDefaultState(), 3);
        world.setBlockState(new net.minecraft.util.math.BlockPos(i, j + 8, k + 12), (Blocks.DIRT).getDefaultState(), 3);
        world.setBlockState(new net.minecraft.util.math.BlockPos(i, j + 8, k + 13), (Blocks.DIRT).getDefaultState(), 3);
        world.setBlockState(new net.minecraft.util.math.BlockPos(i, j + 8, k + 14), (Blocks.DIRT).getDefaultState(), 3);
        world.setBlockState(new net.minecraft.util.math.BlockPos(i, j + 9, k + 4), (Blocks.GRASS).getDefaultState(), 3);
        world.setBlockState(new net.minecraft.util.math.BlockPos(i, j + 9, k + 5), (Blocks.GRASS).getDefaultState(), 3);
        world.setBlockState(new net.minecraft.util.math.BlockPos(i, j + 9, k + 6), (Blocks.GRASS).getDefaultState(), 3);
        world.setBlockState(new net.minecraft.util.math.BlockPos(i, j + 9, k + 7), (Blocks.GRASS).getDefaultState(), 3);
        world.setBlockState(new net.minecraft.util.math.BlockPos(i, j + 9, k + 8), (Blocks.STONE_STAIRS).getDefaultState(), 3);
        world.setBlockState(new net.minecraft.util.math.BlockPos(i, j + 9, k + 9), (Blocks.AIR).getDefaultState(), 3);
        world.setBlockState(new net.minecraft.util.math.BlockPos(i, j + 9, k + 10), (Blocks.STONE_STAIRS).getDefaultState(), 3);
        world.setBlockState(new net.minecraft.util.math.BlockPos(i, j + 9, k + 11), (Blocks.GRASS).getDefaultState(), 3);
        world.setBlockState(new net.minecraft.util.math.BlockPos(i, j + 9, k + 12), (Blocks.GRASS).getDefaultState(), 3);
        world.setBlockState(new net.minecraft.util.math.BlockPos(i, j + 9, k + 13), (Blocks.GRASS).getDefaultState(), 3);
        world.setBlockState(new net.minecraft.util.math.BlockPos(i, j + 9, k + 14), (Blocks.GRASS).getDefaultState(), 3);
        world.setBlockState(new net.minecraft.util.math.BlockPos(i, j + 10, k + 8), (Blocks.AIR).getDefaultState(), 3);
        world.setBlockState(new net.minecraft.util.math.BlockPos(i, j + 10, k + 9), (Blocks.AIR).getDefaultState(), 3);
        world.setBlockState(new net.minecraft.util.math.BlockPos(i, j + 10, k + 10), (Blocks.AIR).getDefaultState(), 3);
        world.setBlockState(new net.minecraft.util.math.BlockPos(i + 1, j + 8, k + 3), (Blocks.DIRT).getDefaultState(), 3);
        world.setBlockState(new net.minecraft.util.math.BlockPos(i + 1, j + 8, k + 4), (Blocks.DIRT).getDefaultState(), 3);
        world.setBlockState(new net.minecraft.util.math.BlockPos(i + 1, j + 8, k + 5), (Blocks.DIRT).getDefaultState(), 3);
        world.setBlockState(new net.minecraft.util.math.BlockPos(i + 1, j + 8, k + 6), (Blocks.DIRT).getDefaultState(), 3);
        world.setBlockState(new net.minecraft.util.math.BlockPos(i + 1, j + 8, k + 7), (Blocks.DIRT).getDefaultState(), 3);
        world.setBlockState(new net.minecraft.util.math.BlockPos(i + 1, j + 8, k + 8), (Blocks.COBBLESTONE).getDefaultState(), 3);
        world.setBlockState(new net.minecraft.util.math.BlockPos(i + 1, j + 8, k + 9), (Blocks.COBBLESTONE).getDefaultState(), 3);
        world.setBlockState(new net.minecraft.util.math.BlockPos(i + 1, j + 8, k + 10), (Blocks.COBBLESTONE).getDefaultState(), 3);
        world.setBlockState(new net.minecraft.util.math.BlockPos(i + 1, j + 8, k + 11), (Blocks.DIRT).getDefaultState(), 3);
        world.setBlockState(new net.minecraft.util.math.BlockPos(i + 1, j + 8, k + 12), (Blocks.DIRT).getDefaultState(), 3);
        world.setBlockState(new net.minecraft.util.math.BlockPos(i + 1, j + 8, k + 13), (Blocks.DIRT).getDefaultState(), 3);
        world.setBlockState(new net.minecraft.util.math.BlockPos(i + 1, j + 8, k + 14), (Blocks.DIRT).getDefaultState(), 3);
        world.setBlockState(new net.minecraft.util.math.BlockPos(i + 1, j + 8, k + 15), (Blocks.DIRT).getDefaultState(), 3);
        world.setBlockState(new net.minecraft.util.math.BlockPos(i + 1, j + 9, k + 3), (Blocks.GRASS).getDefaultState(), 3);
        world.setBlockState(new net.minecraft.util.math.BlockPos(i + 1, j + 9, k + 4), (Blocks.DIRT).getDefaultState(), 3);
        world.setBlockState(new net.minecraft.util.math.BlockPos(i + 1, j + 9, k + 5), (Blocks.DIRT).getDefaultState(), 3);
        world.setBlockState(new net.minecraft.util.math.BlockPos(i + 1, j + 9, k + 6), (Blocks.DIRT).getDefaultState(), 3);
        world.setBlockState(new net.minecraft.util.math.BlockPos(i + 1, j + 9, k + 7), (Blocks.DIRT).getDefaultState(), 3);
        world.setBlockState(new net.minecraft.util.math.BlockPos(i + 1, j + 9, k + 8), (Blocks.COBBLESTONE).getDefaultState(), 3);
        world.setBlockState(new net.minecraft.util.math.BlockPos(i + 1, j + 9, k + 9), (Blocks.AIR).getDefaultState(), 3);
        world.setBlockState(new net.minecraft.util.math.BlockPos(i + 1, j + 9, k + 10), (Blocks.COBBLESTONE).getDefaultState(), 3);
        world.setBlockState(new net.minecraft.util.math.BlockPos(i + 1, j + 9, k + 11), (Blocks.DIRT).getDefaultState(), 3);
        world.setBlockState(new net.minecraft.util.math.BlockPos(i + 1, j + 9, k + 12), (Blocks.DIRT).getDefaultState(), 3);
        world.setBlockState(new net.minecraft.util.math.BlockPos(i + 1, j + 9, k + 13), (Blocks.DIRT).getDefaultState(), 3);
        world.setBlockState(new net.minecraft.util.math.BlockPos(i + 1, j + 9, k + 14), (Blocks.DIRT).getDefaultState(), 3);
        world.setBlockState(new net.minecraft.util.math.BlockPos(i + 1, j + 9, k + 15), (Blocks.GRASS).getDefaultState(), 3);
        world.setBlockState(new net.minecraft.util.math.BlockPos(i + 1, j + 10, k + 4), (Blocks.GRASS).getDefaultState(), 3);
        world.setBlockState(new net.minecraft.util.math.BlockPos(i + 1, j + 10, k + 5), (Blocks.GRASS).getDefaultState(), 3);
        world.setBlockState(new net.minecraft.util.math.BlockPos(i + 1, j + 10, k + 6), (Blocks.DIRT).getDefaultState(), 3);
        world.setBlockState(new net.minecraft.util.math.BlockPos(i + 1, j + 10, k + 7), (Blocks.DIRT).getDefaultState(), 3);
        world.setBlockState(new net.minecraft.util.math.BlockPos(i + 1, j + 10, k + 8), (Blocks.STONE_STAIRS).getDefaultState(), 3);
        world.setBlockState(new net.minecraft.util.math.BlockPos(i + 1, j + 10, k + 9), (Blocks.AIR).getDefaultState(), 3);
        world.setBlockState(new net.minecraft.util.math.BlockPos(i + 1, j + 10, k + 10), (Blocks.STONE_STAIRS).getDefaultState(), 3);
        world.setBlockState(new net.minecraft.util.math.BlockPos(i + 1, j + 10, k + 11), (Blocks.GRASS).getDefaultState(), 3);
        world.setBlockState(new net.minecraft.util.math.BlockPos(i + 1, j + 10, k + 12), (Blocks.GRASS).getDefaultState(), 3);
        world.setBlockState(new net.minecraft.util.math.BlockPos(i + 1, j + 10, k + 13), (Blocks.GRASS).getDefaultState(), 3);
        world.setBlockState(new net.minecraft.util.math.BlockPos(i + 1, j + 10, k + 14), (Blocks.GRASS).getDefaultState(), 3);
        world.setBlockState(new net.minecraft.util.math.BlockPos(i + 1, j + 11, k + 6), (Blocks.GRASS).getDefaultState(), 3);
        world.setBlockState(new net.minecraft.util.math.BlockPos(i + 1, j + 11, k + 7), (Blocks.GRASS).getDefaultState(), 3);
        world.setBlockState(new net.minecraft.util.math.BlockPos(i + 1, j + 11, k + 8), (Blocks.AIR).getDefaultState(), 3);
        world.setBlockState(new net.minecraft.util.math.BlockPos(i + 1, j + 11, k + 9), (Blocks.AIR).getDefaultState(), 3);
        world.setBlockState(new net.minecraft.util.math.BlockPos(i + 1, j + 11, k + 10), (Blocks.AIR).getDefaultState(), 3);
        world.setBlockState(new net.minecraft.util.math.BlockPos(i + 2, j + 8, k + 2), (Blocks.DIRT).getDefaultState(), 3);
        world.setBlockState(new net.minecraft.util.math.BlockPos(i + 2, j + 8, k + 3), (Blocks.DIRT).getDefaultState(), 3);
        world.setBlockState(new net.minecraft.util.math.BlockPos(i + 2, j + 8, k + 4), (Blocks.DIRT).getDefaultState(), 3);
        world.setBlockState(new net.minecraft.util.math.BlockPos(i + 2, j + 8, k + 5), (Blocks.DIRT).getDefaultState(), 3);
        world.setBlockState(new net.minecraft.util.math.BlockPos(i + 2, j + 8, k + 6), (Blocks.DIRT).getDefaultState(), 3);
        world.setBlockState(new net.minecraft.util.math.BlockPos(i + 2, j + 8, k + 7), (Blocks.COBBLESTONE).getDefaultState(), 3);
        world.setBlockState(new net.minecraft.util.math.BlockPos(i + 2, j + 8, k + 8), (Blocks.COBBLESTONE).getDefaultState(), 3);
        world.setBlockState(new net.minecraft.util.math.BlockPos(i + 2, j + 8, k + 9), (Blocks.MOSSY_COBBLESTONE).getDefaultState(), 3);
        world.setBlockState(new net.minecraft.util.math.BlockPos(i + 2, j + 8, k + 10), (Blocks.COBBLESTONE).getDefaultState(), 3);
        world.setBlockState(new net.minecraft.util.math.BlockPos(i + 2, j + 8, k + 11), (Blocks.COBBLESTONE).getDefaultState(), 3);
        world.setBlockState(new net.minecraft.util.math.BlockPos(i + 2, j + 8, k + 12), (Blocks.DIRT).getDefaultState(), 3);
        world.setBlockState(new net.minecraft.util.math.BlockPos(i + 2, j + 8, k + 13), (Blocks.DIRT).getDefaultState(), 3);
        world.setBlockState(new net.minecraft.util.math.BlockPos(i + 2, j + 8, k + 14), (Blocks.DIRT).getDefaultState(), 3);
        world.setBlockState(new net.minecraft.util.math.BlockPos(i + 2, j + 8, k + 15), (Blocks.DIRT).getDefaultState(), 3);
        world.setBlockState(new net.minecraft.util.math.BlockPos(i + 2, j + 8, k + 16), (Blocks.DIRT).getDefaultState(), 3);
        world.setBlockState(new net.minecraft.util.math.BlockPos(i + 2, j + 9, k + 2), (Blocks.GRASS).getDefaultState(), 3);
        world.setBlockState(new net.minecraft.util.math.BlockPos(i + 2, j + 9, k + 3), (Blocks.DIRT).getDefaultState(), 3);
        world.setBlockState(new net.minecraft.util.math.BlockPos(i + 2, j + 9, k + 4), (Blocks.DIRT).getDefaultState(), 3);
        world.setBlockState(new net.minecraft.util.math.BlockPos(i + 2, j + 9, k + 5), (Blocks.DIRT).getDefaultState(), 3);
        world.setBlockState(new net.minecraft.util.math.BlockPos(i + 2, j + 9, k + 6), (Blocks.DIRT).getDefaultState(), 3);
        world.setBlockState(new net.minecraft.util.math.BlockPos(i + 2, j + 9, k + 7), (Blocks.DIRT).getDefaultState(), 3);
        world.setBlockState(new net.minecraft.util.math.BlockPos(i + 2, j + 9, k + 8), (Blocks.COBBLESTONE).getDefaultState(), 3);
        world.setBlockState(new net.minecraft.util.math.BlockPos(i + 2, j + 9, k + 9), (Blocks.AIR).getDefaultState(), 3);
        world.setBlockState(new net.minecraft.util.math.BlockPos(i + 2, j + 9, k + 10), (Blocks.COBBLESTONE).getDefaultState(), 3);
        world.setBlockState(new net.minecraft.util.math.BlockPos(i + 2, j + 9, k + 11), (Blocks.DIRT).getDefaultState(), 3);
        world.setBlockState(new net.minecraft.util.math.BlockPos(i + 2, j + 9, k + 12), (Blocks.DIRT).getDefaultState(), 3);
        world.setBlockState(new net.minecraft.util.math.BlockPos(i + 2, j + 9, k + 13), (Blocks.DIRT).getDefaultState(), 3);
        world.setBlockState(new net.minecraft.util.math.BlockPos(i + 2, j + 9, k + 14), (Blocks.DIRT).getDefaultState(), 3);
        world.setBlockState(new net.minecraft.util.math.BlockPos(i + 2, j + 9, k + 15), (Blocks.DIRT).getDefaultState(), 3);
        world.setBlockState(new net.minecraft.util.math.BlockPos(i + 2, j + 9, k + 16), (Blocks.GRASS).getDefaultState(), 3);
        world.setBlockState(new net.minecraft.util.math.BlockPos(i + 2, j + 10, k + 3), (Blocks.GRASS).getDefaultState(), 3);
        world.setBlockState(new net.minecraft.util.math.BlockPos(i + 2, j + 10, k + 4), (Blocks.DIRT).getDefaultState(), 3);
        world.setBlockState(new net.minecraft.util.math.BlockPos(i + 2, j + 10, k + 5), (Blocks.DIRT).getDefaultState(), 3);
        world.setBlockState(new net.minecraft.util.math.BlockPos(i + 2, j + 10, k + 6), (Blocks.DIRT).getDefaultState(), 3);
        world.setBlockState(new net.minecraft.util.math.BlockPos(i + 2, j + 10, k + 7), (Blocks.DIRT).getDefaultState(), 3);
        world.setBlockState(new net.minecraft.util.math.BlockPos(i + 2, j + 10, k + 8), (Blocks.COBBLESTONE).getDefaultState(), 3);
        world.setBlockState(new net.minecraft.util.math.BlockPos(i + 2, j + 10, k + 9), (Blocks.AIR).getDefaultState(), 3);
        world.setBlockState(new net.minecraft.util.math.BlockPos(i + 2, j + 10, k + 10), (Blocks.MOSSY_COBBLESTONE).getDefaultState(), 3);
        world.setBlockState(new net.minecraft.util.math.BlockPos(i + 2, j + 10, k + 11), (Blocks.DIRT).getDefaultState(), 3);
        world.setBlockState(new net.minecraft.util.math.BlockPos(i + 2, j + 10, k + 12), (Blocks.DIRT).getDefaultState(), 3);
        world.setBlockState(new net.minecraft.util.math.BlockPos(i + 2, j + 10, k + 13), (Blocks.DIRT).getDefaultState(), 3);
        world.setBlockState(new net.minecraft.util.math.BlockPos(i + 2, j + 10, k + 14), (Blocks.DIRT).getDefaultState(), 3);
        world.setBlockState(new net.minecraft.util.math.BlockPos(i + 2, j + 10, k + 15), (Blocks.GRASS).getDefaultState(), 3);
        world.setBlockState(new net.minecraft.util.math.BlockPos(i + 2, j + 11, k + 4), (Blocks.GRASS).getDefaultState(), 3);
        world.setBlockState(new net.minecraft.util.math.BlockPos(i + 2, j + 11, k + 5), (Blocks.GRASS).getDefaultState(), 3);
        world.setBlockState(new net.minecraft.util.math.BlockPos(i + 2, j + 11, k + 6), (Blocks.DIRT).getDefaultState(), 3);
        world.setBlockState(new net.minecraft.util.math.BlockPos(i + 2, j + 11, k + 7), (Blocks.DIRT).getDefaultState(), 3);
        world.setBlockState(new net.minecraft.util.math.BlockPos(i + 2, j + 11, k + 8), (Blocks.COBBLESTONE).getDefaultState(), 3);
        world.setBlockState(new net.minecraft.util.math.BlockPos(i + 2, j + 11, k + 9), (Blocks.STONEBRICK).getStateFromMeta(3), 3);
        world.setBlockState(new net.minecraft.util.math.BlockPos(i + 2, j + 11, k + 10), (Blocks.MOSSY_COBBLESTONE).getDefaultState(), 3);
        world.setBlockState(new net.minecraft.util.math.BlockPos(i + 2, j + 11, k + 11), (Blocks.DIRT).getDefaultState(), 3);
        world.setBlockState(new net.minecraft.util.math.BlockPos(i + 2, j + 11, k + 12), (Blocks.GRASS).getDefaultState(), 3);
        world.setBlockState(new net.minecraft.util.math.BlockPos(i + 2, j + 11, k + 13), (Blocks.GRASS).getDefaultState(), 3);
        world.setBlockState(new net.minecraft.util.math.BlockPos(i + 2, j + 11, k + 14), (Blocks.GRASS).getDefaultState(), 3);
        world.setBlockState(new net.minecraft.util.math.BlockPos(i + 2, j + 12, k + 6), (Blocks.GRASS).getDefaultState(), 3);
        world.setBlockState(new net.minecraft.util.math.BlockPos(i + 2, j + 12, k + 7), (Blocks.GRASS).getDefaultState(), 3);
        world.setBlockState(new net.minecraft.util.math.BlockPos(i + 2, j + 12, k + 8), (Blocks.GRASS).getDefaultState(), 3);
        world.setBlockState(new net.minecraft.util.math.BlockPos(i + 2, j + 12, k + 9), (Blocks.GRASS).getDefaultState(), 3);
        world.setBlockState(new net.minecraft.util.math.BlockPos(i + 2, j + 12, k + 10), (Blocks.GRASS).getDefaultState(), 3);
        world.setBlockState(new net.minecraft.util.math.BlockPos(i + 2, j + 12, k + 11), (Blocks.GRASS).getDefaultState(), 3);
        world.setBlockState(new net.minecraft.util.math.BlockPos(i + 3, j + 4, k + 3), (Blocks.COBBLESTONE).getDefaultState(), 3);
        world.setBlockState(new net.minecraft.util.math.BlockPos(i + 3, j + 4, k + 4), (Blocks.COBBLESTONE).getDefaultState(), 3);
        world.setBlockState(new net.minecraft.util.math.BlockPos(i + 3, j + 4, k + 5), (Blocks.COBBLESTONE).getDefaultState(), 3);
        world.setBlockState(new net.minecraft.util.math.BlockPos(i + 3, j + 4, k + 6), (Blocks.COBBLESTONE).getDefaultState(), 3);
        world.setBlockState(new net.minecraft.util.math.BlockPos(i + 3, j + 4, k + 7), (Blocks.COBBLESTONE).getDefaultState(), 3);
        world.setBlockState(new net.minecraft.util.math.BlockPos(i + 3, j + 4, k + 8), (Blocks.COBBLESTONE).getDefaultState(), 3);
        world.setBlockState(new net.minecraft.util.math.BlockPos(i + 3, j + 4, k + 9), (Blocks.COBBLESTONE).getDefaultState(), 3);
        world.setBlockState(new net.minecraft.util.math.BlockPos(i + 3, j + 4, k + 10), (Blocks.COBBLESTONE).getDefaultState(), 3);
        world.setBlockState(new net.minecraft.util.math.BlockPos(i + 3, j + 4, k + 11), (Blocks.COBBLESTONE).getDefaultState(), 3);
        world.setBlockState(new net.minecraft.util.math.BlockPos(i + 3, j + 4, k + 12), (Blocks.COBBLESTONE).getDefaultState(), 3);
        world.setBlockState(new net.minecraft.util.math.BlockPos(i + 3, j + 4, k + 13), (Blocks.COBBLESTONE).getDefaultState(), 3);
        world.setBlockState(new net.minecraft.util.math.BlockPos(i + 3, j + 4, k + 14), (Blocks.COBBLESTONE).getDefaultState(), 3);
        world.setBlockState(new net.minecraft.util.math.BlockPos(i + 3, j + 4, k + 15), (Blocks.COBBLESTONE).getDefaultState(), 3);
        world.setBlockState(new net.minecraft.util.math.BlockPos(i + 3, j + 5, k + 3), (Blocks.COBBLESTONE).getDefaultState(), 3);
        world.setBlockState(new net.minecraft.util.math.BlockPos(i + 3, j + 5, k + 4), (Blocks.COBBLESTONE).getDefaultState(), 3);
        world.setBlockState(new net.minecraft.util.math.BlockPos(i + 3, j + 5, k + 5), (Blocks.COBBLESTONE).getDefaultState(), 3);
        world.setBlockState(new net.minecraft.util.math.BlockPos(i + 3, j + 5, k + 6), (Blocks.COBBLESTONE).getDefaultState(), 3);
        world.setBlockState(new net.minecraft.util.math.BlockPos(i + 3, j + 5, k + 7), (Blocks.MOSSY_COBBLESTONE).getDefaultState(), 3);
        world.setBlockState(new net.minecraft.util.math.BlockPos(i + 3, j + 5, k + 8), (Blocks.MOSSY_COBBLESTONE).getDefaultState(), 3);
        world.setBlockState(new net.minecraft.util.math.BlockPos(i + 3, j + 5, k + 9), (Blocks.COBBLESTONE).getDefaultState(), 3);
        world.setBlockState(new net.minecraft.util.math.BlockPos(i + 3, j + 5, k + 10), (Blocks.COBBLESTONE).getDefaultState(), 3);
        world.setBlockState(new net.minecraft.util.math.BlockPos(i + 3, j + 5, k + 11), (Blocks.COBBLESTONE).getDefaultState(), 3);
        world.setBlockState(new net.minecraft.util.math.BlockPos(i + 3, j + 5, k + 12), (Blocks.COBBLESTONE).getDefaultState(), 3);
        world.setBlockState(new net.minecraft.util.math.BlockPos(i + 3, j + 5, k + 13), (Blocks.COBBLESTONE).getDefaultState(), 3);
        world.setBlockState(new net.minecraft.util.math.BlockPos(i + 3, j + 5, k + 14), (Blocks.COBBLESTONE).getDefaultState(), 3);
        world.setBlockState(new net.minecraft.util.math.BlockPos(i + 3, j + 5, k + 15), (Blocks.COBBLESTONE).getDefaultState(), 3);
        world.setBlockState(new net.minecraft.util.math.BlockPos(i + 3, j + 6, k + 3), (Blocks.COBBLESTONE).getDefaultState(), 3);
        world.setBlockState(new net.minecraft.util.math.BlockPos(i + 3, j + 6, k + 4), (Blocks.COBBLESTONE).getDefaultState(), 3);
        world.setBlockState(new net.minecraft.util.math.BlockPos(i + 3, j + 6, k + 5), (Blocks.COBBLESTONE).getDefaultState(), 3);
        world.setBlockState(new net.minecraft.util.math.BlockPos(i + 3, j + 6, k + 6), (Blocks.COBBLESTONE).getDefaultState(), 3);
        world.setBlockState(new net.minecraft.util.math.BlockPos(i + 3, j + 6, k + 7), (Blocks.COBBLESTONE).getDefaultState(), 3);
        world.setBlockState(new net.minecraft.util.math.BlockPos(i + 3, j + 6, k + 8), (Blocks.COBBLESTONE).getDefaultState(), 3);
        world.setBlockState(new net.minecraft.util.math.BlockPos(i + 3, j + 6, k + 9), (Blocks.COBBLESTONE).getDefaultState(), 3);
        world.setBlockState(new net.minecraft.util.math.BlockPos(i + 3, j + 6, k + 10), (Blocks.COBBLESTONE).getDefaultState(), 3);
        world.setBlockState(new net.minecraft.util.math.BlockPos(i + 3, j + 6, k + 11), (Blocks.COBBLESTONE).getDefaultState(), 3);
        world.setBlockState(new net.minecraft.util.math.BlockPos(i + 3, j + 6, k + 12), (Blocks.COBBLESTONE).getDefaultState(), 3);
        world.setBlockState(new net.minecraft.util.math.BlockPos(i + 3, j + 6, k + 13), (Blocks.MOSSY_COBBLESTONE).getDefaultState(), 3);
        world.setBlockState(new net.minecraft.util.math.BlockPos(i + 3, j + 6, k + 14), (Blocks.COBBLESTONE).getDefaultState(), 3);
        world.setBlockState(new net.minecraft.util.math.BlockPos(i + 3, j + 6, k + 15), (Blocks.COBBLESTONE).getDefaultState(), 3);
        world.setBlockState(new net.minecraft.util.math.BlockPos(i + 3, j + 7, k + 3), (Blocks.COBBLESTONE).getDefaultState(), 3);
        world.setBlockState(new net.minecraft.util.math.BlockPos(i + 3, j + 7, k + 4), (Blocks.COBBLESTONE).getDefaultState(), 3);
        world.setBlockState(new net.minecraft.util.math.BlockPos(i + 3, j + 7, k + 5), (Blocks.COBBLESTONE).getDefaultState(), 3);
        world.setBlockState(new net.minecraft.util.math.BlockPos(i + 3, j + 7, k + 6), (Blocks.COBBLESTONE).getDefaultState(), 3);
        world.setBlockState(new net.minecraft.util.math.BlockPos(i + 3, j + 7, k + 7), (Blocks.COBBLESTONE).getDefaultState(), 3);
        world.setBlockState(new net.minecraft.util.math.BlockPos(i + 3, j + 7, k + 8), (Blocks.COBBLESTONE).getDefaultState(), 3);
        world.setBlockState(new net.minecraft.util.math.BlockPos(i + 3, j + 7, k + 9), (Blocks.COBBLESTONE).getDefaultState(), 3);
        world.setBlockState(new net.minecraft.util.math.BlockPos(i + 3, j + 7, k + 10), (Blocks.COBBLESTONE).getDefaultState(), 3);
        world.setBlockState(new net.minecraft.util.math.BlockPos(i + 3, j + 7, k + 11), (Blocks.MOSSY_COBBLESTONE).getDefaultState(), 3);
        world.setBlockState(new net.minecraft.util.math.BlockPos(i + 3, j + 7, k + 12), (Blocks.COBBLESTONE).getDefaultState(), 3);
        world.setBlockState(new net.minecraft.util.math.BlockPos(i + 3, j + 7, k + 13), (Blocks.COBBLESTONE).getDefaultState(), 3);
        world.setBlockState(new net.minecraft.util.math.BlockPos(i + 3, j + 7, k + 14), (Blocks.COBBLESTONE).getDefaultState(), 3);
        world.setBlockState(new net.minecraft.util.math.BlockPos(i + 3, j + 7, k + 15), (Blocks.COBBLESTONE).getDefaultState(), 3);
        world.setBlockState(new net.minecraft.util.math.BlockPos(i + 3, j + 8, k + 1), (Blocks.DIRT).getDefaultState(), 3);
        world.setBlockState(new net.minecraft.util.math.BlockPos(i + 3, j + 8, k + 2), (Blocks.DIRT).getDefaultState(), 3);
        world.setBlockState(new net.minecraft.util.math.BlockPos(i + 3, j + 8, k + 3), (Blocks.COBBLESTONE).getDefaultState(), 3);
        world.setBlockState(new net.minecraft.util.math.BlockPos(i + 3, j + 8, k + 4), (Blocks.COBBLESTONE).getDefaultState(), 3);
        world.setBlockState(new net.minecraft.util.math.BlockPos(i + 3, j + 8, k + 5), (Blocks.COBBLESTONE).getDefaultState(), 3);
        world.setBlockState(new net.minecraft.util.math.BlockPos(i + 3, j + 8, k + 6), (Blocks.COBBLESTONE).getDefaultState(), 3);
        world.setBlockState(new net.minecraft.util.math.BlockPos(i + 3, j + 8, k + 7), (Blocks.MOSSY_COBBLESTONE).getDefaultState(), 3);
        world.setBlockState(new net.minecraft.util.math.BlockPos(i + 3, j + 8, k + 8), (Blocks.COBBLESTONE).getDefaultState(), 3);
        world.setBlockState(new net.minecraft.util.math.BlockPos(i + 3, j + 8, k + 9), (Blocks.COBBLESTONE).getDefaultState(), 3);
        world.setBlockState(new net.minecraft.util.math.BlockPos(i + 3, j + 8, k + 10), (Blocks.COBBLESTONE).getDefaultState(), 3);
        world.setBlockState(new net.minecraft.util.math.BlockPos(i + 3, j + 8, k + 11), (Blocks.COBBLESTONE).getDefaultState(), 3);
        world.setBlockState(new net.minecraft.util.math.BlockPos(i + 3, j + 8, k + 12), (Blocks.COBBLESTONE).getDefaultState(), 3);
        world.setBlockState(new net.minecraft.util.math.BlockPos(i + 3, j + 8, k + 13), (Blocks.COBBLESTONE).getDefaultState(), 3);
        world.setBlockState(new net.minecraft.util.math.BlockPos(i + 3, j + 8, k + 14), (Blocks.COBBLESTONE).getDefaultState(), 3);
        world.setBlockState(new net.minecraft.util.math.BlockPos(i + 3, j + 8, k + 15), (Blocks.COBBLESTONE).getDefaultState(), 3);
        world.setBlockState(new net.minecraft.util.math.BlockPos(i + 3, j + 8, k + 16), (Blocks.DIRT).getDefaultState(), 3);
        world.setBlockState(new net.minecraft.util.math.BlockPos(i + 3, j + 8, k + 17), (Blocks.DIRT).getDefaultState(), 3);
        world.setBlockState(new net.minecraft.util.math.BlockPos(i + 3, j + 9, k + 1), (Blocks.GRASS).getDefaultState(), 3);
        world.setBlockState(new net.minecraft.util.math.BlockPos(i + 3, j + 9, k + 2), (Blocks.DIRT).getDefaultState(), 3);
        world.setBlockState(new net.minecraft.util.math.BlockPos(i + 3, j + 9, k + 3), (Blocks.COBBLESTONE).getDefaultState(), 3);
        world.setBlockState(new net.minecraft.util.math.BlockPos(i + 3, j + 9, k + 4), (Blocks.COBBLESTONE).getDefaultState(), 3);
        world.setBlockState(new net.minecraft.util.math.BlockPos(i + 3, j + 9, k + 5), (Blocks.COBBLESTONE).getDefaultState(), 3);
        world.setBlockState(new net.minecraft.util.math.BlockPos(i + 3, j + 9, k + 6), (Blocks.COBBLESTONE).getDefaultState(), 3);
        world.setBlockState(new net.minecraft.util.math.BlockPos(i + 3, j + 9, k + 7), (Blocks.COBBLESTONE).getDefaultState(), 3);
        world.setBlockState(new net.minecraft.util.math.BlockPos(i + 3, j + 9, k + 8), (Blocks.COBBLESTONE).getDefaultState(), 3);
        world.setBlockState(new net.minecraft.util.math.BlockPos(i + 3, j + 9, k + 9), (Blocks.IRON_BARS).getDefaultState(), 3);
        world.setBlockState(new net.minecraft.util.math.BlockPos(i + 3, j + 9, k + 10), (Blocks.COBBLESTONE).getDefaultState(), 3);
        world.setBlockState(new net.minecraft.util.math.BlockPos(i + 3, j + 9, k + 11), (Blocks.COBBLESTONE).getDefaultState(), 3);
        world.setBlockState(new net.minecraft.util.math.BlockPos(i + 3, j + 9, k + 12), (Blocks.MOSSY_COBBLESTONE).getDefaultState(), 3);
        world.setBlockState(new net.minecraft.util.math.BlockPos(i + 3, j + 9, k + 13), (Blocks.COBBLESTONE).getDefaultState(), 3);
        world.setBlockState(new net.minecraft.util.math.BlockPos(i + 3, j + 9, k + 14), (Blocks.COBBLESTONE).getDefaultState(), 3);
        world.setBlockState(new net.minecraft.util.math.BlockPos(i + 3, j + 9, k + 15), (Blocks.COBBLESTONE).getDefaultState(), 3);
        world.setBlockState(new net.minecraft.util.math.BlockPos(i + 3, j + 9, k + 16), (Blocks.DIRT).getDefaultState(), 3);
        world.setBlockState(new net.minecraft.util.math.BlockPos(i + 3, j + 9, k + 17), (Blocks.GRASS).getDefaultState(), 3);
        world.setBlockState(new net.minecraft.util.math.BlockPos(i + 3, j + 10, k + 2), (Blocks.GRASS).getDefaultState(), 3);
        world.setBlockState(new net.minecraft.util.math.BlockPos(i + 3, j + 10, k + 3), (Blocks.COBBLESTONE).getDefaultState(), 3);
        world.setBlockState(new net.minecraft.util.math.BlockPos(i + 3, j + 10, k + 4), (Blocks.MOSSY_COBBLESTONE).getDefaultState(), 3);
        world.setBlockState(new net.minecraft.util.math.BlockPos(i + 3, j + 10, k + 5), (Blocks.MOSSY_COBBLESTONE).getDefaultState(), 3);
        world.setBlockState(new net.minecraft.util.math.BlockPos(i + 3, j + 10, k + 6), (Blocks.COBBLESTONE).getDefaultState(), 3);
        world.setBlockState(new net.minecraft.util.math.BlockPos(i + 3, j + 10, k + 7), (Blocks.MOSSY_COBBLESTONE).getDefaultState(), 3);
        world.setBlockState(new net.minecraft.util.math.BlockPos(i + 3, j + 10, k + 8), (Blocks.COBBLESTONE).getDefaultState(), 3);
        world.setBlockState(new net.minecraft.util.math.BlockPos(i + 3, j + 10, k + 9), (Blocks.IRON_BARS).getDefaultState(), 3);
        world.setBlockState(new net.minecraft.util.math.BlockPos(i + 3, j + 10, k + 10), (Blocks.COBBLESTONE).getDefaultState(), 3);
        world.setBlockState(new net.minecraft.util.math.BlockPos(i + 3, j + 10, k + 11), (Blocks.COBBLESTONE).getDefaultState(), 3);
        world.setBlockState(new net.minecraft.util.math.BlockPos(i + 3, j + 10, k + 12), (Blocks.COBBLESTONE).getDefaultState(), 3);
        world.setBlockState(new net.minecraft.util.math.BlockPos(i + 3, j + 10, k + 13), (Blocks.COBBLESTONE).getDefaultState(), 3);
        world.setBlockState(new net.minecraft.util.math.BlockPos(i + 3, j + 10, k + 14), (Blocks.COBBLESTONE).getDefaultState(), 3);
        world.setBlockState(new net.minecraft.util.math.BlockPos(i + 3, j + 10, k + 15), (Blocks.COBBLESTONE).getDefaultState(), 3);
        world.setBlockState(new net.minecraft.util.math.BlockPos(i + 3, j + 10, k + 16), (Blocks.GRASS).getDefaultState(), 3);
        world.setBlockState(new net.minecraft.util.math.BlockPos(i + 3, j + 11, k + 3), (Blocks.GRASS).getDefaultState(), 3);
        world.setBlockState(new net.minecraft.util.math.BlockPos(i + 3, j + 11, k + 4), (Blocks.DIRT).getDefaultState(), 3);
        world.setBlockState(new net.minecraft.util.math.BlockPos(i + 3, j + 11, k + 5), (Blocks.COBBLESTONE).getDefaultState(), 3);
        world.setBlockState(new net.minecraft.util.math.BlockPos(i + 3, j + 11, k + 6), (Blocks.COBBLESTONE).getDefaultState(), 3);
        world.setBlockState(new net.minecraft.util.math.BlockPos(i + 3, j + 11, k + 7), (Blocks.COBBLESTONE).getDefaultState(), 3);
        world.setBlockState(new net.minecraft.util.math.BlockPos(i + 3, j + 11, k + 8), (Blocks.COBBLESTONE).getDefaultState(), 3);
        world.setBlockState(new net.minecraft.util.math.BlockPos(i + 3, j + 11, k + 9), (Blocks.MOSSY_COBBLESTONE).getDefaultState(), 3);
        world.setBlockState(new net.minecraft.util.math.BlockPos(i + 3, j + 11, k + 10), (Blocks.COBBLESTONE).getDefaultState(), 3);
        world.setBlockState(new net.minecraft.util.math.BlockPos(i + 3, j + 11, k + 11), (Blocks.COBBLESTONE).getDefaultState(), 3);
        world.setBlockState(new net.minecraft.util.math.BlockPos(i + 3, j + 11, k + 12), (Blocks.COBBLESTONE).getDefaultState(), 3);
        world.setBlockState(new net.minecraft.util.math.BlockPos(i + 3, j + 11, k + 13), (Blocks.COBBLESTONE).getDefaultState(), 3);
        world.setBlockState(new net.minecraft.util.math.BlockPos(i + 3, j + 11, k + 14), (Blocks.DIRT).getDefaultState(), 3);
        world.setBlockState(new net.minecraft.util.math.BlockPos(i + 3, j + 11, k + 15), (Blocks.GRASS).getDefaultState(), 3);
        world.setBlockState(new net.minecraft.util.math.BlockPos(i + 3, j + 12, k + 4), (Blocks.GRASS).getDefaultState(), 3);
        world.setBlockState(new net.minecraft.util.math.BlockPos(i + 3, j + 12, k + 5), (Blocks.GRASS).getDefaultState(), 3);
        world.setBlockState(new net.minecraft.util.math.BlockPos(i + 3, j + 12, k + 6), (Blocks.GRASS).getDefaultState(), 3);
        world.setBlockState(new net.minecraft.util.math.BlockPos(i + 3, j + 12, k + 7), (Blocks.GRASS).getDefaultState(), 3);
        world.setBlockState(new net.minecraft.util.math.BlockPos(i + 3, j + 12, k + 8), (Blocks.GRASS).getDefaultState(), 3);
        world.setBlockState(new net.minecraft.util.math.BlockPos(i + 3, j + 12, k + 9), (Blocks.GRASS).getDefaultState(), 3);
        world.setBlockState(new net.minecraft.util.math.BlockPos(i + 3, j + 12, k + 10), (Blocks.GRASS).getDefaultState(), 3);
        world.setBlockState(new net.minecraft.util.math.BlockPos(i + 3, j + 12, k + 11), (Blocks.GRASS).getDefaultState(), 3);
        world.setBlockState(new net.minecraft.util.math.BlockPos(i + 3, j + 12, k + 12), (Blocks.GRASS).getDefaultState(), 3);
        world.setBlockState(new net.minecraft.util.math.BlockPos(i + 3, j + 12, k + 13), (Blocks.GRASS).getDefaultState(), 3);
        world.setBlockState(new net.minecraft.util.math.BlockPos(i + 3, j + 12, k + 14), (Blocks.GRASS).getDefaultState(), 3);
        world.setBlockState(new net.minecraft.util.math.BlockPos(i + 4, j + 4, k + 3), (Blocks.COBBLESTONE).getDefaultState(), 3);
        world.setBlockState(new net.minecraft.util.math.BlockPos(i + 4, j + 4, k + 4), (Blocks.COBBLESTONE).getDefaultState(), 3);
        world.setBlockState(new net.minecraft.util.math.BlockPos(i + 4, j + 4, k + 5), (Blocks.COBBLESTONE).getDefaultState(), 3);
        world.setBlockState(new net.minecraft.util.math.BlockPos(i + 4, j + 4, k + 6), (Blocks.COBBLESTONE).getDefaultState(), 3);
        world.setBlockState(new net.minecraft.util.math.BlockPos(i + 4, j + 4, k + 7), (Blocks.COBBLESTONE).getDefaultState(), 3);
        world.setBlockState(new net.minecraft.util.math.BlockPos(i + 4, j + 4, k + 8), (Blocks.COBBLESTONE).getDefaultState(), 3);
        world.setBlockState(new net.minecraft.util.math.BlockPos(i + 4, j + 4, k + 9), (Blocks.COBBLESTONE).getDefaultState(), 3);
        world.setBlockState(new net.minecraft.util.math.BlockPos(i + 4, j + 4, k + 10), (Blocks.COBBLESTONE).getDefaultState(), 3);
        world.setBlockState(new net.minecraft.util.math.BlockPos(i + 4, j + 4, k + 11), (Blocks.COBBLESTONE).getDefaultState(), 3);
        world.setBlockState(new net.minecraft.util.math.BlockPos(i + 4, j + 4, k + 12), (Blocks.COBBLESTONE).getDefaultState(), 3);
        world.setBlockState(new net.minecraft.util.math.BlockPos(i + 4, j + 4, k + 13), (Blocks.COBBLESTONE).getDefaultState(), 3);
        world.setBlockState(new net.minecraft.util.math.BlockPos(i + 4, j + 4, k + 14), (Blocks.COBBLESTONE).getDefaultState(), 3);
        world.setBlockState(new net.minecraft.util.math.BlockPos(i + 4, j + 4, k + 15), (Blocks.COBBLESTONE).getDefaultState(), 3);
        world.setBlockState(new net.minecraft.util.math.BlockPos(i + 4, j + 5, k + 3), (Blocks.COBBLESTONE).getDefaultState(), 3);
        world.setBlockState(new net.minecraft.util.math.BlockPos(i + 4, j + 5, k + 15), (Blocks.COBBLESTONE).getDefaultState(), 3);
        world.setBlockState(new net.minecraft.util.math.BlockPos(i + 4, j + 6, k + 3), (Blocks.COBBLESTONE).getDefaultState(), 3);
        world.setBlockState(new net.minecraft.util.math.BlockPos(i + 4, j + 6, k + 15), (Blocks.COBBLESTONE).getDefaultState(), 3);
        world.setBlockState(new net.minecraft.util.math.BlockPos(i + 4, j + 7, k + 3), (Blocks.MOSSY_COBBLESTONE).getDefaultState(), 3);
        world.setBlockState(new net.minecraft.util.math.BlockPos(i + 4, j + 7, k + 15), (Blocks.COBBLESTONE).getDefaultState(), 3);
        world.setBlockState(new net.minecraft.util.math.BlockPos(i + 4, j + 8, k), (Blocks.DIRT).getDefaultState(), 3);
        world.setBlockState(new net.minecraft.util.math.BlockPos(i + 4, j + 8, k + 1), (Blocks.DIRT).getDefaultState(), 3);
        world.setBlockState(new net.minecraft.util.math.BlockPos(i + 4, j + 8, k + 2), (Blocks.DIRT).getDefaultState(), 3);
        world.setBlockState(new net.minecraft.util.math.BlockPos(i + 4, j + 8, k + 3), (Blocks.COBBLESTONE).getDefaultState(), 3);
        world.setBlockState(new net.minecraft.util.math.BlockPos(i + 4, j + 8, k + 4), (Blocks.MOSSY_COBBLESTONE).getDefaultState(), 3);
        world.setBlockState(new net.minecraft.util.math.BlockPos(i + 4, j + 8, k + 5), (Blocks.MOSSY_COBBLESTONE).getDefaultState(), 3);
        world.setBlockState(new net.minecraft.util.math.BlockPos(i + 4, j + 8, k + 6), (Blocks.COBBLESTONE).getDefaultState(), 3);
        world.setBlockState(new net.minecraft.util.math.BlockPos(i + 4, j + 8, k + 7), (Blocks.COBBLESTONE).getDefaultState(), 3);
        world.setBlockState(new net.minecraft.util.math.BlockPos(i + 4, j + 8, k + 8), (Blocks.COBBLESTONE).getDefaultState(), 3);
        world.setBlockState(new net.minecraft.util.math.BlockPos(i + 4, j + 8, k + 9), (Blocks.MOSSY_COBBLESTONE).getDefaultState(), 3);
        world.setBlockState(new net.minecraft.util.math.BlockPos(i + 4, j + 8, k + 10), (Blocks.MOSSY_COBBLESTONE).getDefaultState(), 3);
        world.setBlockState(new net.minecraft.util.math.BlockPos(i + 4, j + 8, k + 11), (Blocks.COBBLESTONE).getDefaultState(), 3);
        world.setBlockState(new net.minecraft.util.math.BlockPos(i + 4, j + 8, k + 12), (Blocks.COBBLESTONE).getDefaultState(), 3);
        world.setBlockState(new net.minecraft.util.math.BlockPos(i + 4, j + 8, k + 13), (Blocks.COBBLESTONE).getDefaultState(), 3);
        world.setBlockState(new net.minecraft.util.math.BlockPos(i + 4, j + 8, k + 14), (Blocks.COBBLESTONE).getDefaultState(), 3);
        world.setBlockState(new net.minecraft.util.math.BlockPos(i + 4, j + 8, k + 15), (Blocks.COBBLESTONE).getDefaultState(), 3);
        world.setBlockState(new net.minecraft.util.math.BlockPos(i + 4, j + 8, k + 16), (Blocks.DIRT).getDefaultState(), 3);
        world.setBlockState(new net.minecraft.util.math.BlockPos(i + 4, j + 8, k + 17), (Blocks.DIRT).getDefaultState(), 3);
        world.setBlockState(new net.minecraft.util.math.BlockPos(i + 4, j + 8, k + 18), (Blocks.DIRT).getDefaultState(), 3);
        world.setBlockState(new net.minecraft.util.math.BlockPos(i + 4, j + 9, k), (Blocks.GRASS).getDefaultState(), 3);
        world.setBlockState(new net.minecraft.util.math.BlockPos(i + 4, j + 9, k + 1), (Blocks.DIRT).getDefaultState(), 3);
        world.setBlockState(new net.minecraft.util.math.BlockPos(i + 4, j + 9, k + 2), (Blocks.DIRT).getDefaultState(), 3);
        world.setBlockState(new net.minecraft.util.math.BlockPos(i + 4, j + 9, k + 3), (Blocks.COBBLESTONE).getDefaultState(), 3);
        world.setBlockState(new net.minecraft.util.math.BlockPos(i + 4, j + 9, k + 15), (Blocks.COBBLESTONE).getDefaultState(), 3);
        world.setBlockState(new net.minecraft.util.math.BlockPos(i + 4, j + 9, k + 16), (Blocks.DIRT).getDefaultState(), 3);
        world.setBlockState(new net.minecraft.util.math.BlockPos(i + 4, j + 9, k + 17), (Blocks.DIRT).getDefaultState(), 3);
        world.setBlockState(new net.minecraft.util.math.BlockPos(i + 4, j + 9, k + 18), (Blocks.GRASS).getDefaultState(), 3);
        world.setBlockState(new net.minecraft.util.math.BlockPos(i + 4, j + 10, k + 1), (Blocks.GRASS).getDefaultState(), 3);
        world.setBlockState(new net.minecraft.util.math.BlockPos(i + 4, j + 10, k + 2), (Blocks.DIRT).getDefaultState(), 3);
        world.setBlockState(new net.minecraft.util.math.BlockPos(i + 4, j + 10, k + 3), (Blocks.COBBLESTONE).getDefaultState(), 3);
        world.setBlockState(new net.minecraft.util.math.BlockPos(i + 4, j + 10, k + 15), (Blocks.MOSSY_COBBLESTONE).getDefaultState(), 3);
        world.setBlockState(new net.minecraft.util.math.BlockPos(i + 4, j + 10, k + 16), (Blocks.DIRT).getDefaultState(), 3);
        world.setBlockState(new net.minecraft.util.math.BlockPos(i + 4, j + 10, k + 17), (Blocks.GRASS).getDefaultState(), 3);
        world.setBlockState(new net.minecraft.util.math.BlockPos(i + 4, j + 11, k + 2), (Blocks.GRASS).getDefaultState(), 3);
        world.setBlockState(new net.minecraft.util.math.BlockPos(i + 4, j + 11, k + 3), (Blocks.DIRT).getDefaultState(), 3);
        world.setBlockState(new net.minecraft.util.math.BlockPos(i + 4, j + 11, k + 4), (Blocks.COBBLESTONE).getDefaultState(), 3);
        world.setBlockState(new net.minecraft.util.math.BlockPos(i + 4, j + 11, k + 14), (Blocks.MOSSY_COBBLESTONE).getDefaultState(), 3);
        world.setBlockState(new net.minecraft.util.math.BlockPos(i + 4, j + 11, k + 15), (Blocks.DIRT).getDefaultState(), 3);
        world.setBlockState(new net.minecraft.util.math.BlockPos(i + 4, j + 11, k + 16), (Blocks.GRASS).getDefaultState(), 3);
        world.setBlockState(new net.minecraft.util.math.BlockPos(i + 4, j + 12, k + 3), (Blocks.GRASS).getDefaultState(), 3);
        world.setBlockState(new net.minecraft.util.math.BlockPos(i + 4, j + 12, k + 4), (Blocks.GRASS).getDefaultState(), 3);
        world.setBlockState(new net.minecraft.util.math.BlockPos(i + 4, j + 12, k + 5), (Blocks.COBBLESTONE).getDefaultState(), 3);
        world.setBlockState(new net.minecraft.util.math.BlockPos(i + 4, j + 12, k + 6), (Blocks.COBBLESTONE).getDefaultState(), 3);
        world.setBlockState(new net.minecraft.util.math.BlockPos(i + 4, j + 12, k + 7), (Blocks.COBBLESTONE).getDefaultState(), 3);
        world.setBlockState(new net.minecraft.util.math.BlockPos(i + 4, j + 12, k + 8), (Blocks.COBBLESTONE).getDefaultState(), 3);
        world.setBlockState(new net.minecraft.util.math.BlockPos(i + 4, j + 12, k + 9), (Blocks.COBBLESTONE).getDefaultState(), 3);
        world.setBlockState(new net.minecraft.util.math.BlockPos(i + 4, j + 12, k + 10), (Blocks.COBBLESTONE).getDefaultState(), 3);
        world.setBlockState(new net.minecraft.util.math.BlockPos(i + 4, j + 12, k + 11), (Blocks.COBBLESTONE).getDefaultState(), 3);
        world.setBlockState(new net.minecraft.util.math.BlockPos(i + 4, j + 12, k + 12), (Blocks.COBBLESTONE).getDefaultState(), 3);
        world.setBlockState(new net.minecraft.util.math.BlockPos(i + 4, j + 12, k + 13), (Blocks.COBBLESTONE).getDefaultState(), 3);
        world.setBlockState(new net.minecraft.util.math.BlockPos(i + 4, j + 12, k + 14), (Blocks.DIRT).getDefaultState(), 3);
        world.setBlockState(new net.minecraft.util.math.BlockPos(i + 4, j + 12, k + 15), (Blocks.GRASS).getDefaultState(), 3);
        world.setBlockState(new net.minecraft.util.math.BlockPos(i + 4, j + 13, k + 5), (Blocks.GRASS).getDefaultState(), 3);
        world.setBlockState(new net.minecraft.util.math.BlockPos(i + 4, j + 13, k + 6), (Blocks.GRASS).getDefaultState(), 3);
        world.setBlockState(new net.minecraft.util.math.BlockPos(i + 4, j + 13, k + 7), (Blocks.GRASS).getDefaultState(), 3);
        world.setBlockState(new net.minecraft.util.math.BlockPos(i + 4, j + 13, k + 8), (Blocks.GRASS).getDefaultState(), 3);
        world.setBlockState(new net.minecraft.util.math.BlockPos(i + 4, j + 13, k + 9), (Blocks.GRASS).getDefaultState(), 3);
        world.setBlockState(new net.minecraft.util.math.BlockPos(i + 4, j + 13, k + 10), (Blocks.GRASS).getDefaultState(), 3);
        world.setBlockState(new net.minecraft.util.math.BlockPos(i + 4, j + 13, k + 11), (Blocks.GRASS).getDefaultState(), 3);
        world.setBlockState(new net.minecraft.util.math.BlockPos(i + 4, j + 13, k + 12), (Blocks.GRASS).getDefaultState(), 3);
        world.setBlockState(new net.minecraft.util.math.BlockPos(i + 4, j + 13, k + 13), (Blocks.GRASS).getDefaultState(), 3);
        world.setBlockState(new net.minecraft.util.math.BlockPos(i + 4, j + 13, k + 14), (Blocks.GRASS).getDefaultState(), 3);
        world.setBlockState(new net.minecraft.util.math.BlockPos(i + 5, j + 4, k + 3), (Blocks.COBBLESTONE).getDefaultState(), 3);
        world.setBlockState(new net.minecraft.util.math.BlockPos(i + 5, j + 4, k + 4), (Blocks.COBBLESTONE).getDefaultState(), 3);
        world.setBlockState(new net.minecraft.util.math.BlockPos(i + 5, j + 4, k + 5), (Blocks.COBBLESTONE).getDefaultState(), 3);
        world.setBlockState(new net.minecraft.util.math.BlockPos(i + 5, j + 4, k + 6), (Blocks.COBBLESTONE).getDefaultState(), 3);
        world.setBlockState(new net.minecraft.util.math.BlockPos(i + 5, j + 4, k + 7), (Blocks.COBBLESTONE).getDefaultState(), 3);
        world.setBlockState(new net.minecraft.util.math.BlockPos(i + 5, j + 4, k + 8), (Blocks.COBBLESTONE).getDefaultState(), 3);
        world.setBlockState(new net.minecraft.util.math.BlockPos(i + 5, j + 4, k + 9), (Blocks.COBBLESTONE).getDefaultState(), 3);
        world.setBlockState(new net.minecraft.util.math.BlockPos(i + 5, j + 4, k + 10), (Blocks.MOSSY_COBBLESTONE).getDefaultState(), 3);
        world.setBlockState(new net.minecraft.util.math.BlockPos(i + 5, j + 4, k + 11), (Blocks.COBBLESTONE).getDefaultState(), 3);
        world.setBlockState(new net.minecraft.util.math.BlockPos(i + 5, j + 4, k + 12), (Blocks.COBBLESTONE).getDefaultState(), 3);
        world.setBlockState(new net.minecraft.util.math.BlockPos(i + 5, j + 4, k + 13), (Blocks.MOSSY_COBBLESTONE).getDefaultState(), 3);
        world.setBlockState(new net.minecraft.util.math.BlockPos(i + 5, j + 4, k + 14), (Blocks.COBBLESTONE).getDefaultState(), 3);
        world.setBlockState(new net.minecraft.util.math.BlockPos(i + 5, j + 4, k + 15), (Blocks.COBBLESTONE).getDefaultState(), 3);
        world.setBlockState(new net.minecraft.util.math.BlockPos(i + 5, j + 5, k + 3), (Blocks.COBBLESTONE).getDefaultState(), 3);
        world.setBlockState(new net.minecraft.util.math.BlockPos(i + 5, j + 5, k + 15), (Blocks.COBBLESTONE).getDefaultState(), 3);
        world.setBlockState(new net.minecraft.util.math.BlockPos(i + 5, j + 6, k + 3), (Blocks.MOSSY_COBBLESTONE).getDefaultState(), 3);
        world.setBlockState(new net.minecraft.util.math.BlockPos(i + 5, j + 6, k + 15), (Blocks.COBBLESTONE).getDefaultState(), 3);
        world.setBlockState(new net.minecraft.util.math.BlockPos(i + 5, j + 7, k + 3), (Blocks.COBBLESTONE).getDefaultState(), 3);
        world.setBlockState(new net.minecraft.util.math.BlockPos(i + 5, j + 7, k + 15), (Blocks.COBBLESTONE).getDefaultState(), 3);
        world.setBlockState(new net.minecraft.util.math.BlockPos(i + 5, j + 8, k), (Blocks.DIRT).getDefaultState(), 3);
        world.setBlockState(new net.minecraft.util.math.BlockPos(i + 5, j + 8, k + 1), (Blocks.DIRT).getDefaultState(), 3);
        world.setBlockState(new net.minecraft.util.math.BlockPos(i + 5, j + 8, k + 2), (Blocks.DIRT).getDefaultState(), 3);
        world.setBlockState(new net.minecraft.util.math.BlockPos(i + 5, j + 8, k + 3), (Blocks.COBBLESTONE).getDefaultState(), 3);
        world.setBlockState(new net.minecraft.util.math.BlockPos(i + 5, j + 8, k + 4), (Blocks.MOSSY_COBBLESTONE).getDefaultState(), 3);
        world.setBlockState(new net.minecraft.util.math.BlockPos(i + 5, j + 8, k + 5), (Blocks.COBBLESTONE).getDefaultState(), 3);
        world.setBlockState(new net.minecraft.util.math.BlockPos(i + 5, j + 8, k + 6), (Blocks.COBBLESTONE).getDefaultState(), 3);
        world.setBlockState(new net.minecraft.util.math.BlockPos(i + 5, j + 8, k + 7), (Blocks.COBBLESTONE).getDefaultState(), 3);
        world.setBlockState(new net.minecraft.util.math.BlockPos(i + 5, j + 8, k + 8), (Blocks.COBBLESTONE).getDefaultState(), 3);
        world.setBlockState(new net.minecraft.util.math.BlockPos(i + 5, j + 8, k + 9), (Blocks.COBBLESTONE).getDefaultState(), 3);
        world.setBlockState(new net.minecraft.util.math.BlockPos(i + 5, j + 8, k + 10), (Blocks.COBBLESTONE).getDefaultState(), 3);
        world.setBlockState(new net.minecraft.util.math.BlockPos(i + 5, j + 8, k + 11), (Blocks.COBBLESTONE).getDefaultState(), 3);
        world.setBlockState(new net.minecraft.util.math.BlockPos(i + 5, j + 8, k + 12), (Blocks.COBBLESTONE).getDefaultState(), 3);
        world.setBlockState(new net.minecraft.util.math.BlockPos(i + 5, j + 8, k + 13), (Blocks.MOSSY_COBBLESTONE).getDefaultState(), 3);
        world.setBlockState(new net.minecraft.util.math.BlockPos(i + 5, j + 8, k + 14), (Blocks.COBBLESTONE).getDefaultState(), 3);
        world.setBlockState(new net.minecraft.util.math.BlockPos(i + 5, j + 8, k + 15), (Blocks.COBBLESTONE).getDefaultState(), 3);
        world.setBlockState(new net.minecraft.util.math.BlockPos(i + 5, j + 8, k + 16), (Blocks.DIRT).getDefaultState(), 3);
        world.setBlockState(new net.minecraft.util.math.BlockPos(i + 5, j + 8, k + 17), (Blocks.DIRT).getDefaultState(), 3);
        world.setBlockState(new net.minecraft.util.math.BlockPos(i + 5, j + 8, k + 18), (Blocks.DIRT).getDefaultState(), 3);
        world.setBlockState(new net.minecraft.util.math.BlockPos(i + 5, j + 9, k), (Blocks.GRASS).getDefaultState(), 3);
        world.setBlockState(new net.minecraft.util.math.BlockPos(i + 5, j + 9, k + 1), (Blocks.DIRT).getDefaultState(), 3);
        world.setBlockState(new net.minecraft.util.math.BlockPos(i + 5, j + 9, k + 2), (Blocks.DIRT).getDefaultState(), 3);
        world.setBlockState(new net.minecraft.util.math.BlockPos(i + 5, j + 9, k + 3), (Blocks.COBBLESTONE).getDefaultState(), 3);
        world.setBlockState(new net.minecraft.util.math.BlockPos(i + 5, j + 9, k + 15), (Blocks.COBBLESTONE).getDefaultState(), 3);
        world.setBlockState(new net.minecraft.util.math.BlockPos(i + 5, j + 9, k + 16), (Blocks.DIRT).getDefaultState(), 3);
        world.setBlockState(new net.minecraft.util.math.BlockPos(i + 5, j + 9, k + 17), (Blocks.DIRT).getDefaultState(), 3);
        world.setBlockState(new net.minecraft.util.math.BlockPos(i + 5, j + 9, k + 18), (Blocks.GRASS).getDefaultState(), 3);
        world.setBlockState(new net.minecraft.util.math.BlockPos(i + 5, j + 10, k + 1), (Blocks.GRASS).getDefaultState(), 3);
        world.setBlockState(new net.minecraft.util.math.BlockPos(i + 5, j + 10, k + 2), (Blocks.DIRT).getDefaultState(), 3);
        world.setBlockState(new net.minecraft.util.math.BlockPos(i + 5, j + 10, k + 3), (Blocks.COBBLESTONE).getDefaultState(), 3);
        world.setBlockState(new net.minecraft.util.math.BlockPos(i + 5, j + 10, k + 15), (Blocks.COBBLESTONE).getDefaultState(), 3);
        world.setBlockState(new net.minecraft.util.math.BlockPos(i + 5, j + 10, k + 16), (Blocks.DIRT).getDefaultState(), 3);
        world.setBlockState(new net.minecraft.util.math.BlockPos(i + 5, j + 10, k + 17), (Blocks.GRASS).getDefaultState(), 3);
        world.setBlockState(new net.minecraft.util.math.BlockPos(i + 5, j + 11, k + 2), (Blocks.DIRT).getDefaultState(), 3);
        world.setBlockState(new net.minecraft.util.math.BlockPos(i + 5, j + 11, k + 3), (Blocks.COBBLESTONE).getDefaultState(), 3);
        world.setBlockState(new net.minecraft.util.math.BlockPos(i + 5, j + 11, k + 6), (Blocks.STONE_STAIRS).getStateFromMeta(4), 3);
        world.setBlockState(new net.minecraft.util.math.BlockPos(i + 5, j + 11, k + 12), (Blocks.STONE_STAIRS).getStateFromMeta(4), 3);
        world.setBlockState(new net.minecraft.util.math.BlockPos(i + 5, j + 11, k + 15), (Blocks.COBBLESTONE).getDefaultState(), 3);
        world.setBlockState(new net.minecraft.util.math.BlockPos(i + 5, j + 11, k + 16), (Blocks.GRASS).getDefaultState(), 3);
        world.setBlockState(new net.minecraft.util.math.BlockPos(i + 5, j + 12, k + 2), (Blocks.GRASS).getDefaultState(), 3);
        world.setBlockState(new net.minecraft.util.math.BlockPos(i + 5, j + 12, k + 3), (Blocks.GRASS).getDefaultState(), 3);
        world.setBlockState(new net.minecraft.util.math.BlockPos(i + 5, j + 12, k + 4), (Blocks.COBBLESTONE).getDefaultState(), 3);
        world.setBlockState(new net.minecraft.util.math.BlockPos(i + 5, j + 12, k + 5), (Blocks.COBBLESTONE).getDefaultState(), 3);
        world.setBlockState(new net.minecraft.util.math.BlockPos(i + 5, j + 12, k + 6), (Blocks.COBBLESTONE).getDefaultState(), 3);
        world.setBlockState(new net.minecraft.util.math.BlockPos(i + 5, j + 12, k + 7), (Blocks.COBBLESTONE).getDefaultState(), 3);
        world.setBlockState(new net.minecraft.util.math.BlockPos(i + 5, j + 12, k + 8), (Blocks.COBBLESTONE).getDefaultState(), 3);
        world.setBlockState(new net.minecraft.util.math.BlockPos(i + 5, j + 12, k + 9), (Blocks.COBBLESTONE).getDefaultState(), 3);
        world.setBlockState(new net.minecraft.util.math.BlockPos(i + 5, j + 12, k + 10), (Blocks.COBBLESTONE).getDefaultState(), 3);
        world.setBlockState(new net.minecraft.util.math.BlockPos(i + 5, j + 12, k + 11), (Blocks.COBBLESTONE).getDefaultState(), 3);
        world.setBlockState(new net.minecraft.util.math.BlockPos(i + 5, j + 12, k + 12), (Blocks.MOSSY_COBBLESTONE).getDefaultState(), 3);
        world.setBlockState(new net.minecraft.util.math.BlockPos(i + 5, j + 12, k + 13), (Blocks.COBBLESTONE).getDefaultState(), 3);
        world.setBlockState(new net.minecraft.util.math.BlockPos(i + 5, j + 12, k + 14), (Blocks.COBBLESTONE).getDefaultState(), 3);
        world.setBlockState(new net.minecraft.util.math.BlockPos(i + 5, j + 12, k + 15), (Blocks.DIRT).getDefaultState(), 3);
        world.setBlockState(new net.minecraft.util.math.BlockPos(i + 5, j + 13, k + 4), (Blocks.GRASS).getDefaultState(), 3);
        world.setBlockState(new net.minecraft.util.math.BlockPos(i + 5, j + 13, k + 5), (Blocks.GRASS).getDefaultState(), 3);
        world.setBlockState(new net.minecraft.util.math.BlockPos(i + 5, j + 13, k + 6), (Blocks.GRASS).getDefaultState(), 3);
        world.setBlockState(new net.minecraft.util.math.BlockPos(i + 5, j + 13, k + 7), (Blocks.GRASS).getDefaultState(), 3);
        world.setBlockState(new net.minecraft.util.math.BlockPos(i + 5, j + 13, k + 8), (Blocks.GRASS).getDefaultState(), 3);
        world.setBlockState(new net.minecraft.util.math.BlockPos(i + 5, j + 13, k + 9), (Blocks.GRASS).getDefaultState(), 3);
        world.setBlockState(new net.minecraft.util.math.BlockPos(i + 5, j + 13, k + 10), (Blocks.GRASS).getDefaultState(), 3);
        world.setBlockState(new net.minecraft.util.math.BlockPos(i + 5, j + 13, k + 11), (Blocks.GRASS).getDefaultState(), 3);
        world.setBlockState(new net.minecraft.util.math.BlockPos(i + 5, j + 13, k + 12), (Blocks.GRASS).getDefaultState(), 3);
        world.setBlockState(new net.minecraft.util.math.BlockPos(i + 5, j + 13, k + 13), (Blocks.GRASS).getDefaultState(), 3);
        world.setBlockState(new net.minecraft.util.math.BlockPos(i + 5, j + 13, k + 14), (Blocks.GRASS).getDefaultState(), 3);
        world.setBlockState(new net.minecraft.util.math.BlockPos(i + 5, j + 13, k + 15), (Blocks.GRASS).getDefaultState(), 3);
        world.setBlockState(new net.minecraft.util.math.BlockPos(i + 6, j, k + 6), (Blocks.COBBLESTONE).getDefaultState(), 3);
        world.setBlockState(new net.minecraft.util.math.BlockPos(i + 6, j, k + 7), (Blocks.COBBLESTONE).getDefaultState(), 3);
        world.setBlockState(new net.minecraft.util.math.BlockPos(i + 6, j, k + 8), (Blocks.COBBLESTONE).getDefaultState(), 3);
        world.setBlockState(new net.minecraft.util.math.BlockPos(i + 6, j, k + 9), (Blocks.COBBLESTONE).getDefaultState(), 3);
        world.setBlockState(new net.minecraft.util.math.BlockPos(i + 6, j, k + 10), (Blocks.COBBLESTONE).getDefaultState(), 3);
        world.setBlockState(new net.minecraft.util.math.BlockPos(i + 6, j, k + 11), (Blocks.COBBLESTONE).getDefaultState(), 3);
        world.setBlockState(new net.minecraft.util.math.BlockPos(i + 6, j, k + 12), (Blocks.COBBLESTONE).getDefaultState(), 3);
        world.setBlockState(new net.minecraft.util.math.BlockPos(i + 6, j + 1, k + 6), (Blocks.MOSSY_COBBLESTONE).getDefaultState(), 3);
        world.setBlockState(new net.minecraft.util.math.BlockPos(i + 6, j + 1, k + 7), (Blocks.COBBLESTONE).getDefaultState(), 3);
        world.setBlockState(new net.minecraft.util.math.BlockPos(i + 6, j + 1, k + 8), (Blocks.COBBLESTONE).getDefaultState(), 3);
        world.setBlockState(new net.minecraft.util.math.BlockPos(i + 6, j + 1, k + 9), (Blocks.MOSSY_COBBLESTONE).getDefaultState(), 3);
        world.setBlockState(new net.minecraft.util.math.BlockPos(i + 6, j + 1, k + 10), (Blocks.MOSSY_COBBLESTONE).getDefaultState(), 3);
        world.setBlockState(new net.minecraft.util.math.BlockPos(i + 6, j + 1, k + 11), (Blocks.COBBLESTONE).getDefaultState(), 3);
        world.setBlockState(new net.minecraft.util.math.BlockPos(i + 6, j + 1, k + 12), (Blocks.COBBLESTONE).getDefaultState(), 3);
        world.setBlockState(new net.minecraft.util.math.BlockPos(i + 6, j + 2, k + 6), (Blocks.COBBLESTONE).getDefaultState(), 3);
        world.setBlockState(new net.minecraft.util.math.BlockPos(i + 6, j + 2, k + 7), (Blocks.COBBLESTONE).getDefaultState(), 3);
        world.setBlockState(new net.minecraft.util.math.BlockPos(i + 6, j + 2, k + 8), (Blocks.COBBLESTONE).getDefaultState(), 3);
        world.setBlockState(new net.minecraft.util.math.BlockPos(i + 6, j + 2, k + 9), (Blocks.COBBLESTONE).getDefaultState(), 3);
        world.setBlockState(new net.minecraft.util.math.BlockPos(i + 6, j + 2, k + 10), (Blocks.COBBLESTONE).getDefaultState(), 3);
        world.setBlockState(new net.minecraft.util.math.BlockPos(i + 6, j + 2, k + 11), (Blocks.COBBLESTONE).getDefaultState(), 3);
        world.setBlockState(new net.minecraft.util.math.BlockPos(i + 6, j + 2, k + 12), (Blocks.COBBLESTONE).getDefaultState(), 3);
        world.setBlockState(new net.minecraft.util.math.BlockPos(i + 6, j + 3, k + 6), (Blocks.COBBLESTONE).getDefaultState(), 3);
        world.setBlockState(new net.minecraft.util.math.BlockPos(i + 6, j + 3, k + 7), (Blocks.COBBLESTONE).getDefaultState(), 3);
        world.setBlockState(new net.minecraft.util.math.BlockPos(i + 6, j + 3, k + 8), (Blocks.MOSSY_COBBLESTONE).getDefaultState(), 3);
        world.setBlockState(new net.minecraft.util.math.BlockPos(i + 6, j + 3, k + 9), (Blocks.COBBLESTONE).getDefaultState(), 3);
        world.setBlockState(new net.minecraft.util.math.BlockPos(i + 6, j + 3, k + 10), (Blocks.COBBLESTONE).getDefaultState(), 3);
        world.setBlockState(new net.minecraft.util.math.BlockPos(i + 6, j + 3, k + 11), (Blocks.COBBLESTONE).getDefaultState(), 3);
        world.setBlockState(new net.minecraft.util.math.BlockPos(i + 6, j + 3, k + 12), (Blocks.COBBLESTONE).getDefaultState(), 3);
        world.setBlockState(new net.minecraft.util.math.BlockPos(i + 6, j + 4, k + 3), (Blocks.COBBLESTONE).getDefaultState(), 3);
        world.setBlockState(new net.minecraft.util.math.BlockPos(i + 6, j + 4, k + 4), (Blocks.COBBLESTONE).getDefaultState(), 3);
        world.setBlockState(new net.minecraft.util.math.BlockPos(i + 6, j + 4, k + 5), (Blocks.COBBLESTONE).getDefaultState(), 3);
        world.setBlockState(new net.minecraft.util.math.BlockPos(i + 6, j + 4, k + 6), (Blocks.COBBLESTONE).getDefaultState(), 3);
        world.setBlockState(new net.minecraft.util.math.BlockPos(i + 6, j + 4, k + 7), (Blocks.STONE_STAIRS).getStateFromMeta(1), 3);
        world.setBlockState(new net.minecraft.util.math.BlockPos(i + 6, j + 4, k + 8), (Blocks.STONE_STAIRS).getStateFromMeta(1), 3);
        world.setBlockState(new net.minecraft.util.math.BlockPos(i + 6, j + 4, k + 9), (Blocks.COBBLESTONE).getDefaultState(), 3);
        world.setBlockState(new net.minecraft.util.math.BlockPos(i + 6, j + 4, k + 10), (Blocks.STONE_STAIRS).getStateFromMeta(1), 3);
        world.setBlockState(new net.minecraft.util.math.BlockPos(i + 6, j + 4, k + 11), (Blocks.STONE_STAIRS).getStateFromMeta(1), 3);
        world.setBlockState(new net.minecraft.util.math.BlockPos(i + 6, j + 4, k + 12), (Blocks.COBBLESTONE).getDefaultState(), 3);
        world.setBlockState(new net.minecraft.util.math.BlockPos(i + 6, j + 4, k + 13), (Blocks.COBBLESTONE).getDefaultState(), 3);
        world.setBlockState(new net.minecraft.util.math.BlockPos(i + 6, j + 4, k + 14), (Blocks.COBBLESTONE).getDefaultState(), 3);
        world.setBlockState(new net.minecraft.util.math.BlockPos(i + 6, j + 4, k + 15), (Blocks.COBBLESTONE).getDefaultState(), 3);
        world.setBlockState(new net.minecraft.util.math.BlockPos(i + 6, j + 5, k + 3), (Blocks.COBBLESTONE).getDefaultState(), 3);
        world.setBlockState(new net.minecraft.util.math.BlockPos(i + 6, j + 5, k + 6), (Blocks.MOSSY_COBBLESTONE).getDefaultState(), 3);
        world.setBlockState(new net.minecraft.util.math.BlockPos(i + 6, j + 5, k + 12), (Blocks.COBBLESTONE).getDefaultState(), 3);
        world.setBlockState(new net.minecraft.util.math.BlockPos(i + 6, j + 5, k + 15), (Blocks.MOSSY_COBBLESTONE).getDefaultState(), 3);
        world.setBlockState(new net.minecraft.util.math.BlockPos(i + 6, j + 6, k + 3), (Blocks.COBBLESTONE).getDefaultState(), 3);
        world.setBlockState(new net.minecraft.util.math.BlockPos(i + 6, j + 6, k + 6), (Blocks.MOSSY_COBBLESTONE).getDefaultState(), 3);
        world.setBlockState(new net.minecraft.util.math.BlockPos(i + 6, j + 6, k + 12), (Blocks.COBBLESTONE).getDefaultState(), 3);
        world.setBlockState(new net.minecraft.util.math.BlockPos(i + 6, j + 6, k + 15), (Blocks.COBBLESTONE).getDefaultState(), 3);
        world.setBlockState(new net.minecraft.util.math.BlockPos(i + 6, j + 7, k + 3), (Blocks.COBBLESTONE).getDefaultState(), 3);
        world.setBlockState(new net.minecraft.util.math.BlockPos(i + 6, j + 7, k + 6), (Blocks.COBBLESTONE).getDefaultState(), 3);
        world.setBlockState(new net.minecraft.util.math.BlockPos(i + 6, j + 7, k + 12), (Blocks.COBBLESTONE).getDefaultState(), 3);
        world.setBlockState(new net.minecraft.util.math.BlockPos(i + 6, j + 7, k + 15), (Blocks.COBBLESTONE).getDefaultState(), 3);
        world.setBlockState(new net.minecraft.util.math.BlockPos(i + 6, j + 8, k), (Blocks.DIRT).getDefaultState(), 3);
        world.setBlockState(new net.minecraft.util.math.BlockPos(i + 6, j + 8, k + 1), (Blocks.DIRT).getDefaultState(), 3);
        world.setBlockState(new net.minecraft.util.math.BlockPos(i + 6, j + 8, k + 2), (Blocks.DIRT).getDefaultState(), 3);
        world.setBlockState(new net.minecraft.util.math.BlockPos(i + 6, j + 8, k + 3), (Blocks.COBBLESTONE).getDefaultState(), 3);
        world.setBlockState(new net.minecraft.util.math.BlockPos(i + 6, j + 8, k + 4), (Blocks.COBBLESTONE).getDefaultState(), 3);
        world.setBlockState(new net.minecraft.util.math.BlockPos(i + 6, j + 8, k + 5), (Blocks.COBBLESTONE).getDefaultState(), 3);
        world.setBlockState(new net.minecraft.util.math.BlockPos(i + 6, j + 8, k + 6), (Blocks.COBBLESTONE).getDefaultState(), 3);
        world.setBlockState(new net.minecraft.util.math.BlockPos(i + 6, j + 8, k + 7), (Blocks.STONE_STAIRS).getStateFromMeta(5), 3);
        world.setBlockState(new net.minecraft.util.math.BlockPos(i + 6, j + 8, k + 8), (Blocks.STONE_STAIRS).getStateFromMeta(5), 3);
        world.setBlockState(new net.minecraft.util.math.BlockPos(i + 6, j + 8, k + 9), (Blocks.STONE_STAIRS).getStateFromMeta(5), 3);
        world.setBlockState(new net.minecraft.util.math.BlockPos(i + 6, j + 8, k + 10), (Blocks.STONE_STAIRS).getStateFromMeta(5), 3);
        world.setBlockState(new net.minecraft.util.math.BlockPos(i + 6, j + 8, k + 11), (Blocks.STONE_STAIRS).getStateFromMeta(5), 3);
        world.setBlockState(new net.minecraft.util.math.BlockPos(i + 6, j + 8, k + 12), (Blocks.MOSSY_COBBLESTONE).getDefaultState(), 3);
        world.setBlockState(new net.minecraft.util.math.BlockPos(i + 6, j + 8, k + 13), (Blocks.COBBLESTONE).getDefaultState(), 3);
        world.setBlockState(new net.minecraft.util.math.BlockPos(i + 6, j + 8, k + 14), (Blocks.COBBLESTONE).getDefaultState(), 3);
        world.setBlockState(new net.minecraft.util.math.BlockPos(i + 6, j + 8, k + 15), (Blocks.COBBLESTONE).getDefaultState(), 3);
        world.setBlockState(new net.minecraft.util.math.BlockPos(i + 6, j + 8, k + 16), (Blocks.DIRT).getDefaultState(), 3);
        world.setBlockState(new net.minecraft.util.math.BlockPos(i + 6, j + 8, k + 17), (Blocks.DIRT).getDefaultState(), 3);
        world.setBlockState(new net.minecraft.util.math.BlockPos(i + 6, j + 8, k + 18), (Blocks.DIRT).getDefaultState(), 3);
        world.setBlockState(new net.minecraft.util.math.BlockPos(i + 6, j + 9, k), (Blocks.GRASS).getDefaultState(), 3);
        world.setBlockState(new net.minecraft.util.math.BlockPos(i + 6, j + 9, k + 1), (Blocks.DIRT).getDefaultState(), 3);
        world.setBlockState(new net.minecraft.util.math.BlockPos(i + 6, j + 9, k + 2), (Blocks.DIRT).getDefaultState(), 3);
        world.setBlockState(new net.minecraft.util.math.BlockPos(i + 6, j + 9, k + 3), (Blocks.COBBLESTONE).getDefaultState(), 3);
        world.setBlockState(new net.minecraft.util.math.BlockPos(i + 6, j + 9, k + 6), (Blocks.MOSSY_COBBLESTONE).getDefaultState(), 3);
        world.setBlockState(new net.minecraft.util.math.BlockPos(i + 6, j + 9, k + 12), (Blocks.COBBLESTONE).getDefaultState(), 3);
        world.setBlockState(new net.minecraft.util.math.BlockPos(i + 6, j + 9, k + 15), (Blocks.COBBLESTONE).getDefaultState(), 3);
        world.setBlockState(new net.minecraft.util.math.BlockPos(i + 6, j + 9, k + 16), (Blocks.DIRT).getDefaultState(), 3);
        world.setBlockState(new net.minecraft.util.math.BlockPos(i + 6, j + 9, k + 17), (Blocks.DIRT).getDefaultState(), 3);
        world.setBlockState(new net.minecraft.util.math.BlockPos(i + 6, j + 9, k + 18), (Blocks.GRASS).getDefaultState(), 3);
        world.setBlockState(new net.minecraft.util.math.BlockPos(i + 6, j + 10, k + 1), (Blocks.GRASS).getDefaultState(), 3);
        world.setBlockState(new net.minecraft.util.math.BlockPos(i + 6, j + 10, k + 2), (Blocks.DIRT).getDefaultState(), 3);
        world.setBlockState(new net.minecraft.util.math.BlockPos(i + 6, j + 10, k + 3), (Blocks.COBBLESTONE).getDefaultState(), 3);
        world.setBlockState(new net.minecraft.util.math.BlockPos(i + 6, j + 10, k + 6), (Blocks.COBBLESTONE).getDefaultState(), 3);
        world.setBlockState(new net.minecraft.util.math.BlockPos(i + 6, j + 10, k + 12), (Blocks.MOSSY_COBBLESTONE).getDefaultState(), 3);
        world.setBlockState(new net.minecraft.util.math.BlockPos(i + 6, j + 10, k + 15), (Blocks.COBBLESTONE).getDefaultState(), 3);
        world.setBlockState(new net.minecraft.util.math.BlockPos(i + 6, j + 10, k + 16), (Blocks.DIRT).getDefaultState(), 3);
        world.setBlockState(new net.minecraft.util.math.BlockPos(i + 6, j + 10, k + 17), (Blocks.GRASS).getDefaultState(), 3);
        world.setBlockState(new net.minecraft.util.math.BlockPos(i + 6, j + 11, k + 2), (Blocks.GRASS).getDefaultState(), 3);
        world.setBlockState(new net.minecraft.util.math.BlockPos(i + 6, j + 11, k + 3), (Blocks.COBBLESTONE).getDefaultState(), 3);
        world.setBlockState(new net.minecraft.util.math.BlockPos(i + 6, j + 11, k + 5), (Blocks.STONE_STAIRS).getStateFromMeta(6), 3);
        world.setBlockState(new net.minecraft.util.math.BlockPos(i + 6, j + 11, k + 6), (Blocks.COBBLESTONE).getDefaultState(), 3);
        world.setBlockState(new net.minecraft.util.math.BlockPos(i + 6, j + 11, k + 7), (Blocks.STONE_STAIRS).getStateFromMeta(7), 3);
        world.setBlockState(new net.minecraft.util.math.BlockPos(i + 6, j + 11, k + 11), (Blocks.STONE_STAIRS).getStateFromMeta(6), 3);
        world.setBlockState(new net.minecraft.util.math.BlockPos(i + 6, j + 11, k + 12), (Blocks.COBBLESTONE).getDefaultState(), 3);
        world.setBlockState(new net.minecraft.util.math.BlockPos(i + 6, j + 11, k + 13), (Blocks.STONE_STAIRS).getStateFromMeta(7), 3);
        world.setBlockState(new net.minecraft.util.math.BlockPos(i + 6, j + 11, k + 15), (Blocks.MOSSY_COBBLESTONE).getDefaultState(), 3);
        world.setBlockState(new net.minecraft.util.math.BlockPos(i + 6, j + 11, k + 16), (Blocks.GRASS).getDefaultState(), 3);
        world.setBlockState(new net.minecraft.util.math.BlockPos(i + 6, j + 12, k + 3), (Blocks.GRASS).getDefaultState(), 3);
        world.setBlockState(new net.minecraft.util.math.BlockPos(i + 6, j + 12, k + 4), (Blocks.COBBLESTONE).getDefaultState(), 3);
        world.setBlockState(new net.minecraft.util.math.BlockPos(i + 6, j + 12, k + 5), (Blocks.COBBLESTONE).getDefaultState(), 3);
        world.setBlockState(new net.minecraft.util.math.BlockPos(i + 6, j + 12, k + 6), (Blocks.MOSSY_COBBLESTONE).getDefaultState(), 3);
        world.setBlockState(new net.minecraft.util.math.BlockPos(i + 6, j + 12, k + 7), (Blocks.COBBLESTONE).getDefaultState(), 3);
        world.setBlockState(new net.minecraft.util.math.BlockPos(i + 6, j + 12, k + 8), (Blocks.COBBLESTONE).getDefaultState(), 3);
        world.setBlockState(new net.minecraft.util.math.BlockPos(i + 6, j + 12, k + 9), (Blocks.MOSSY_COBBLESTONE).getDefaultState(), 3);
        world.setBlockState(new net.minecraft.util.math.BlockPos(i + 6, j + 12, k + 10), (Blocks.COBBLESTONE).getDefaultState(), 3);
        world.setBlockState(new net.minecraft.util.math.BlockPos(i + 6, j + 12, k + 11), (Blocks.COBBLESTONE).getDefaultState(), 3);
        world.setBlockState(new net.minecraft.util.math.BlockPos(i + 6, j + 12, k + 12), (Blocks.COBBLESTONE).getDefaultState(), 3);
        world.setBlockState(new net.minecraft.util.math.BlockPos(i + 6, j + 12, k + 13), (Blocks.COBBLESTONE).getDefaultState(), 3);
        world.setBlockState(new net.minecraft.util.math.BlockPos(i + 6, j + 12, k + 14), (Blocks.COBBLESTONE).getDefaultState(), 3);
        world.setBlockState(new net.minecraft.util.math.BlockPos(i + 6, j + 12, k + 15), (Blocks.GRASS).getDefaultState(), 3);
        world.setBlockState(new net.minecraft.util.math.BlockPos(i + 6, j + 13, k + 4), (Blocks.GRASS).getDefaultState(), 3);
        world.setBlockState(new net.minecraft.util.math.BlockPos(i + 6, j + 13, k + 5), (Blocks.GRASS).getDefaultState(), 3);
        world.setBlockState(new net.minecraft.util.math.BlockPos(i + 6, j + 13, k + 6), (Blocks.GRASS).getDefaultState(), 3);
        world.setBlockState(new net.minecraft.util.math.BlockPos(i + 6, j + 13, k + 7), (Blocks.GRASS).getDefaultState(), 3);
        world.setBlockState(new net.minecraft.util.math.BlockPos(i + 6, j + 13, k + 8), (Blocks.GRASS).getDefaultState(), 3);
        world.setBlockState(new net.minecraft.util.math.BlockPos(i + 6, j + 13, k + 9), (Blocks.GRASS).getDefaultState(), 3);
        world.setBlockState(new net.minecraft.util.math.BlockPos(i + 6, j + 13, k + 10), (Blocks.GRASS).getDefaultState(), 3);
        world.setBlockState(new net.minecraft.util.math.BlockPos(i + 6, j + 13, k + 11), (Blocks.GRASS).getDefaultState(), 3);
        world.setBlockState(new net.minecraft.util.math.BlockPos(i + 6, j + 13, k + 12), (Blocks.GRASS).getDefaultState(), 3);
        world.setBlockState(new net.minecraft.util.math.BlockPos(i + 6, j + 13, k + 13), (Blocks.GRASS).getDefaultState(), 3);
        world.setBlockState(new net.minecraft.util.math.BlockPos(i + 6, j + 13, k + 14), (Blocks.GRASS).getDefaultState(), 3);
        world.setBlockState(new net.minecraft.util.math.BlockPos(i + 7, j, k + 6), (Blocks.COBBLESTONE).getDefaultState(), 3);
        world.setBlockState(new net.minecraft.util.math.BlockPos(i + 7, j, k + 7), (Blocks.MOSSY_COBBLESTONE).getDefaultState(), 3);
        world.setBlockState(new net.minecraft.util.math.BlockPos(i + 7, j, k + 8), (Blocks.COBBLESTONE).getDefaultState(), 3);
        world.setBlockState(new net.minecraft.util.math.BlockPos(i + 7, j, k + 9), (Blocks.COBBLESTONE).getDefaultState(), 3);
        world.setBlockState(new net.minecraft.util.math.BlockPos(i + 7, j, k + 10), (Blocks.MOSSY_COBBLESTONE).getDefaultState(), 3);
        world.setBlockState(new net.minecraft.util.math.BlockPos(i + 7, j, k + 11), (Blocks.MOSSY_COBBLESTONE).getDefaultState(), 3);
        world.setBlockState(new net.minecraft.util.math.BlockPos(i + 7, j, k + 12), (Blocks.COBBLESTONE).getDefaultState(), 3);
        world.setBlockState(new net.minecraft.util.math.BlockPos(i + 7, j + 1, k + 6), (Blocks.MOSSY_COBBLESTONE).getDefaultState(), 3);
        world.setBlockState(new net.minecraft.util.math.BlockPos(i + 7, j + 1, k + 12), (Blocks.COBBLESTONE).getDefaultState(), 3);
        world.setBlockState(new net.minecraft.util.math.BlockPos(i + 7, j + 2, k + 6), (Blocks.COBBLESTONE).getDefaultState(), 3);
        world.setBlockState(new net.minecraft.util.math.BlockPos(i + 7, j + 2, k + 12), (Blocks.COBBLESTONE).getDefaultState(), 3);
        world.setBlockState(new net.minecraft.util.math.BlockPos(i + 7, j + 3, k + 6), (Blocks.COBBLESTONE).getDefaultState(), 3);
        world.setBlockState(new net.minecraft.util.math.BlockPos(i + 7, j + 3, k + 12), (Blocks.COBBLESTONE).getDefaultState(), 3);
        world.setBlockState(new net.minecraft.util.math.BlockPos(i + 7, j + 4, k + 3), (Blocks.COBBLESTONE).getDefaultState(), 3);
        world.setBlockState(new net.minecraft.util.math.BlockPos(i + 7, j + 4, k + 4), (Blocks.COBBLESTONE).getDefaultState(), 3);
        world.setBlockState(new net.minecraft.util.math.BlockPos(i + 7, j + 4, k + 5), (Blocks.COBBLESTONE).getDefaultState(), 3);
        world.setBlockState(new net.minecraft.util.math.BlockPos(i + 7, j + 4, k + 6), (Blocks.STONE_STAIRS).getStateFromMeta(3), 3);
        world.setBlockState(new net.minecraft.util.math.BlockPos(i + 7, j + 4, k + 12), (Blocks.STONE_STAIRS).getStateFromMeta(2), 3);
        world.setBlockState(new net.minecraft.util.math.BlockPos(i + 7, j + 4, k + 13), (Blocks.COBBLESTONE).getDefaultState(), 3);
        world.setBlockState(new net.minecraft.util.math.BlockPos(i + 7, j + 4, k + 14), (Blocks.COBBLESTONE).getDefaultState(), 3);
        world.setBlockState(new net.minecraft.util.math.BlockPos(i + 7, j + 4, k + 15), (Blocks.COBBLESTONE).getDefaultState(), 3);
        world.setBlockState(new net.minecraft.util.math.BlockPos(i + 7, j + 5, k + 3), (Blocks.COBBLESTONE).getDefaultState(), 3);
        world.setBlockState(new net.minecraft.util.math.BlockPos(i + 7, j + 5, k + 15), (Blocks.COBBLESTONE).getDefaultState(), 3);
        world.setBlockState(new net.minecraft.util.math.BlockPos(i + 7, j + 6, k + 3), (Blocks.COBBLESTONE).getDefaultState(), 3);
        world.setBlockState(new net.minecraft.util.math.BlockPos(i + 7, j + 6, k + 15), (Blocks.MOSSY_COBBLESTONE).getDefaultState(), 3);
        world.setBlockState(new net.minecraft.util.math.BlockPos(i + 7, j + 7, k + 3), (Blocks.COBBLESTONE).getDefaultState(), 3);
        world.setBlockState(new net.minecraft.util.math.BlockPos(i + 7, j + 7, k + 15), (Blocks.COBBLESTONE).getDefaultState(), 3);
        world.setBlockState(new net.minecraft.util.math.BlockPos(i + 7, j + 8, k), (Blocks.DIRT).getDefaultState(), 3);
        world.setBlockState(new net.minecraft.util.math.BlockPos(i + 7, j + 8, k + 1), (Blocks.DIRT).getDefaultState(), 3);
        world.setBlockState(new net.minecraft.util.math.BlockPos(i + 7, j + 8, k + 2), (Blocks.DIRT).getDefaultState(), 3);
        world.setBlockState(new net.minecraft.util.math.BlockPos(i + 7, j + 8, k + 3), (Blocks.COBBLESTONE).getDefaultState(), 3);
        world.setBlockState(new net.minecraft.util.math.BlockPos(i + 7, j + 8, k + 4), (Blocks.COBBLESTONE).getDefaultState(), 3);
        world.setBlockState(new net.minecraft.util.math.BlockPos(i + 7, j + 8, k + 5), (Blocks.COBBLESTONE).getDefaultState(), 3);
        world.setBlockState(new net.minecraft.util.math.BlockPos(i + 7, j + 8, k + 6), (Blocks.STONE_STAIRS).getStateFromMeta(7), 3);
        world.setBlockState(new net.minecraft.util.math.BlockPos(i + 7, j + 8, k + 12), (Blocks.STONE_STAIRS).getStateFromMeta(6), 3);
        world.setBlockState(new net.minecraft.util.math.BlockPos(i + 7, j + 8, k + 13), (Blocks.COBBLESTONE).getDefaultState(), 3);
        world.setBlockState(new net.minecraft.util.math.BlockPos(i + 7, j + 8, k + 14), (Blocks.MOSSY_COBBLESTONE).getDefaultState(), 3);
        world.setBlockState(new net.minecraft.util.math.BlockPos(i + 7, j + 8, k + 15), (Blocks.COBBLESTONE).getDefaultState(), 3);
        world.setBlockState(new net.minecraft.util.math.BlockPos(i + 7, j + 8, k + 16), (Blocks.DIRT).getDefaultState(), 3);
        world.setBlockState(new net.minecraft.util.math.BlockPos(i + 7, j + 8, k + 17), (Blocks.DIRT).getDefaultState(), 3);
        world.setBlockState(new net.minecraft.util.math.BlockPos(i + 7, j + 8, k + 18), (Blocks.DIRT).getDefaultState(), 3);
        world.setBlockState(new net.minecraft.util.math.BlockPos(i + 7, j + 9, k), (Blocks.GRASS).getDefaultState(), 3);
        world.setBlockState(new net.minecraft.util.math.BlockPos(i + 7, j + 9, k + 1), (Blocks.DIRT).getDefaultState(), 3);
        world.setBlockState(new net.minecraft.util.math.BlockPos(i + 7, j + 9, k + 2), (Blocks.DIRT).getDefaultState(), 3);
        world.setBlockState(new net.minecraft.util.math.BlockPos(i + 7, j + 9, k + 3), (Blocks.COBBLESTONE).getDefaultState(), 3);
        world.setBlockState(new net.minecraft.util.math.BlockPos(i + 7, j + 9, k + 15), (Blocks.COBBLESTONE).getDefaultState(), 3);
        world.setBlockState(new net.minecraft.util.math.BlockPos(i + 7, j + 9, k + 16), (Blocks.DIRT).getDefaultState(), 3);
        world.setBlockState(new net.minecraft.util.math.BlockPos(i + 7, j + 9, k + 17), (Blocks.DIRT).getDefaultState(), 3);
        world.setBlockState(new net.minecraft.util.math.BlockPos(i + 7, j + 9, k + 18), (Blocks.GRASS).getDefaultState(), 3);
        world.setBlockState(new net.minecraft.util.math.BlockPos(i + 7, j + 10, k + 1), (Blocks.DIRT).getDefaultState(), 3);
        world.setBlockState(new net.minecraft.util.math.BlockPos(i + 7, j + 10, k + 2), (Blocks.DIRT).getDefaultState(), 3);
        world.setBlockState(new net.minecraft.util.math.BlockPos(i + 7, j + 10, k + 3), (Blocks.COBBLESTONE).getDefaultState(), 3);
        world.setBlockState(new net.minecraft.util.math.BlockPos(i + 7, j + 10, k + 15), (Blocks.COBBLESTONE).getDefaultState(), 3);
        world.setBlockState(new net.minecraft.util.math.BlockPos(i + 7, j + 10, k + 16), (Blocks.DIRT).getDefaultState(), 3);
        world.setBlockState(new net.minecraft.util.math.BlockPos(i + 7, j + 10, k + 17), (Blocks.DIRT).getDefaultState(), 3);
        world.setBlockState(new net.minecraft.util.math.BlockPos(i + 7, j + 11, k + 1), (Blocks.GRASS).getDefaultState(), 3);
        world.setBlockState(new net.minecraft.util.math.BlockPos(i + 7, j + 11, k + 2), (Blocks.GRASS).getDefaultState(), 3);
        world.setBlockState(new net.minecraft.util.math.BlockPos(i + 7, j + 11, k + 3), (Blocks.MOSSY_COBBLESTONE).getDefaultState(), 3);
        world.setBlockState(new net.minecraft.util.math.BlockPos(i + 7, j + 11, k + 6), (Blocks.STONE_STAIRS).getStateFromMeta(5), 3);
        world.setBlockState(new net.minecraft.util.math.BlockPos(i + 7, j + 11, k + 12), (Blocks.STONE_STAIRS).getStateFromMeta(5), 3);
        world.setBlockState(new net.minecraft.util.math.BlockPos(i + 7, j + 11, k + 15), (Blocks.COBBLESTONE).getDefaultState(), 3);
        world.setBlockState(new net.minecraft.util.math.BlockPos(i + 7, j + 11, k + 16), (Blocks.GRASS).getDefaultState(), 3);
        world.setBlockState(new net.minecraft.util.math.BlockPos(i + 7, j + 11, k + 17), (Blocks.GRASS).getDefaultState(), 3);
        world.setBlockState(new net.minecraft.util.math.BlockPos(i + 7, j + 12, k + 3), (Blocks.GRASS).getDefaultState(), 3);
        world.setBlockState(new net.minecraft.util.math.BlockPos(i + 7, j + 12, k + 4), (Blocks.COBBLESTONE).getDefaultState(), 3);
        world.setBlockState(new net.minecraft.util.math.BlockPos(i + 7, j + 12, k + 5), (Blocks.COBBLESTONE).getDefaultState(), 3);
        world.setBlockState(new net.minecraft.util.math.BlockPos(i + 7, j + 12, k + 6), (Blocks.COBBLESTONE).getDefaultState(), 3);
        world.setBlockState(new net.minecraft.util.math.BlockPos(i + 7, j + 12, k + 7), (Blocks.COBBLESTONE).getDefaultState(), 3);
        world.setBlockState(new net.minecraft.util.math.BlockPos(i + 7, j + 12, k + 8), (Blocks.COBBLESTONE).getDefaultState(), 3);
        world.setBlockState(new net.minecraft.util.math.BlockPos(i + 7, j + 12, k + 9), (Blocks.MOSSY_COBBLESTONE).getDefaultState(), 3);
        world.setBlockState(new net.minecraft.util.math.BlockPos(i + 7, j + 12, k + 10), (Blocks.COBBLESTONE).getDefaultState(), 3);
        world.setBlockState(new net.minecraft.util.math.BlockPos(i + 7, j + 12, k + 11), (Blocks.COBBLESTONE).getDefaultState(), 3);
        world.setBlockState(new net.minecraft.util.math.BlockPos(i + 7, j + 12, k + 12), (Blocks.COBBLESTONE).getDefaultState(), 3);
        world.setBlockState(new net.minecraft.util.math.BlockPos(i + 7, j + 12, k + 13), (Blocks.COBBLESTONE).getDefaultState(), 3);
        world.setBlockState(new net.minecraft.util.math.BlockPos(i + 7, j + 12, k + 14), (Blocks.COBBLESTONE).getDefaultState(), 3);
        world.setBlockState(new net.minecraft.util.math.BlockPos(i + 7, j + 12, k + 15), (Blocks.GRASS).getDefaultState(), 3);
        world.setBlockState(new net.minecraft.util.math.BlockPos(i + 7, j + 13, k + 4), (Blocks.GRASS).getDefaultState(), 3);
        world.setBlockState(new net.minecraft.util.math.BlockPos(i + 7, j + 13, k + 5), (Blocks.GRASS).getDefaultState(), 3);
        world.setBlockState(new net.minecraft.util.math.BlockPos(i + 7, j + 13, k + 6), (Blocks.GRASS).getDefaultState(), 3);
        world.setBlockState(new net.minecraft.util.math.BlockPos(i + 7, j + 13, k + 7), (Blocks.DIRT).getDefaultState(), 3);
        world.setBlockState(new net.minecraft.util.math.BlockPos(i + 7, j + 13, k + 8), (Blocks.DIRT).getDefaultState(), 3);
        world.setBlockState(new net.minecraft.util.math.BlockPos(i + 7, j + 13, k + 9), (Blocks.DIRT).getDefaultState(), 3);
        world.setBlockState(new net.minecraft.util.math.BlockPos(i + 7, j + 13, k + 10), (Blocks.GRASS).getDefaultState(), 3);
        world.setBlockState(new net.minecraft.util.math.BlockPos(i + 7, j + 13, k + 11), (Blocks.GRASS).getDefaultState(), 3);
        world.setBlockState(new net.minecraft.util.math.BlockPos(i + 7, j + 13, k + 12), (Blocks.GRASS).getDefaultState(), 3);
        world.setBlockState(new net.minecraft.util.math.BlockPos(i + 7, j + 13, k + 13), (Blocks.GRASS).getDefaultState(), 3);
        world.setBlockState(new net.minecraft.util.math.BlockPos(i + 7, j + 13, k + 14), (Blocks.GRASS).getDefaultState(), 3);
        world.setBlockState(new net.minecraft.util.math.BlockPos(i + 7, j + 14, k + 7), (Blocks.GRASS).getDefaultState(), 3);
        world.setBlockState(new net.minecraft.util.math.BlockPos(i + 7, j + 14, k + 8), (Blocks.GRASS).getDefaultState(), 3);
        world.setBlockState(new net.minecraft.util.math.BlockPos(i + 7, j + 14, k + 9), (Blocks.GRASS).getDefaultState(), 3);
        world.setBlockState(new net.minecraft.util.math.BlockPos(i + 8, j, k + 6), (Blocks.COBBLESTONE).getDefaultState(), 3);
        world.setBlockState(new net.minecraft.util.math.BlockPos(i + 8, j, k + 7), (Blocks.COBBLESTONE).getDefaultState(), 3);
        world.setBlockState(new net.minecraft.util.math.BlockPos(i + 8, j, k + 8), (Blocks.COBBLESTONE).getDefaultState(), 3);
        world.setBlockState(new net.minecraft.util.math.BlockPos(i + 8, j, k + 9), (Blocks.COBBLESTONE).getDefaultState(), 3);
        world.setBlockState(new net.minecraft.util.math.BlockPos(i + 8, j, k + 10), (Blocks.COBBLESTONE).getDefaultState(), 3);
        world.setBlockState(new net.minecraft.util.math.BlockPos(i + 8, j, k + 11), (Blocks.COBBLESTONE).getDefaultState(), 3);
        world.setBlockState(new net.minecraft.util.math.BlockPos(i + 8, j, k + 12), (Blocks.COBBLESTONE).getDefaultState(), 3);
        world.setBlockState(new net.minecraft.util.math.BlockPos(i + 8, j + 1, k + 6), (Blocks.COBBLESTONE).getDefaultState(), 3);
        world.setBlockState(new net.minecraft.util.math.BlockPos(i + 8, j + 1, k + 12), (Blocks.MOSSY_COBBLESTONE).getDefaultState(), 3);
        world.setBlockState(new net.minecraft.util.math.BlockPos(i + 8, j + 2, k + 6), (Blocks.COBBLESTONE).getDefaultState(), 3);
        world.setBlockState(new net.minecraft.util.math.BlockPos(i + 8, j + 2, k + 12), (Blocks.COBBLESTONE).getDefaultState(), 3);
        world.setBlockState(new net.minecraft.util.math.BlockPos(i + 8, j + 3, k + 6), (Blocks.COBBLESTONE).getDefaultState(), 3);
        world.setBlockState(new net.minecraft.util.math.BlockPos(i + 8, j + 3, k + 12), (Blocks.COBBLESTONE).getDefaultState(), 3);
        world.setBlockState(new net.minecraft.util.math.BlockPos(i + 8, j + 4, k + 3), (Blocks.COBBLESTONE).getDefaultState(), 3);
        world.setBlockState(new net.minecraft.util.math.BlockPos(i + 8, j + 4, k + 4), (Blocks.COBBLESTONE).getDefaultState(), 3);
        world.setBlockState(new net.minecraft.util.math.BlockPos(i + 8, j + 4, k + 5), (Blocks.MOSSY_COBBLESTONE).getDefaultState(), 3);
        world.setBlockState(new net.minecraft.util.math.BlockPos(i + 8, j + 4, k + 6), (Blocks.STONE_STAIRS).getStateFromMeta(3), 3);
        world.setBlockState(new net.minecraft.util.math.BlockPos(i + 8, j + 4, k + 12), (Blocks.STONE_STAIRS).getStateFromMeta(2), 3);
        world.setBlockState(new net.minecraft.util.math.BlockPos(i + 8, j + 4, k + 13), (Blocks.COBBLESTONE).getDefaultState(), 3);
        world.setBlockState(new net.minecraft.util.math.BlockPos(i + 8, j + 4, k + 14), (Blocks.COBBLESTONE).getDefaultState(), 3);
        world.setBlockState(new net.minecraft.util.math.BlockPos(i + 8, j + 4, k + 15), (Blocks.COBBLESTONE).getDefaultState(), 3);
        world.setBlockState(new net.minecraft.util.math.BlockPos(i + 8, j + 5, k + 3), (Blocks.COBBLESTONE).getDefaultState(), 3);
        world.setBlockState(new net.minecraft.util.math.BlockPos(i + 8, j + 5, k + 15), (Blocks.COBBLESTONE).getDefaultState(), 3);
        world.setBlockState(new net.minecraft.util.math.BlockPos(i + 8, j + 6, k + 3), (Blocks.MOSSY_COBBLESTONE).getDefaultState(), 3);
        world.setBlockState(new net.minecraft.util.math.BlockPos(i + 8, j + 6, k + 15), (Blocks.COBBLESTONE).getDefaultState(), 3);
        world.setBlockState(new net.minecraft.util.math.BlockPos(i + 8, j + 7, k + 3), (Blocks.COBBLESTONE).getDefaultState(), 3);
        world.setBlockState(new net.minecraft.util.math.BlockPos(i + 8, j + 7, k + 15), (Blocks.COBBLESTONE).getDefaultState(), 3);
        world.setBlockState(new net.minecraft.util.math.BlockPos(i + 8, j + 8, k), (Blocks.DIRT).getDefaultState(), 3);
        world.setBlockState(new net.minecraft.util.math.BlockPos(i + 8, j + 8, k + 1), (Blocks.DIRT).getDefaultState(), 3);
        world.setBlockState(new net.minecraft.util.math.BlockPos(i + 8, j + 8, k + 2), (Blocks.DIRT).getDefaultState(), 3);
        world.setBlockState(new net.minecraft.util.math.BlockPos(i + 8, j + 8, k + 3), (Blocks.COBBLESTONE).getDefaultState(), 3);
        world.setBlockState(new net.minecraft.util.math.BlockPos(i + 8, j + 8, k + 4), (Blocks.COBBLESTONE).getDefaultState(), 3);
        world.setBlockState(new net.minecraft.util.math.BlockPos(i + 8, j + 8, k + 5), (Blocks.MOSSY_COBBLESTONE).getDefaultState(), 3);
        world.setBlockState(new net.minecraft.util.math.BlockPos(i + 8, j + 8, k + 6), (Blocks.STONE_STAIRS).getStateFromMeta(7), 3);
        world.setBlockState(new net.minecraft.util.math.BlockPos(i + 8, j + 8, k + 12), (Blocks.STONE_STAIRS).getStateFromMeta(6), 3);
        world.setBlockState(new net.minecraft.util.math.BlockPos(i + 8, j + 8, k + 13), (Blocks.COBBLESTONE).getDefaultState(), 3);
        world.setBlockState(new net.minecraft.util.math.BlockPos(i + 8, j + 8, k + 14), (Blocks.COBBLESTONE).getDefaultState(), 3);
        world.setBlockState(new net.minecraft.util.math.BlockPos(i + 8, j + 8, k + 15), (Blocks.COBBLESTONE).getDefaultState(), 3);
        world.setBlockState(new net.minecraft.util.math.BlockPos(i + 8, j + 8, k + 16), (Blocks.DIRT).getDefaultState(), 3);
        world.setBlockState(new net.minecraft.util.math.BlockPos(i + 8, j + 8, k + 17), (Blocks.DIRT).getDefaultState(), 3);
        world.setBlockState(new net.minecraft.util.math.BlockPos(i + 8, j + 8, k + 18), (Blocks.DIRT).getDefaultState(), 3);
        world.setBlockState(new net.minecraft.util.math.BlockPos(i + 8, j + 9, k), (Blocks.GRASS).getDefaultState(), 3);
        world.setBlockState(new net.minecraft.util.math.BlockPos(i + 8, j + 9, k + 1), (Blocks.DIRT).getDefaultState(), 3);
        world.setBlockState(new net.minecraft.util.math.BlockPos(i + 8, j + 9, k + 2), (Blocks.DIRT).getDefaultState(), 3);
        world.setBlockState(new net.minecraft.util.math.BlockPos(i + 8, j + 9, k + 3), (Blocks.COBBLESTONE).getDefaultState(), 3);
        world.setBlockState(new net.minecraft.util.math.BlockPos(i + 8, j + 9, k + 15), (Blocks.COBBLESTONE).getDefaultState(), 3);
        world.setBlockState(new net.minecraft.util.math.BlockPos(i + 8, j + 9, k + 16), (Blocks.DIRT).getDefaultState(), 3);
        world.setBlockState(new net.minecraft.util.math.BlockPos(i + 8, j + 9, k + 17), (Blocks.DIRT).getDefaultState(), 3);
        world.setBlockState(new net.minecraft.util.math.BlockPos(i + 8, j + 9, k + 18), (Blocks.GRASS).getDefaultState(), 3);
        world.setBlockState(new net.minecraft.util.math.BlockPos(i + 8, j + 10, k + 1), (Blocks.GRASS).getDefaultState(), 3);
        world.setBlockState(new net.minecraft.util.math.BlockPos(i + 8, j + 10, k + 2), (Blocks.DIRT).getDefaultState(), 3);
        world.setBlockState(new net.minecraft.util.math.BlockPos(i + 8, j + 10, k + 3), (Blocks.MOSSY_COBBLESTONE).getDefaultState(), 3);
        world.setBlockState(new net.minecraft.util.math.BlockPos(i + 8, j + 10, k + 15), (Blocks.MOSSY_COBBLESTONE).getDefaultState(), 3);
        world.setBlockState(new net.minecraft.util.math.BlockPos(i + 8, j + 10, k + 16), (Blocks.DIRT).getDefaultState(), 3);
        world.setBlockState(new net.minecraft.util.math.BlockPos(i + 8, j + 10, k + 17), (Blocks.DIRT).getDefaultState(), 3);
        world.setBlockState(new net.minecraft.util.math.BlockPos(i + 8, j + 11, k + 2), (Blocks.GRASS).getDefaultState(), 3);
        world.setBlockState(new net.minecraft.util.math.BlockPos(i + 8, j + 11, k + 3), (Blocks.COBBLESTONE).getDefaultState(), 3);
        world.setBlockState(new net.minecraft.util.math.BlockPos(i + 8, j + 11, k + 15), (Blocks.COBBLESTONE).getDefaultState(), 3);
        world.setBlockState(new net.minecraft.util.math.BlockPos(i + 8, j + 11, k + 16), (Blocks.GRASS).getDefaultState(), 3);
        world.setBlockState(new net.minecraft.util.math.BlockPos(i + 8, j + 11, k + 17), (Blocks.GRASS).getDefaultState(), 3);
        world.setBlockState(new net.minecraft.util.math.BlockPos(i + 8, j + 12, k + 3), (Blocks.GRASS).getDefaultState(), 3);
        world.setBlockState(new net.minecraft.util.math.BlockPos(i + 8, j + 12, k + 4), (Blocks.COBBLESTONE).getDefaultState(), 3);
        world.setBlockState(new net.minecraft.util.math.BlockPos(i + 8, j + 12, k + 5), (Blocks.COBBLESTONE).getDefaultState(), 3);
        world.setBlockState(new net.minecraft.util.math.BlockPos(i + 8, j + 12, k + 6), (Blocks.COBBLESTONE).getDefaultState(), 3);
        world.setBlockState(new net.minecraft.util.math.BlockPos(i + 8, j + 12, k + 7), (Blocks.MOSSY_COBBLESTONE).getDefaultState(), 3);
        world.setBlockState(new net.minecraft.util.math.BlockPos(i + 8, j + 12, k + 8), (Blocks.COBBLESTONE).getDefaultState(), 3);
        world.setBlockState(new net.minecraft.util.math.BlockPos(i + 8, j + 12, k + 9), (Blocks.COBBLESTONE).getDefaultState(), 3);
        world.setBlockState(new net.minecraft.util.math.BlockPos(i + 8, j + 12, k + 10), (Blocks.COBBLESTONE).getDefaultState(), 3);
        world.setBlockState(new net.minecraft.util.math.BlockPos(i + 8, j + 12, k + 11), (Blocks.COBBLESTONE).getDefaultState(), 3);
        world.setBlockState(new net.minecraft.util.math.BlockPos(i + 8, j + 12, k + 12), (Blocks.COBBLESTONE).getDefaultState(), 3);
        world.setBlockState(new net.minecraft.util.math.BlockPos(i + 8, j + 12, k + 13), (Blocks.COBBLESTONE).getDefaultState(), 3);
        world.setBlockState(new net.minecraft.util.math.BlockPos(i + 8, j + 12, k + 14), (Blocks.COBBLESTONE).getDefaultState(), 3);
        world.setBlockState(new net.minecraft.util.math.BlockPos(i + 8, j + 12, k + 15), (Blocks.GRASS).getDefaultState(), 3);
        world.setBlockState(new net.minecraft.util.math.BlockPos(i + 8, j + 13, k + 4), (Blocks.GRASS).getDefaultState(), 3);
        world.setBlockState(new net.minecraft.util.math.BlockPos(i + 8, j + 13, k + 5), (Blocks.GRASS).getDefaultState(), 3);
        world.setBlockState(new net.minecraft.util.math.BlockPos(i + 8, j + 13, k + 6), (Blocks.DIRT).getDefaultState(), 3);
        world.setBlockState(new net.minecraft.util.math.BlockPos(i + 8, j + 13, k + 7), (Blocks.DIRT).getDefaultState(), 3);
        world.setBlockState(new net.minecraft.util.math.BlockPos(i + 8, j + 13, k + 8), (Blocks.DIRT).getDefaultState(), 3);
        world.setBlockState(new net.minecraft.util.math.BlockPos(i + 8, j + 13, k + 9), (Blocks.DIRT).getDefaultState(), 3);
        world.setBlockState(new net.minecraft.util.math.BlockPos(i + 8, j + 13, k + 10), (Blocks.DIRT).getDefaultState(), 3);
        world.setBlockState(new net.minecraft.util.math.BlockPos(i + 8, j + 13, k + 11), (Blocks.GRASS).getDefaultState(), 3);
        world.setBlockState(new net.minecraft.util.math.BlockPos(i + 8, j + 13, k + 12), (Blocks.GRASS).getDefaultState(), 3);
        world.setBlockState(new net.minecraft.util.math.BlockPos(i + 8, j + 13, k + 13), (Blocks.GRASS).getDefaultState(), 3);
        world.setBlockState(new net.minecraft.util.math.BlockPos(i + 8, j + 13, k + 14), (Blocks.GRASS).getDefaultState(), 3);
        world.setBlockState(new net.minecraft.util.math.BlockPos(i + 8, j + 14, k + 6), (Blocks.GRASS).getDefaultState(), 3);
        world.setBlockState(new net.minecraft.util.math.BlockPos(i + 8, j + 14, k + 7), (Blocks.GRASS).getDefaultState(), 3);
        world.setBlockState(new net.minecraft.util.math.BlockPos(i + 8, j + 14, k + 8), (Blocks.GRASS).getDefaultState(), 3);
        world.setBlockState(new net.minecraft.util.math.BlockPos(i + 8, j + 14, k + 9), (Blocks.GRASS).getDefaultState(), 3);
        world.setBlockState(new net.minecraft.util.math.BlockPos(i + 8, j + 14, k + 10), (Blocks.GRASS).getDefaultState(), 3);
        world.setBlockState(new net.minecraft.util.math.BlockPos(i + 9, j, k + 6), (Blocks.COBBLESTONE).getDefaultState(), 3);
        world.setBlockState(new net.minecraft.util.math.BlockPos(i + 9, j, k + 7), (Blocks.COBBLESTONE).getDefaultState(), 3);
        world.setBlockState(new net.minecraft.util.math.BlockPos(i + 9, j, k + 8), (Blocks.MOSSY_COBBLESTONE).getDefaultState(), 3);
        world.setBlockState(new net.minecraft.util.math.BlockPos(i + 9, j, k + 9), (Blocks.COBBLESTONE).getDefaultState(), 3);
        world.setBlockState(new net.minecraft.util.math.BlockPos(i + 9, j, k + 10), (Blocks.MOSSY_COBBLESTONE).getDefaultState(), 3);
        world.setBlockState(new net.minecraft.util.math.BlockPos(i + 9, j, k + 11), (Blocks.MOSSY_COBBLESTONE).getDefaultState(), 3);
        world.setBlockState(new net.minecraft.util.math.BlockPos(i + 9, j, k + 12), (Blocks.COBBLESTONE).getDefaultState(), 3);
        world.setBlockState(new net.minecraft.util.math.BlockPos(i + 9, j + 1, k + 6), (Blocks.MOSSY_COBBLESTONE).getDefaultState(), 3);
        world.setBlockState(new net.minecraft.util.math.BlockPos(i + 9, j + 1, k + 12), (Blocks.MOSSY_COBBLESTONE).getDefaultState(), 3);
        world.setBlockState(new net.minecraft.util.math.BlockPos(i + 9, j + 2, k + 6), (Blocks.COBBLESTONE).getDefaultState(), 3);
        world.setBlockState(new net.minecraft.util.math.BlockPos(i + 9, j + 2, k + 12), (Blocks.COBBLESTONE).getDefaultState(), 3);
        world.setBlockState(new net.minecraft.util.math.BlockPos(i + 9, j + 3, k + 6), (Blocks.COBBLESTONE).getDefaultState(), 3);
        world.setBlockState(new net.minecraft.util.math.BlockPos(i + 9, j + 3, k + 12), (Blocks.MOSSY_COBBLESTONE).getDefaultState(), 3);
        world.setBlockState(new net.minecraft.util.math.BlockPos(i + 9, j + 4, k + 3), (Blocks.COBBLESTONE).getDefaultState(), 3);
        world.setBlockState(new net.minecraft.util.math.BlockPos(i + 9, j + 4, k + 4), (Blocks.COBBLESTONE).getDefaultState(), 3);
        world.setBlockState(new net.minecraft.util.math.BlockPos(i + 9, j + 4, k + 5), (Blocks.COBBLESTONE).getDefaultState(), 3);
        world.setBlockState(new net.minecraft.util.math.BlockPos(i + 9, j + 4, k + 6), (Blocks.STONE_STAIRS).getStateFromMeta(3), 3);
        world.setBlockState(new net.minecraft.util.math.BlockPos(i + 9, j + 4, k + 12), (Blocks.STONE_STAIRS).getStateFromMeta(2), 3);
        world.setBlockState(new net.minecraft.util.math.BlockPos(i + 9, j + 4, k + 13), (Blocks.COBBLESTONE).getDefaultState(), 3);
        world.setBlockState(new net.minecraft.util.math.BlockPos(i + 9, j + 4, k + 14), (Blocks.COBBLESTONE).getDefaultState(), 3);
        world.setBlockState(new net.minecraft.util.math.BlockPos(i + 9, j + 4, k + 15), (Blocks.COBBLESTONE).getDefaultState(), 3);
        world.setBlockState(new net.minecraft.util.math.BlockPos(i + 9, j + 5, k + 3), (Blocks.COBBLESTONE).getDefaultState(), 3);
        world.setBlockState(new net.minecraft.util.math.BlockPos(i + 9, j + 5, k + 15), (Blocks.COBBLESTONE).getDefaultState(), 3);
        world.setBlockState(new net.minecraft.util.math.BlockPos(i + 9, j + 6, k + 3), (Blocks.COBBLESTONE).getDefaultState(), 3);
        world.setBlockState(new net.minecraft.util.math.BlockPos(i + 9, j + 6, k + 15), (Blocks.COBBLESTONE).getDefaultState(), 3);
        world.setBlockState(new net.minecraft.util.math.BlockPos(i + 9, j + 7, k + 3), (Blocks.COBBLESTONE).getDefaultState(), 3);
